Workbook

Sheet Key
A1: Guide to interpreting this cost-effectiveness analysis
A2: Sheet descriptions
E4: Main CEA | F4: This sheet contains the primary calculations that result in final cost-effectiveness estimates. This sheet draws on inputs from the "Inputs" sheet and inputs calculated in the other supplemental sheets listed below.
E5: Counterfactual mortality | F5: This sheet contains our calculations of how high mortality rates would be in the absence of VAS campaigns.
E6: External validity | F6: This sheet contains our calculations of the external validity adjustments we apply to the effect of VAS on mortality, based on differences between the populations treated in studies and the populations treated by grantee programs.
E7: Leverage/Funging | F7: This sheet contains our calculations of the impact that crowding in and crowding out funding by other contributors has on the benefits of the program.
E8: Inputs | F8: This sheet contains all of the manually entered input values informing the CEA, along with the sources and reasoning supporting them. This sheet also contains inputs sourced from the "GBD estimates" sheet.
E9: GBD estimates | F9: This sheet contains disease burden and population datasets downloaded from the Institute of Health Metrics (IHME)'s Global Burden of Disease (GBD) project.
E10: Simple CEA | F10: This sheet contains a simplified version of the CEA that is designed to be comparable to our CEAs of other programs.
E11: Confidence intervals | F11: This sheet contains our best guesses of the 25th and 75th percentile values for each of the parameters of our simple CEA.
E12: Sensitivity analysis | F12: This sheet contains the outputs of our sensitivity analysis that tests the cost-effectiveness ranges that would result from updating certain inputs to their 25th or 75th percentile values.
A14: Terminology key
C16: Terms specific to this CEA
E17: VAS | F17: Stands for vitamin A supplementation; describes an intervention in which vitamin A supplements are delivered to a population in an effort to reduce rates of vitamin A deficiency.
E18: VAD | F18: Stands for vitamin A deficiency; describes a condition resulting from insufficient dietary intake of vitamin A that is associated with increased morbidity and mortality.
E19: Stunting | F19: Describes a condition in which a child has a height-for-age measurement more than two standard deviations below average. We use rates of stunting as one of several proxies for rates of vitamin A deficiency.
E20: Wasting | F20: Describes a condition in which a child has a weight-for-age measurement more than two standard deviations below average. We use rates of wasting as one of several proxies for rates of vitamin A deficiency.
E21: Anemia | F21: Describes a condition in which a person does not have enough healthy red blood cells or hemoglobin in their blood to transport oxygen through their body. We use anemia rates as one of several proxies for rates of vitamin A deficiency.
E22: Poverty headcount | F22: Refers to the percentage of a population that has income or consumption levels lower than a given poverty benchmark.
E23: Fixed-effects | F23: A fixed-effect meta-analysis assumes that the true impact of the intervention is consistent in every study in the analysis. Differences between study results are assumed to be solely down to chance. The main estimate from the analysis can be interpreted as the typical intervention effect.
E24: Random-effects | F24: A random-effects meta-analysis assumes that the true impact of the intervention varies and follows some distribution. The main estimate from the analysis can be interpreted as the average impact of the intervention across heterogenous studies with different findings.
C26: Terms used across GiveWell's CEAs
E27: Internal validity | F27: Describes an adjustment we make to the treatment effect of an intervention to account for the possibility that the treatment effects found in studies may not represent the true effect the intervention had on the populations studied.
E28: External validity | F28: Describes an adjustment we make to the treatment effect of an intervention to account for differences in the program implementation or populations treated in studies from the program implementation or populations treated by grantee programs.
E29: Leverage | F29: Describes a situation where a grantee's spending on a program causes other organizations or governments to contribute more to the program than they otherwise would have. In most cases, accounting for leverage increases cost-effectiveness
E30: Funging | F30: Describes a situation where a grantee's spending on a program causes other organizations or governments to contribute less to the program than they otherwise would have. In most cases, accounting for funging decreases cost-effectiveness.
E31: In-kind contributions | F31: Describes non-financial (e.g., staff time, office space) contributions to a program that might otherwise have been used for other activities or programs.
E32: Counterfactual | F32: In most cases, describes the state of the world that would exist if we did not provide funding to a grantee for a program. When discussing the "counterfactual value of other actors' spending," we are referring to how much benefit another organization's or government's spending would generate if it were spent on something other than the grantee program.
E33: Moral weights | F33: To compare cost-effectiveness across different programs, we use ‘moral weights’ to quantify the benefits of different program impacts (e.g. increased income vs reduced deaths). We benchmark the value of each benefit to a value of 1, which we define as the value of doubling someone’s consumption for one year.
E34: Philanthropic actors | F34: Non-governmental organizations (NGOs) providing funding to philanthropic programs.
A36: Unit and source key
C38: Unit labels used in the CEA
E39: # | F39: Number
E40: per 1k | F40: Rate per 1,000
E41: per 100k | F41: Rate per 100,000
E42: $ | F42: U.S. dollars
E43: ln($) | F43: The natural logarithm of a monetary value
E44: % | F44: Percentage
E45: ppt | F45: Percentage points
E46: UoV | F46: Units of value: an arbitrary unit GiveWell uses to compare the moral value of different types of outcomes, such as saving lives or increasing income
...

Sheet Main CEA
I1: Helen Keller International | Q1: Helen Keller International | Y1: Helen Keller International | AG1: Nutrition International
I2: Burkina Faso | J2: Cameroon | K2: Côte d'Ivoire | L2: DRC | M2: Guinea | N2: Kenya | O2: Madagascar | P2: Mali | Q2: Niger | R2: Nigeria | S2: Nigeria | T2: Nigeria | U2: Nigeria | V2: Nigeria | W2: Nigeria | X2: Nigeria | Y2: Nigeria | Z2: Nigeria | AA2: Nigeria | AB2: Nigeria | AC2: Nigeria | AD2: Nigeria | AE2: Nigeria | AF2: Nigeria | AG2: Angola | AH2: Chad | AI2: Togo | AJ2: Uganda
A3: Main calculations | F3: unit | G3: type | H3: Overall | R3: Adamawa | S3: Akwa Ibom | T3: Anambra | U3: Benue | V3: Delta | W3: Ebonyi | X3: Edo | Y3: Ekiti | Z3: Imo | AA3: Kogi | AB3: Nasarawa | AC3: Ogun | AD3: Osun | AE3: Rivers | AF3: Taraba
E4: Final cost-effectiveness estimate (pulled from below for visibility) | F4: =F149 -> xbenchmark | G4: feed | H4: =H149 -> - | I4: =I149 -> 22.604158 | J4: =J149 -> 15.907951 | K4: =K149 -> 8.5391703 | L4: =L149 -> 16.914533 | M4: =M149 -> 10.932207 | N4: =N149 -> 4.7974496 | O4: =O149 -> 15.912911 | ... AJ4: =AJ149 -> 6.3105992
A5: Costs
C7: GiveWell costs
E8: Grant size | F8: =Inputs!F8 -> $ | G8: =Inputs!G8 -> input | H8: =Inputs!H8 -> 1000000 | I8: =Inputs!I8 -> - | J8: =Inputs!J8 -> - | K8: =Inputs!K8 -> - | L8: =Inputs!L8 -> - | M8: =Inputs!M8 -> - | ... AJ8: =Inputs!AJ8 -> -
C10: Cost breakdown
E11: Percentage of total costs covered by the grantee | F11: =Inputs!F11 -> % | G11: =Inputs!G11 -> input | H11: =Inputs!H11 -> - | I11: =Inputs!I11 -> 0.4310638 | J11: =Inputs!J11 -> 0.6403403 | K11: =Inputs!K11 -> 0.4659904 | L11: =Inputs!L11 -> 0.4659904 | M11: =Inputs!M11 -> 0.5527665 | ... AJ11: =Inputs!AJ11 -> 0.7
E12: Percentage of total costs covered by Nutrition International (vitamin A capsule procurement) | F12: =Inputs!F12 -> % | G12: =Inputs!G12 -> input | H12: =Inputs!H12 -> - | I12: =Inputs!I12 -> 0.0642112 | J12: =Inputs!J12 -> 0.0596597 | K12: =Inputs!K12 -> 0.0697078 | L12: =Inputs!L12 -> 0.0697078 | M12: =Inputs!M12 -> 0.0486625 | ... AJ12: =Inputs!AJ12 -> 0
E13: Percentage of total costs covered by other philanthropic actors | F13: =Inputs!F13 -> % | G13: =Inputs!G13 -> input | H13: =Inputs!H13 -> - | I13: =Inputs!I13 -> 0.0565391 | J13: =Inputs!J13 -> 0 | K13: =Inputs!K13 -> 0.1323195 | L13: =Inputs!L13 -> 0.1323195 | M13: =Inputs!M13 -> 0.098571 | ... AJ13: =Inputs!AJ13 -> 0
E14: Percentage of total costs covered by domestic governments (financial contributions) | F14: =Inputs!F14 -> % | G14: =Inputs!G14 -> input | H14: =Inputs!H14 -> - | I14: =Inputs!I14 -> 0.1481859 | J14: =Inputs!J14 -> 0 | K14: =Inputs!K14 -> 0.0319823 | L14: =Inputs!L14 -> 0.0319823 | M14: =Inputs!M14 -> 0 | ... AJ14: =Inputs!AJ14 -> 0
E15: Percentage of total costs covered by domestic governments (in-kind contributions) | F15: =Inputs!F15 -> % | G15: =Inputs!G15 -> input | H15: =Inputs!H15 -> - | I15: =Inputs!I15 -> 0.3 | J15: =Inputs!J15 -> 0.3 | K15: =Inputs!K15 -> 0.3 | L15: =Inputs!L15 -> 0.3 | M15: =Inputs!M15 -> 0.3 | ... AJ15: =Inputs!AJ15 -> 0.3
C17: Total costs
E18: Total spending by all contributors | F18: $ | G18: calc | H18: - | I18: =IF(I8="-",$H8/I11,I8/I11) -> 2319842.2 | J18: =IF(J8="-",$H8/J11,J8/J11) -> 1561669.6 | K18: =IF(K8="-",$H8/K11,K8/K11) -> 2145967 | L18: =IF(L8="-",$H8/L11,L8/L11) -> 2145967 | M18: =IF(M8="-",$H8/M11,M8/M11) -> 1809082.1 | N18: =IF(N8="-",$H8/N11,N8/N11) -> 2145967 | O18: =IF(O8="-",$H8/O11,O8/O11) -> 1671374.6 | P18: =IF(P8="-",$H8/P11,P8/P11) -> 2312316.8 | ... AJ18: =IF(AJ8="-",$H8/AJ11,AJ8/AJ11) -> 1428571.4
C20: Total spending attributable to different actors
E21: Total spending contributed by grantee | F21: $ | G21: calc | H21: - | I21: =I$18*I11 -> 1000000 | J21: =J$18*J11 -> 1000000 | K21: =K$18*K11 -> 1000000 | L21: =L$18*L11 -> 1000000 | M21: =M$18*M11 -> 1000000 | N21: =N$18*N11 -> 1000000 | O21: =O$18*O11 -> 1000000 | P21: =P$18*P11 -> 1000000 | ... AJ21: =AJ$18*AJ11 -> 1000000
E22: Total spending contributed by Nutrition International (vitamin A capsule procurement) | F22: $ | G22: calc | H22: - | I22: =I$18*I12 -> 148959.85 | J22: =J$18*J12 -> 93168.742 | K22: =K$18*K12 -> 149590.64 | L22: =L$18*L12 -> 149590.64 | M22: =M$18*M12 -> 88034.459 | N22: =N$18*N12 -> 149590.64 | O22: =O$18*O12 -> 116507.85 | P22: =P$18*P12 -> 195582.46 | ... AJ22: =AJ$18*AJ12 -> 0
E23: Total spending contributed by other philanthropic actors | F23: $ | G23: calc | H23: - | I23: =I$18*I13 -> 131161.79 | J23: =J$18*J13 -> 0 | K23: =K$18*K13 -> 283953.27 | L23: =L$18*L13 -> 283953.27 | M23: =M$18*M13 -> 178323.04 | N23: =N$18*N13 -> 283953.27 | O23: =O$18*O13 -> 0 | P23: =P$18*P13 -> 423039.28 | ... AJ23: =AJ$18*AJ13 -> 0
E24: Total spending contributed by domestic governments (financial contributions) | F24: $ | G24: calc | H24: - | I24: =I$18*I14 -> 343767.91 | J24: =J$18*J14 -> 0 | K24: =K$18*K14 -> 68632.959 | L24: =L$18*L14 -> 68632.959 | M24: =M$18*M14 -> 0 | N24: =N$18*N14 -> 68632.959 | O24: =O$18*O14 -> 53454.405 | P24: =P$18*P14 -> 0 | ... AJ24: =AJ$18*AJ14 -> 0
E25: Total spending contributed by domestic governments (in-kind contributions) | F25: $ | G25: calc | H25: - | I25: =I$18*I15 -> 695952.66 | J25: =J$18*J15 -> 468500.89 | K25: =K$18*K15 -> 643790.09 | L25: =L$18*L15 -> 643790.09 | M25: =M$18*M15 -> 542724.64 | N25: =N$18*N15 -> 643790.09 | O25: =O$18*O15 -> 501412.4 | P25: =P$18*P15 -> 693695.03 | ... AJ25: =AJ$18*AJ15 -> 428571.43
C27: Upstream / downstream spending
E28: Total spending causally upstream of donations to grantee | F28: $ | G28: calc | H28: - | I28: =SUM(I21,I23:I24) -> 1474929.7 | J28: =SUM(J21,J23:J24) -> 1000000 | K28: =SUM(K21,K23:K24) -> 1352586.2 | L28: =SUM(L21,L23:L24) -> 1352586.2 | M28: =SUM(M21,M23:M24) -> 1178323 | N28: =SUM(N21,N23:N24) -> 1352586.2 | O28: =SUM(O21,O23:O24) -> 1053454.4 | P28: =SUM(P21,P23:P24) -> 1423039.3 | ... AJ28: =SUM(AJ21,AJ23:AJ24) -> 1000000
E29: Total spending causally downstream of donations to grantee | F29: $ | G29: calc | H29: - | I29: =SUM(I22,I25) -> 844912.52 | J29: =SUM(J22,J25) -> 561669.63 | K29: =SUM(K22,K25) -> 793380.72 | L29: =SUM(L22,L25) -> 793380.72 | M29: =SUM(M22,M25) -> 630759.1 | N29: =SUM(N22,N25) -> 793380.72 | O29: =SUM(O22,O25) -> 617920.24 | P29: =SUM(P22,P25) -> 889277.49 | ... AJ29: =SUM(AJ22,AJ25) -> 428571.43
C31: Cost per child covered
E32: Cost per vitamin A supplement delivered | F32: =Inputs!F18 -> $ | G32: =Inputs!G18 -> input | H32: =Inputs!H18 -> - | I32: =Inputs!I18 -> 1.05602 | J32: =Inputs!J18 -> 1.13658 | K32: =Inputs!K18 -> 1.01732 | L32: =Inputs!L18 -> 1.01732 | M32: =Inputs!M18 -> 1.39344 | ... AJ32: =Inputs!AJ18 -> 1.01732
E33: Supplementation rounds delivered per year | F33: =Inputs!F19 -> # | G33: =Inputs!G19 -> input | H33: =Inputs!H19 -> 2 | I33: =Inputs!I19 -> - | J33: =Inputs!J19 -> - | K33: =Inputs!K19 -> - | L33: =Inputs!L19 -> - | M33: =Inputs!M19 -> - | ... AJ33: =Inputs!AJ19 -> -
E34: Total cost per child receiving a year of vitamin A supplementation (VAS) | F34: $ | G34: calc | H34: - | I34: =I32*$H33 -> 2.11204 | J34: =J32*$H33 -> 2.27316 | K34: =K32*$H33 -> 2.03464 | L34: =L32*$H33 -> 2.03464 | M34: =M32*$H33 -> 2.78688 | N34: =N32*$H33 -> 2.03464 | O34: =O32*$H33 -> 2.03464 | P34: =P32*$H33 -> 1.60336 | ... AJ34: =AJ32*$H33 -> 2.03464
E35: Upstream costs per child receiving a year of VAS | F35: $ | G35: calc | H35: - | I35: =(I28/I18)*I34 -> 1.3428114 | J35: =(J28/J18)*J34 -> 1.455596 | K35: =(K28/K18)*K34 -> 1.2824177 | L35: =(L28/L18)*L34 -> 1.2824177 | M35: =(M28/M18)*M34 -> 1.8151995 | N35: =(N28/N18)*N34 -> 1.2824177 | O35: =(O28/O18)*O34 -> 1.2824177 | P35: =(P28/P18)*P34 -> 0.98673516 | ... AJ35: =(AJ28/AJ18)*AJ34 -> 1.424248
A37: Outputs
C39: Total children covered
E40: Total people under age 5 receiving a year of VAS | F40: # | G40: calc | H40: - | I40: =I21/I35 -> 744706.23 | J40: =J21/J35 -> 687003.83 | K40: =K21/K35 -> 779777.12 | L40: =L21/L35 -> 779777.12 | M40: =M21/M35 -> 550903.65 | N40: =N21/N35 -> 779777.12 | O40: =O21/O35 -> 779777.12 | P40: =P21/P35 -> 1013443.2 | ... AJ40: =AJ21/AJ35 -> 702124.91
E41: Baseline proportion of people under age 5 who receive VAS from non-campaign sources | F41: =Inputs!F139 -> % | G41: =Inputs!G139 -> input | H41: =Inputs!H139 -> - | I41: =Inputs!I139 -> 0.25 | J41: =Inputs!J139 -> 0.25 | K41: =Inputs!K139 -> 0.25 | L41: =Inputs!L139 -> 0.25 | M41: =Inputs!M139 -> 0.25 | ... AJ41: =Inputs!AJ139 -> 0.25
E42: Additional people under age 5 receiving a year of VAS as a result of the program | F42: # | G42: calc | H42: - | I42: =I40*(1-I41) -> 558529.67 | J42: =J40*(1-J41) -> 515252.87 | K42: =K40*(1-K41) -> 584832.84 | L42: =L40*(1-L41) -> 584832.84 | M42: =M40*(1-M41) -> 413177.74 | N42: =N40*(1-N41) -> 584832.84 | O42: =O40*(1-O41) -> 436675.19 | P42: =P40*(1-P41) -> 760082.37 | ... AJ42: =AJ40*(1-AJ41) -> 526593.68
A44: Outcomes
C46: Mortality reduction among people under age 5
E47: Reduction in all-cause mortality for children under age 5 participating in VAS programs found in the Imdad et al. 2017 meta-analysis | F47: =Inputs!F144 -> % | G47: =Inputs!G144 -> input | H47: =Inputs!H144 -> 0.24 | I47: =Inputs!I144 -> - | J47: =Inputs!J144 -> - | K47: =Inputs!K144 -> - | L47: =Inputs!L144 -> - | M47: =Inputs!M144 -> - | ... AJ47: =Inputs!AJ144 -> -
E48: Proportion of participating children that received VAS in the trials from the Imdad et al. 2017 meta-analysis | F48: =Inputs!F145 -> % | G48: =Inputs!G145 -> input | H48: =Inputs!H145 -> 0.8729567 | I48: =Inputs!I145 -> - | J48: =Inputs!J145 -> - | K48: =Inputs!K145 -> - | L48: =Inputs!L145 -> - | M48: =Inputs!M145 -> - | ... AJ48: =Inputs!AJ145 -> -
E49: Implied reduction in all-cause mortality for children under age 5 receiving vitamin A supplementation | F49: % | G49: calc | H49: =H47/H48 -> 0.27492773 | I49: - | J49: - | K49: - | L49: - | M49: - | N49: - | O49: - | P49: - | Q49: - | R49: - | S49: - | T49: - | U49: - | V49: - | W49: - | X49: - | Y49: - | Z49: - | AA49: - | AB49: - | AC49: - | AD49: - | AE49: - | AF49: - | AG49: - | AH49: - | AI49: - | AJ49: -
E50: Internal validity adjustment | F50: =Inputs!F146 -> % | G50: =Inputs!G146 -> input | H50: =Inputs!H146 -> -0.25 | I50: =Inputs!I146 -> - | J50: =Inputs!J146 -> - | K50: =Inputs!K146 -> - | L50: =Inputs!L146 -> - | M50: =Inputs!M146 -> - | ... AJ50: =Inputs!AJ146 -> -
...

Sheet Counterfactual mortality
I1: Helen Keller International | Q1: Helen Keller International | Y1: Helen Keller International | AG1: Nutrition International
I2: Burkina Faso | J2: Cameroon | K2: Côte d'Ivoire | L2: DRC | M2: Guinea | N2: Kenya | O2: Madagascar | P2: Mali | Q2: Niger | R2: Nigeria | S2: Nigeria | T2: Nigeria | U2: Nigeria | V2: Nigeria | W2: Nigeria | X2: Nigeria | Y2: Nigeria | Z2: Nigeria | AA2: Nigeria | AB2: Nigeria | AC2: Nigeria | AD2: Nigeria | AE2: Nigeria | AF2: Nigeria | AG2: Angola | AH2: Chad | AI2: Togo | AJ2: Uganda
A3: Supplemental calculations for counterfactual mortality rates | H3: Overall | R3: Adamawa | S3: Akwa Ibom | T3: Anambra | U3: Benue | V3: Delta | W3: Ebonyi | X3: Edo | Y3: Ekiti | Z3: Imo | AA3: Kogi | AB3: Nasarawa | AC3: Ogun | AD3: Osun | AE3: Rivers | AF3: Taraba
E4: Final cost-effectiveness estimate (pulled from "Main calcs" sheet for visibility) | F4: ='Main CEA'!F149 -> xbenchmark | G4: main | H4: ='Main CEA'!H149 -> - | I4: ='Main CEA'!I149 -> 22.604158 | J4: ='Main CEA'!J149 -> 15.907951 | K4: ='Main CEA'!K149 -> 8.5391703 | L4: ='Main CEA'!L149 -> 16.914533 | M4: ='Main CEA'!M149 -> 10.932207 | N4: ='Main CEA'!N149 -> 4.7974496 | O4: ='Main CEA'!O149 -> 15.912911 | ... AJ4: ='Main CEA'!AJ149 -> 6.3105992
C7: Mortalities per year among people under age 5
E8: Total mortalities per year among people under age 5 | F8: =Inputs!F24 -> # | G8: =Inputs!G24 -> input | H8: =Inputs!H24 -> - | I8: =Inputs!I24 -> 98779.14 | J8: =Inputs!J24 -> 64035.007 | K8: =Inputs!K24 -> 64816.604 | L8: =Inputs!L24 -> 168468.45 | M8: =Inputs!M24 -> 45406.175 | ... AJ8: =Inputs!AJ24 -> 91702.416
E9: Total early neonatal mortalities per year (babies under 7 days old) | F9: =Inputs!F25 -> # | G9: =Inputs!G25 -> input | H9: =Inputs!H25 -> - | I9: =Inputs!I25 -> 19940.749 | J9: =Inputs!J25 -> 17016.724 | K9: =Inputs!K25 -> 25085.602 | L9: =Inputs!L25 -> 53762.704 | M9: =Inputs!M25 -> 11002.662 | ... AJ9: =Inputs!AJ25 -> 33674.565
E10: Total late neonatal mortalities per year (babies between 7 and 27 days old) | F10: =Inputs!F26 -> # | G10: =Inputs!G26 -> input | H10: =Inputs!H26 -> - | I10: =Inputs!I26 -> 6949.4673 | J10: =Inputs!J26 -> 4718.8947 | K10: =Inputs!K26 -> 5328.8585 | L10: =Inputs!L26 -> 10893.455 | M10: =Inputs!M26 -> 3633.8561 | ... AJ10: =Inputs!AJ26 -> 7103.6055
E11: Total post-neonatal mortalities per year (babies between 28 and 364 days old) | F11: =Inputs!F27 -> # | G11: =Inputs!G27 -> input | H11: =Inputs!H27 -> - | I11: =Inputs!I27 -> 30592.149 | J11: =Inputs!J27 -> 19245.01 | K11: =Inputs!K27 -> 12225.341 | L11: =Inputs!L27 -> 50492.306 | M11: =Inputs!M27 -> 11984.047 | ... AJ11: =Inputs!AJ27 -> 25133.879
C13: Estimated mortalities per year among the VAS-eligible population
E14: =Inputs!E30 -> Proportion of post-neonatal mortalities that are among 1-5-month-olds | F14: =Inputs!F30 -> % | G14: =Inputs!G30 -> input | H14: =Inputs!H30 -> 0.53 | I14: =Inputs!I30 | J14: =Inputs!J30 | K14: =Inputs!K30 | L14: =Inputs!L30 | ... AJ14: =Inputs!AJ30 -> -
E15: Estimated mortalities per year among 1-5-month-olds | F15: # | G15: calc | H15: - | I15: =I11*$H14 -> 16213.839 | J15: =J11*$H14 -> 10199.856 | K15: =K11*$H14 -> 6479.4309 | L15: =L11*$H14 -> 26760.922 | M15: =M11*$H14 -> 6351.545 | N15: =N11*$H14 -> 8124.8035 | O15: =O11*$H14 -> 8188.9652 | P15: =P11*$H14 -> 15058.856 | ... AJ15: =AJ11*$H14 -> 13320.956
E16: Total mortalities per year among 6-59-month-olds | F16: # | G16: calc | H16: - | I16: =I8-SUM(I9:I10,I15) -> 55675.086 | J16: =J8-SUM(J9:J10,J15) -> 32099.534 | K16: =K8-SUM(K9:K10,K15) -> 27922.712 | L16: =L8-SUM(L9:L10,L15) -> 77051.37 | M16: =M8-SUM(M9:M10,M15) -> 24418.112 | N16: =N8-SUM(N9:N10,N15) -> 19571.679 | O16: =O8-SUM(O9:O10,O15) -> 20147.329 | P16: =P8-SUM(P9:P10,P15) -> 56546.983 | ... AJ16: =AJ8-SUM(AJ9:AJ10,AJ15) -> 37603.289
E17: Proportion of mortalities among people under age 5 that occur among 6-59-month-olds | F17: % | G17: calc | H17: - | I17: =I16/I8 -> 0.56363201 | J17: =J16/J8 -> 0.50128102 | K17: =K16/K8 -> 0.43079567 | L17: =L16/L8 -> 0.45736379 | M17: =M16/M8 -> 0.53777073 | N17: =N16/N8 -> 0.36689072 | O17: =O16/O8 -> 0.41837539 | P17: =P16/P8 -> 0.51573906 | ... AJ17: =AJ16/AJ8 -> 0.41005778
C19: All-cause mortality rate among the VAS-eligible population
E20: All-cause mortality rate among people under age 5 | F20: =Inputs!F33 -> per 100k | G20: =Inputs!G33 -> input | H20: =Inputs!H33 -> - | I20: =Inputs!I33 -> 2442.0317 | J20: =Inputs!J33 -> 1522.0667 | K20: =Inputs!K33 -> 1615.569 | L20: =Inputs!L33 -> 1236.0606 | M20: =Inputs!M33 -> 2118.4232 | ... AJ20: =Inputs!AJ33 -> 1293.4507
E21: Implied population under age 5 | F21: # | G21: calc | H21: - | I21: =I8/I20*100000 -> 4044957.3 | J21: =J8/J20*100000 -> 4207109.2 | K21: =K8/K20*100000 -> 4011998.5 | L21: =L8/L20*100000 -> 13629465 | M21: =M8/M20*100000 -> 2143394.9 | N21: =N8/N20*100000 -> 6416042.8 | O21: =O8/O20*100000 -> 3939181.5 | P21: =P8/P20*100000 -> 4064332.1 | ... AJ21: =AJ8/AJ20*100000 -> 7089749.8
E22: Estimated proportion of people under age 5 who are 6-59-month-olds | F22: =Inputs!F34 -> % | G22: =Inputs!G34 -> input | H22: =Inputs!H34 -> - | I22: =Inputs!I34 -> 0.91525424 | J22: =Inputs!J34 -> 0.91525424 | K22: =Inputs!K34 -> 0.91525424 | L22: =Inputs!L34 -> 0.91525424 | M22: =Inputs!M34 -> 0.91525424 | ... AJ22: =Inputs!AJ34 -> 0.91525424
E23: Estimated population of 6-59-month-olds | F23: # | G23: calc | H23: - | I23: =I21*I22 -> 3702164.3 | J23: =J21*J22 -> 3850574.6 | K23: =K21*K22 -> 3671998.6 | L23: =L21*L22 -> 12474426 | M23: =M21*M22 -> 1961751.2 | N23: =N21*N22 -> 5872310.3 | O23: =O21*O22 -> 3605352.6 | P23: =P21*P22 -> 3719897.2 | ... AJ23: =AJ21*AJ22 -> 6488923.6
E24: Annual all-cause mortality rate among 6-59-month-olds | F24: % | G24: calc | H24: - | I24: =I16/I23 -> 0.015038524 | J24: =J16/J23 -> 0.0083362971 | K24: =K16/K23 -> 0.0076042273 | L24: =L16/L23 -> 0.0061767469 | M24: =M16/M23 -> 0.012447099 | N24: =N16/N23 -> 0.0033328754 | O24: =O16/O23 -> 0.0055881716 | P24: =P16/P23 -> 0.015201222 | ... AJ24: =AJ16/AJ23 -> 0.0057949964
E25: Adjustment for differences between the national mortality rate and mortality rates in the subnational areas targeted for VAS | F25: =Inputs!F37 -> % | G25: =Inputs!G37 -> input | H25: =Inputs!H37 -> - | I25: =Inputs!I37 -> - | J25: =Inputs!J37 -> -0.1408628 | K25: =Inputs!K37 -> - | L25: =Inputs!L37 -> - | M25: =Inputs!M37 -> - | ... AJ25: =Inputs!AJ37 -> -
E26: Annual all-cause mortality rate among 6-59-month-olds in areas targeted for VAS | F26: % | G26: calc | H26: - | I26: =IF(I25<>"-",I24*(1+I25),I24) -> 0.015038524 | J26: =IF(J25<>"-",J24*(1+J25),J24) -> 0.007162023 | K26: =IF(K25<>"-",K24*(1+K25),K24) -> 0.0076042273 | L26: =IF(L25<>"-",L24*(1+L25),L24) -> 0.0061767469 | M26: =IF(M25<>"-",M24*(1+M25),M24) -> 0.012447099 | N26: =IF(N25<>"-",N24*(1+N25),N24) -> 0.0033328754 | O26: =IF(O25<>"-",O24*(1+O25),O24) -> 0.0065381607 | P26: =IF(P25<>"-",P24*(1+P25),P24) -> 0.015201222 | ... AJ26: =IF(AJ25<>"-",AJ24*(1+AJ25),AJ24) -> 0.0057949964

Sheet External validity
I1: Helen Keller International | Q1: Helen Keller International | Y1: Helen Keller International | AG1: Nutrition International
I2: Burkina Faso | J2: Cameroon | K2: Côte d'Ivoire | L2: DRC | M2: Guinea | N2: Kenya | O2: Madagascar | P2: Mali | Q2: Niger | R2: Nigeria | S2: Nigeria | T2: Nigeria | U2: Nigeria | V2: Nigeria | W2: Nigeria | X2: Nigeria | Y2: Nigeria | Z2: Nigeria | AA2: Nigeria | AB2: Nigeria | AC2: Nigeria | AD2: Nigeria | AE2: Nigeria | AF2: Nigeria | AG2: Angola | AH2: Chad | AI2: Togo | AJ2: Uganda
H3: Overall | R3: Adamawa | S3: Akwa Ibom | T3: Anambra | U3: Benue | V3: Delta | W3: Ebonyi | X3: Edo | Y3: Ekiti | Z3: Imo | AA3: Kogi | AB3: Nasarawa | AC3: Ogun | AD3: Osun | AE3: Rivers | AF3: Taraba
E4: Final cost-effectiveness estimate (pulled from "Main calcs" sheet for visibility) | F4: ='Main CEA'!F149 -> xbenchmark | G4: main | H4: ='Main CEA'!H149 -> - | I4: ='Main CEA'!I149 -> 22.604158 | J4: ='Main CEA'!J149 -> 15.907951 | K4: ='Main CEA'!K149 -> 8.5391703 | L4: ='Main CEA'!L149 -> 16.914533 | M4: ='Main CEA'!M149 -> 10.932207 | N4: ='Main CEA'!N149 -> 4.7974496 | O4: ='Main CEA'!O149 -> 15.912911 | ... AJ4: ='Main CEA'!AJ149 -> 6.3105992
A5: Vitamin A deficiency prevalence for Nigerian states
C7: Vitamin A deficiency prevalence in Nigeria according to the latest national survey
E8: Vitamin A deficiency prevalence in Nigeria according to the latest national survey | F8: =Inputs!F42 -> % | G8: =Inputs!G42 -> input | H8: =Inputs!H42 -> - | I8: =Inputs!I42 -> - | J8: =Inputs!J42 -> - | K8: =Inputs!K42 -> - | L8: =Inputs!L42 -> - | M8: =Inputs!M42 -> - | ... AJ8: =Inputs!AJ42 -> -
E9: Year of latest national vitamin A deficiency survey in Nigeria | F9: =Inputs!F43 -> year | G9: =Inputs!G43 -> input | H9: =Inputs!H43 -> - | I9: =Inputs!I43 -> - | J9: =Inputs!J43 -> - | K9: =Inputs!K43 -> - | L9: =Inputs!L43 -> - | M9: =Inputs!M43 -> - | ... AJ9: =Inputs!AJ43 -> -
C11: National data on health proxies for vitamin A deficiency according to DHS surveys
E12: National proportion of people under age 5 who were experiencing stunting in 2003 | F12: =Inputs!F46 -> % | G12: =Inputs!G46 -> input | H12: =Inputs!H46 -> - | I12: =Inputs!I46 -> - | J12: =Inputs!J46 -> - | K12: =Inputs!K46 -> - | L12: =Inputs!L46 -> - | M12: =Inputs!M46 -> - | ... AJ12: =Inputs!AJ46 -> -
E13: National proportion of people under age 5 who were experiencing wasting in 2003 | F13: =Inputs!F47 -> % | G13: =Inputs!G47 -> input | H13: =Inputs!H47 -> - | I13: =Inputs!I47 -> - | J13: =Inputs!J47 -> - | K13: =Inputs!K47 -> - | L13: =Inputs!L47 -> - | M13: =Inputs!M47 -> - | ... AJ13: =Inputs!AJ47 -> -
E14: National proportion of people under age 5 who were experiencing stunting in 2018 | F14: =Inputs!F48 -> % | G14: =Inputs!G48 -> input | H14: =Inputs!H48 -> - | I14: =Inputs!I48 -> - | J14: =Inputs!J48 -> - | K14: =Inputs!K48 -> - | L14: =Inputs!L48 -> - | M14: =Inputs!M48 -> - | ... AJ14: =Inputs!AJ48 -> -
E15: National proportion of people under age 5 who were experiencing wasting in 2018 | F15: =Inputs!F49 -> % | G15: =Inputs!G49 -> input | H15: =Inputs!H49 -> - | I15: =Inputs!I49 -> - | J15: =Inputs!J49 -> - | K15: =Inputs!K49 -> - | L15: =Inputs!L49 -> - | M15: =Inputs!M49 -> - | ... AJ15: =Inputs!AJ49 -> -
E16: National proportion of 6-59-month-olds who were experiencing anemia in 2018 | F16: =Inputs!F50 -> % | G16: =Inputs!G50 -> input | H16: =Inputs!H50 -> - | I16: =Inputs!I50 -> - | J16: =Inputs!J50 -> - | K16: =Inputs!K50 -> - | L16: =Inputs!L50 -> - | M16: =Inputs!M50 -> - | ... AJ16: =Inputs!AJ50 -> -
C18: National data on economic proxies for vitamin A deficiency according to the World Bank
E19: National proportion of the population below the international poverty line in 2003 | F19: =Inputs!F53 -> % | G19: =Inputs!G53 -> input | H19: =Inputs!H53 -> - | I19: =Inputs!I53 -> - | J19: =Inputs!J53 -> - | K19: =Inputs!K53 -> - | L19: =Inputs!L53 -> - | M19: =Inputs!M53 -> - | ... AJ19: =Inputs!AJ53 -> -
E20: National proportion of the population below the international poverty line in 2018 | F20: =Inputs!F54 -> % | G20: =Inputs!G54 -> input | H20: =Inputs!H54 -> - | I20: =Inputs!I54 -> - | J20: =Inputs!J54 -> - | K20: =Inputs!K54 -> - | L20: =Inputs!L54 -> - | M20: =Inputs!M54 -> - | ... AJ20: =Inputs!AJ54 -> -
C22: National data on economic proxies for vitamin A deficiency according to a 2019 NBS survey
E23: National proportion of the population below Nigeria's poverty line in 2019 | F23: =Inputs!F57 -> % | G23: =Inputs!G57 -> input | H23: =Inputs!H57 -> - | I23: =Inputs!I57 -> - | J23: =Inputs!J57 -> - | K23: =Inputs!K57 -> - | L23: =Inputs!L57 -> - | M23: =Inputs!M57 -> - | ... AJ23: =Inputs!AJ57 -> -
C25: Change in proxies for vitamin A deficiency over time
E26: Change in rates of stunting among people under age 5 between 2003 and 2018 | F26: % | G26: calc | H26: - | I26: - | J26: - | K26: - | L26: - | M26: - | N26: - | O26: - | P26: - | Q26: - | R26: =(R14-R12)/R12 -> -0.039164491 | S26: =(S14-S12)/S12 -> -0.039164491 | T26: =(T14-T12)/T12 -> -0.039164491 | U26: =(U14-U12)/U12 -> -0.039164491 | V26: =(V14-V12)/V12 -> -0.039164491 | W26: =(W14-W12)/W12 -> -0.039164491 | X26: =(X14-X12)/X12 -> -0.039164491 | Y26: =(Y14-Y12)/Y12 -> -0.039164491 | ... AF26: =(AF14-AF12)/AF12 -> -0.039164491 | AG26: - | AH26: - | AI26: - | AJ26: -
E27: Change in rates of wasting among people under age 5 between 2003 and 2018 | F27: % | G27: calc | H27: - | I27: - | J27: - | K27: - | L27: - | M27: - | N27: - | O27: - | P27: - | Q27: - | R27: =(R15-R13)/R13 -> -0.26086957 | S27: =(S15-S13)/S13 -> -0.26086957 | T27: =(T15-T13)/T13 -> -0.26086957 | U27: =(U15-U13)/U13 -> -0.26086957 | V27: =(V15-V13)/V13 -> -0.26086957 | W27: =(W15-W13)/W13 -> -0.26086957 | X27: =(X15-X13)/X13 -> -0.26086957 | Y27: =(Y15-Y13)/Y13 -> -0.26086957 | ... AF27: =(AF15-AF13)/AF13 -> -0.26086957 | AG27: - | AH27: - | AI27: - | AJ27: -
E28: Change in poverty rates between 2003 and 2018 according to World Bank data | F28: % | G28: calc | H28: - | I28: - | J28: - | K28: - | L28: - | M28: - | N28: - | O28: - | P28: - | Q28: - | R28: =(R20-R19)/R19 -> -0.30053667 | S28: =(S20-S19)/S19 -> -0.30053667 | T28: =(T20-T19)/T19 -> -0.30053667 | U28: =(U20-U19)/U19 -> -0.30053667 | V28: =(V20-V19)/V19 -> -0.30053667 | W28: =(W20-W19)/W19 -> -0.30053667 | X28: =(X20-X19)/X19 -> -0.30053667 | Y28: =(Y20-Y19)/Y19 -> -0.30053667 | ... AF28: =(AF20-AF19)/AF19 -> -0.30053667 | AG28: - | AH28: - | AI28: - | AJ28: -
E29: Weight placed on change in rates of stunting as a proxy for changes in vitamin A deficiency | F29: =Inputs!F60 -> % | G29: =Inputs!G60 -> input | H29: =Inputs!H60 -> 0.33333333 | I29: =Inputs!I60 -> - | J29: =Inputs!J60 -> - | K29: =Inputs!K60 -> - | L29: =Inputs!L60 -> - | M29: =Inputs!M60 -> - | ... AK29: =Inputs!AK60
E30: Weight placed on change in rates of wasting as a proxy for changes in vitamin A deficiency | F30: =Inputs!F61 -> % | G30: =Inputs!G61 -> input | H30: =Inputs!H61 -> 0.33333333 | I30: =Inputs!I61 -> - | J30: =Inputs!J61 -> - | K30: =Inputs!K61 -> - | L30: =Inputs!L61 -> - | M30: =Inputs!M61 -> - | ... AK30: =Inputs!AK61
E31: Weight placed on change in poverty rates as a proxy for changes in vitamin A deficiency | F31: =Inputs!F62 -> % | G31: =Inputs!G62 -> input | H31: =Inputs!H62 -> 0.33333333 | I31: =Inputs!I62 -> - | J31: =Inputs!J62 -> - | K31: =Inputs!K62 -> - | L31: =Inputs!L62 -> - | M31: =Inputs!M62 -> - | ... AK31: =Inputs!AK62
C33: Approximated change in vitamin A deficiency prevalence over time
E34: Estimated change in vitamin A deficiency prevalence between 2003 and 2018 | F34: % | G34: calc | H34: - | I34: - | J34: - | K34: - | L34: - | M34: - | N34: - | O34: - | P34: - | Q34: - | R34: =SUMPRODUCT(R26:R28,$H29:$H31) -> -0.20019024 | S34: =SUMPRODUCT(S26:S28,$H29:$H31) -> -0.20019024 | T34: =SUMPRODUCT(T26:T28,$H29:$H31) -> -0.20019024 | U34: =SUMPRODUCT(U26:U28,$H29:$H31) -> -0.20019024 | V34: =SUMPRODUCT(V26:V28,$H29:$H31) -> -0.20019024 | W34: =SUMPRODUCT(W26:W28,$H29:$H31) -> -0.20019024 | X34: =SUMPRODUCT(X26:X28,$H29:$H31) -> -0.20019024 | Y34: =SUMPRODUCT(Y26:Y28,$H29:$H31) -> -0.20019024 | ... AF34: =SUMPRODUCT(AF26:AF28,$H29:$H31) -> -0.20019024 | AG34: - | AH34: - | AI34: - | AJ34: -
E35: Year of early data points for vitamin A deficiency proxies | F35: =Inputs!F65 -> year | G35: =Inputs!G65 -> input | H35: =Inputs!H65 -> - | I35: =Inputs!I65 -> - | J35: =Inputs!J65 -> - | K35: =Inputs!K65 -> - | L35: =Inputs!L65 -> - | M35: =Inputs!M65 -> - | ... AJ35: =Inputs!AJ65 -> -
E36: Year of late data points for vitamin A deficiency proxies | F36: =Inputs!F66 -> year | G36: =Inputs!G66 -> input | H36: =Inputs!H66 -> - | I36: =Inputs!I66 -> - | J36: =Inputs!J66 -> - | K36: =Inputs!K66 -> - | L36: =Inputs!L66 -> - | M36: =Inputs!M66 -> - | ... AJ36: =Inputs!AJ66 -> -
E37: Years between early and late data points for vitamin A deficiency proxies | F37: # | G37: calc | H37: - | I37: - | J37: - | K37: - | L37: - | M37: - | N37: - | O37: - | P37: - | Q37: - | R37: =R36-R35 -> 15 | S37: =S36-S35 -> 15 | T37: =T36-T35 -> 15 | U37: =U36-U35 -> 15 | V37: =V36-V35 -> 15 | W37: =W36-W35 -> 15 | X37: =X36-X35 -> 15 | Y37: =Y36-Y35 -> 15 | ... AF37: =AF36-AF35 -> 15 | AG37: - | AH37: - | AI37: - | AJ37: -
E38: Approximated average change in vitamin A deficiency per year | F38: ppt | G38: calc | H38: - | I38: - | J38: - | K38: - | L38: - | M38: - | N38: - | O38: - | P38: - | Q38: - | R38: =R34/R37 -> -0.013346016 | S38: =S34/S37 -> -0.013346016 | T38: =T34/T37 -> -0.013346016 | U38: =U34/U37 -> -0.013346016 | V38: =V34/V37 -> -0.013346016 | W38: =W34/W37 -> -0.013346016 | X38: =X34/X37 -> -0.013346016 | Y38: =Y34/Y37 -> -0.013346016 | ... AF38: =AF34/AF37 -> -0.013346016 | AG38: - | AH38: - | AI38: - | AJ38: -
E39: Expected year of the grantee's VAS campaign | F39: =Inputs!F67 -> year | G39: =Inputs!G67 -> input | H39: =Inputs!H67 -> - | I39: =Inputs!I67 -> 2022 | J39: =Inputs!J67 -> 2022 | K39: =Inputs!K67 -> 2022 | L39: =Inputs!L67 -> 2022 | M39: =Inputs!M67 -> - | ... AJ39: =Inputs!AJ67 -> 2022
E40: Years between the latest national vitamin A deficiency survey in Nigeria and the grantee's VAS campaign | F40: # | G40: calc | H40: - | I40: - | J40: - | K40: - | L40: - | M40: - | N40: - | O40: - | P40: - | Q40: - | R40: =R39-R9 -> 21 | S40: =S39-S9 -> 21 | T40: =T39-T9 -> 21 | U40: =U39-U9 -> 21 | V40: =V39-V9 -> 21 | W40: =W39-W9 -> 21 | X40: =X39-X9 -> 21 | Y40: =Y39-Y9 -> 21 | ... AF40: =AF39-AF9 -> 21 | AG40: - | AH40: - | AI40: - | AJ40: -
E41: Approximated change in vitamin A deficiency since the latest national survey in Nigeria | F41: % | G41: calc | H41: - | I41: - | J41: - | K41: - | L41: - | M41: - | N41: - | O41: - | P41: - | Q41: - | R41: =R38*R40 -> -0.28026634 | S41: =S38*S40 -> -0.28026634 | T41: =T38*T40 -> -0.28026634 | U41: =U38*U40 -> -0.28026634 | V41: =V38*V40 -> -0.28026634 | W41: =W38*W40 -> -0.28026634 | X41: =X38*X40 -> -0.28026634 | Y41: =Y38*Y40 -> -0.28026634 | ... AF41: =AF38*AF40 -> -0.28026634 | AG41: - | AH41: - | AI41: - | AJ41: -
C43: National vitamin A deficiency prevalence at the time of upcoming campaigns
E44: Estimated national vitamin A deficiency prevalence at the time of a grantee campaign | F44: % | G44: calc | H44: - | I44: - | J44: - | K44: - | L44: - | M44: - | N44: - | O44: - | P44: - | Q44: - | R44: =R8*(1+R41) -> 0.21232143 | S44: =S8*(1+S41) -> 0.21232143 | T44: =T8*(1+T41) -> 0.21232143 | U44: =U8*(1+U41) -> 0.21232143 | V44: =V8*(1+V41) -> 0.21232143 | W44: =W8*(1+W41) -> 0.21232143 | X44: =X8*(1+X41) -> 0.21232143 | Y44: =Y8*(1+Y41) -> 0.21232143 | ... AF44: =AF8*(1+AF41) -> 0.21232143 | AG44: - | AH44: - | AI44: - | AJ44: -
C46: State-level data on health proxies for vitamin A deficiency according to DHS surveys
E47: State-level proportion of people under age 5 who were experiencing stunting in 2018 | F47: =Inputs!F70 -> % | G47: =Inputs!G70 -> input | H47: =Inputs!H70 -> - | I47: =Inputs!I70 -> - | J47: =Inputs!J70 -> - | K47: =Inputs!K70 -> - | L47: =Inputs!L70 -> - | M47: =Inputs!M70 -> - | ... AJ47: =Inputs!AJ70 -> -
E48: State-level proportion of people under age 5 who were experiencing wasting in 2018 | F48: =Inputs!F71 -> % | G48: =Inputs!G71 -> input | H48: =Inputs!H71 -> - | I48: =Inputs!I71 -> - | J48: =Inputs!J71 -> - | K48: =Inputs!K71 -> - | L48: =Inputs!L71 -> - | M48: =Inputs!M71 -> - | ... AJ48: =Inputs!AJ71 -> -
...

Sheet LeverageFunging
I1: Helen Keller International | Q1: Helen Keller International | Y1: Helen Keller International | AG1: Nutrition International
I2: Burkina Faso | J2: Cameroon | K2: Côte d'Ivoire | L2: DRC | M2: Guinea | N2: Kenya | O2: Madagascar | P2: Mali | Q2: Niger | R2: Nigeria | S2: Nigeria | T2: Nigeria | U2: Nigeria | V2: Nigeria | W2: Nigeria | X2: Nigeria | Y2: Nigeria | Z2: Nigeria | AA2: Nigeria | AB2: Nigeria | AC2: Nigeria | AD2: Nigeria | AE2: Nigeria | AF2: Nigeria | AG2: Angola | AH2: Chad | AI2: Togo | AJ2: Uganda
A3: Supplemental calculations for the leverage/funging adjustment | F3: unit | G3: type | H3: Overall | R3: Adamawa | S3: Akwa Ibom | T3: Anambra | U3: Benue | V3: Delta | W3: Ebonyi | X3: Edo | Y3: Ekiti | Z3: Imo | AA3: Kogi | AB3: Nasarawa | AC3: Ogun | AD3: Osun | AE3: Rivers | AF3: Taraba
E4: Final cost-effectiveness estimate (pulled from "Main calcs" sheet for visibility) | F4: ='Main CEA'!F149 -> xbenchmark | G4: main | H4: ='Main CEA'!H149 -> - | I4: ='Main CEA'!I149 -> 22.604158 | J4: ='Main CEA'!J149 -> 15.907951 | K4: ='Main CEA'!K149 -> 8.5391703 | L4: ='Main CEA'!L149 -> 16.914533 | M4: ='Main CEA'!M149 -> 10.932207 | N4: ='Main CEA'!N149 -> 4.7974496 | O4: ='Main CEA'!O149 -> 15.912911 | ... AJ4: ='Main CEA'!AJ149 -> 6.3105992
A5: Costs
C7: GiveWell costs
E8: Grant size | F8: =Inputs!F8 -> $ | G8: =Inputs!G8 -> input | H8: =Inputs!H8 -> 1000000 | I8: =Inputs!I8 -> - | J8: =Inputs!J8 -> - | K8: =Inputs!K8 -> - | L8: =Inputs!L8 -> - | M8: =Inputs!M8 -> - | ... AJ8: =Inputs!AJ8 -> -
C10: Cost breakdown
E11: Percentage of total costs covered by the grantee | F11: =Inputs!F11 -> % | G11: =Inputs!G11 -> input | H11: =Inputs!H11 -> - | I11: =Inputs!I11 -> 0.4310638 | J11: =Inputs!J11 -> 0.6403403 | K11: =Inputs!K11 -> 0.4659904 | L11: =Inputs!L11 -> 0.4659904 | M11: =Inputs!M11 -> 0.5527665 | ... AJ11: =Inputs!AJ11 -> 0.7
E12: Percentage of total costs covered by Nutrition International (vitamin A capsule procurement) | F12: =Inputs!F12 -> % | G12: =Inputs!G12 -> input | H12: =Inputs!H12 -> - | I12: =Inputs!I12 -> 0.0642112 | J12: =Inputs!J12 -> 0.0596597 | K12: =Inputs!K12 -> 0.0697078 | L12: =Inputs!L12 -> 0.0697078 | M12: =Inputs!M12 -> 0.0486625 | ... AJ12: =Inputs!AJ12 -> 0
E13: Percentage of total costs covered by other philanthropic actors | F13: =Inputs!F13 -> % | G13: =Inputs!G13 -> input | H13: =Inputs!H13 -> - | I13: =Inputs!I13 -> 0.0565391 | J13: =Inputs!J13 -> 0 | K13: =Inputs!K13 -> 0.1323195 | L13: =Inputs!L13 -> 0.1323195 | M13: =Inputs!M13 -> 0.098571 | ... AJ13: =Inputs!AJ13 -> 0
E14: Percentage of total costs covered by domestic governments (financial contributions) | F14: =Inputs!F14 -> % | G14: =Inputs!G14 -> input | H14: =Inputs!H14 -> - | I14: =Inputs!I14 -> 0.1481859 | J14: =Inputs!J14 -> 0 | K14: =Inputs!K14 -> 0.0319823 | L14: =Inputs!L14 -> 0.0319823 | M14: =Inputs!M14 -> 0 | ... AJ14: =Inputs!AJ14 -> 0
E15: Percentage of total costs covered by domestic governments (in-kind contributions) | F15: =Inputs!F15 -> % | G15: =Inputs!G15 -> input | H15: =Inputs!H15 -> - | I15: =Inputs!I15 -> 0.3 | J15: =Inputs!J15 -> 0.3 | K15: =Inputs!K15 -> 0.3 | L15: =Inputs!L15 -> 0.3 | M15: =Inputs!M15 -> 0.3 | ... AJ15: =Inputs!AJ15 -> 0.3
C17: Total costs
E18: Total spending by all contributors | F18: ='Main CEA'!F18 -> $ | G18: main | H18: ='Main CEA'!H18 -> - | I18: ='Main CEA'!I18 -> 2319842.2 | J18: ='Main CEA'!J18 -> 1561669.6 | K18: ='Main CEA'!K18 -> 2145967 | L18: ='Main CEA'!L18 -> 2145967 | M18: ='Main CEA'!M18 -> 1809082.1 | N18: ='Main CEA'!N18 -> 2145967 | O18: ='Main CEA'!O18 -> 1671374.6 | ... AJ18: ='Main CEA'!AJ18 -> 1428571.4
C20: Total spending attributable to different actors
E21: Total spending contributed by grantee | F21: ='Main CEA'!F21 -> $ | G21: main | H21: ='Main CEA'!H21 -> - | I21: ='Main CEA'!I21 -> 1000000 | J21: ='Main CEA'!J21 -> 1000000 | K21: ='Main CEA'!K21 -> 1000000 | L21: ='Main CEA'!L21 -> 1000000 | M21: ='Main CEA'!M21 -> 1000000 | N21: ='Main CEA'!N21 -> 1000000 | O21: ='Main CEA'!O21 -> 1000000 | ... AJ21: ='Main CEA'!AJ21 -> 1000000
E22: Total spending contributed by Nutrition International (vitamin A capsule procurement) | F22: ='Main CEA'!F22 -> $ | G22: main | H22: ='Main CEA'!H22 -> - | I22: ='Main CEA'!I22 -> 148959.85 | J22: ='Main CEA'!J22 -> 93168.742 | K22: ='Main CEA'!K22 -> 149590.64 | L22: ='Main CEA'!L22 -> 149590.64 | M22: ='Main CEA'!M22 -> 88034.459 | N22: ='Main CEA'!N22 -> 149590.64 | O22: ='Main CEA'!O22 -> 116507.85 | ... AJ22: ='Main CEA'!AJ22 -> 0
E23: Total spending contributed by other philanthropic actors | F23: ='Main CEA'!F23 -> $ | G23: main | H23: ='Main CEA'!H23 -> - | I23: ='Main CEA'!I23 -> 131161.79 | J23: ='Main CEA'!J23 -> 0 | K23: ='Main CEA'!K23 -> 283953.27 | L23: ='Main CEA'!L23 -> 283953.27 | M23: ='Main CEA'!M23 -> 178323.04 | N23: ='Main CEA'!N23 -> 283953.27 | O23: ='Main CEA'!O23 -> 0 | ... AJ23: ='Main CEA'!AJ23 -> 0
E24: Total spending contributed by domestic governments (financial contributions) | F24: ='Main CEA'!F24 -> $ | G24: main | H24: ='Main CEA'!H24 -> - | I24: ='Main CEA'!I24 -> 343767.91 | J24: ='Main CEA'!J24 -> 0 | K24: ='Main CEA'!K24 -> 68632.959 | L24: ='Main CEA'!L24 -> 68632.959 | M24: ='Main CEA'!M24 -> 0 | N24: ='Main CEA'!N24 -> 68632.959 | O24: ='Main CEA'!O24 -> 53454.405 | ... AJ24: ='Main CEA'!AJ24 -> 0
E25: Total spending contributed by domestic governments (in-kind contributions) | F25: ='Main CEA'!F25 -> $ | G25: main | H25: ='Main CEA'!H25 -> - | I25: ='Main CEA'!I25 -> 695952.66 | J25: ='Main CEA'!J25 -> 468500.89 | K25: ='Main CEA'!K25 -> 643790.09 | L25: ='Main CEA'!L25 -> 643790.09 | M25: ='Main CEA'!M25 -> 542724.64 | N25: ='Main CEA'!N25 -> 643790.09 | O25: ='Main CEA'!O25 -> 501412.4 | ... AJ25: ='Main CEA'!AJ25 -> 428571.43
C27: Upstream / downstream spending
E28: ='Main CEA'!E28 -> Total spending causally upstream of donations to grantee | F28: ='Main CEA'!F28 -> $ | G28: main | H28: ='Main CEA'!H28 -> - | I28: ='Main CEA'!I28 -> 1474929.7 | J28: ='Main CEA'!J28 -> 1000000 | K28: ='Main CEA'!K28 -> 1352586.2 | L28: ='Main CEA'!L28 -> 1352586.2 | M28: ='Main CEA'!M28 -> 1178323 | N28: ='Main CEA'!N28 -> 1352586.2 | O28: ='Main CEA'!O28 -> 1053454.4 | ... AJ28: ='Main CEA'!AJ28 -> 1000000
E29: ='Main CEA'!E29 -> Total spending causally downstream of donations to grantee | F29: ='Main CEA'!F29 -> $ | G29: main | H29: ='Main CEA'!H29 -> - | I29: ='Main CEA'!I29 -> 844912.52 | J29: ='Main CEA'!J29 -> 561669.63 | K29: ='Main CEA'!K29 -> 793380.72 | L29: ='Main CEA'!L29 -> 793380.72 | M29: ='Main CEA'!M29 -> 630759.1 | N29: ='Main CEA'!N29 -> 793380.72 | O29: ='Main CEA'!O29 -> 617920.24 | ... AJ29: ='Main CEA'!AJ29 -> 428571.43
A31: Counterfactual funding scenarios
C33: Probability of scenarios in the absence of philanthropic funding
E34: Scenario 1: Domestic governments would replace the grantee's costs | F34: =Inputs!F193 -> % | G34: =Inputs!G193 -> input | H34: =Inputs!H193 -> - | I34: =Inputs!I193 -> 0.1 | J34: =Inputs!J193 -> 0.05 | K34: =Inputs!K193 -> 0.1 | L34: =Inputs!L193 -> 0.1 | M34: =Inputs!M193 -> 0.1 | ... AJ34: =Inputs!AJ193 -> 0.1
E35: Scenario 2: Other philanthropic actors would replace the grantee's costs | F35: =Inputs!F194 -> % | G35: =Inputs!G194 -> input | H35: =Inputs!H194 -> - | I35: =Inputs!I194 -> 0.2 | J35: =Inputs!J194 -> 0.33 | K35: =Inputs!K194 -> 0.35 | L35: =Inputs!L194 -> 0.1 | M35: =Inputs!M194 -> 0.35 | ... AJ35: =Inputs!AJ194 -> 0.3
E36: Scenario 3: Other actors' upstream costs would stay the same (downstream costs would shrink in proportion to the total size of the program) | F36: =Inputs!F195 -> % | G36: =Inputs!G195 -> input | H36: =Inputs!H195 -> - | I36: =Inputs!I195 -> 0.7 | J36: =Inputs!J195 -> 0.62 | K36: =Inputs!K195 -> 0.55 | L36: =Inputs!L195 -> 0.8 | M36: =Inputs!M195 -> 0.55 | ... AJ36: =Inputs!AJ195 -> 0.6
E37: Scenario 4: Distributions would go unfunded | F37: % | G37: calc | H37: - | I37: =1-SUM(I34:I36) -> 0 | J37: =1-SUM(J34:J36) -> 0 | K37: =1-SUM(K34:K36) -> 0 | L37: =1-SUM(L34:L36) -> 0 | M37: =1-SUM(M34:M36) -> 0 | N37: =1-SUM(N34:N36) -> 0 | O37: =1-SUM(O34:O36) -> 0 | P37: =1-SUM(P34:P36) -> 0 | ... AJ37: =1-SUM(AJ34:AJ36) -> 0
C39: Proportion of the program that would still occur in each scenario
E40: Scenario 1: Domestic governments would replace the grantee's costs | F40: =Inputs!F198 -> % | G40: =Inputs!G198 -> input | H40: =Inputs!H198 -> 1 | I40: =Inputs!I198 -> - | J40: =Inputs!J198 -> - | K40: =Inputs!K198 -> - | L40: =Inputs!L198 -> - | M40: =Inputs!M198 -> - | ... AJ40: =Inputs!AJ198 -> -
E41: Scenario 2: Other philanthropic actors would replace the grantee's costs | F41: =Inputs!F199 -> % | G41: =Inputs!G199 -> input | H41: =Inputs!H199 -> 1 | I41: =Inputs!I199 -> - | J41: =Inputs!J199 -> - | K41: =Inputs!K199 -> - | L41: =Inputs!L199 -> - | M41: =Inputs!M199 -> - | ... AJ41: =Inputs!AJ199 -> -
E42: Scenario 3: Other actors' upstream costs would stay the same (downstream costs would shrink in proportion to the total size of the program) | F42: % | G42: calc | H42: - | I42: =SUM(I23:I24)/I28 -> 0.32200158 | J42: =SUM(J23:J24)/J28 -> 0 | K42: =SUM(K23:K24)/K28 -> 0.2606756 | L42: =SUM(L23:L24)/L28 -> 0.2606756 | M42: =SUM(M23:M24)/M28 -> 0.15133629 | N42: =SUM(N23:N24)/N28 -> 0.2606756 | O42: =SUM(O23:O24)/O28 -> 0.050742021 | P42: =SUM(P23:P24)/P28 -> 0.29727871 | ... AJ42: =SUM(AJ23:AJ24)/AJ28 -> 0
E43: Scenario 4: Distributions would go unfunded | F43: =Inputs!F200 -> % | G43: =Inputs!G200 -> input | H43: =Inputs!H200 -> 0 | I43: =Inputs!I200 -> - | J43: =Inputs!J200 -> - | K43: =Inputs!K200 -> - | L43: =Inputs!L200 -> - | M43: =Inputs!M200 -> - | ... AJ43: =Inputs!AJ200 -> -
A45: Value of spending
C47: Cost-effectiveness of the program (before leverage and funging)
E48: Units of value generated per dollar spent (before final adjustments) | F48: ='Main CEA'!F93 -> UoV | G48: main | H48: ='Main CEA'!H93 -> - | I48: ='Main CEA'!I93 -> 0.081810521 | J48: ='Main CEA'!J93 -> 0.062659406 | K48: ='Main CEA'!K93 -> 0.035403361 | L48: ='Main CEA'!L93 -> 0.054875268 | M48: ='Main CEA'!M93 -> 0.046344013 | N48: ='Main CEA'!N93 -> 0.018989343 | O48: ='Main CEA'!O93 -> 0.05394946 | ... AJ48: ='Main CEA'!AJ93 -> 0.026496545
E49: Total supplemental grantee-level adjustment | F49: ='Main CEA'!F121 -> % | G49: main | H49: ='Main CEA'!H121 -> - | I49: ='Main CEA'!I121 -> -0.22 | J49: ='Main CEA'!J121 -> -0.22 | K49: ='Main CEA'!K121 -> -0.22 | L49: ='Main CEA'!L121 -> -0.22 | M49: ='Main CEA'!M121 -> -0.22 | N49: ='Main CEA'!N121 -> -0.22 | O49: ='Main CEA'!O121 -> -0.22 | ... AJ49: ='Main CEA'!AJ121 -> -0.24
E50: Total supplemental intervention-level adjustment | F50: ='Main CEA'!F135 -> % | G50: main | H50: ='Main CEA'!H135 -> - | I50: ='Main CEA'!I135 -> 0.665 | J50: ='Main CEA'!J135 -> 0.665 | K50: ='Main CEA'!K135 -> 0.665 | L50: ='Main CEA'!L135 -> 0.665 | M50: ='Main CEA'!M135 -> 0.665 | N50: ='Main CEA'!N135 -> 0.665 | O50: ='Main CEA'!O135 -> 0.665 | ... AJ50: ='Main CEA'!AJ135 -> 0.665
...

Sheet Inputs
I1: Helen Keller International | Q1: Helen Keller International | Y1: Helen Keller International | AG1: Nutrition International
I2: Burkina Faso | J2: Cameroon | K2: Côte d'Ivoire | L2: DRC | M2: Guinea | N2: Kenya | O2: Madagascar | P2: Mali | Q2: Niger | R2: Nigeria | S2: Nigeria | T2: Nigeria | U2: Nigeria | V2: Nigeria | W2: Nigeria | X2: Nigeria | Y2: Nigeria | Z2: Nigeria | AA2: Nigeria | AB2: Nigeria | AC2: Nigeria | AD2: Nigeria | AE2: Nigeria | AF2: Nigeria | AG2: Angola | AH2: Chad | AI2: Togo | AJ2: Uganda
A3: Inputs | F3: unit | G3: type | H3: Overall | R3: Adamawa | S3: Akwa Ibom | T3: Anambra | U3: Benue | V3: Delta | W3: Ebonyi | X3: Edo | Y3: Ekiti | Z3: Imo | AA3: Kogi | AB3: Nasarawa | AC3: Ogun | AD3: Osun | AE3: Rivers | AF3: Taraba | AL3: Source | AM3: GW analysis and discussion
E4: Final cost-effectiveness estimate (pulled from "Main calcs" sheet for visibility) | F4: ='Main CEA'!F149 -> xbenchmark | G4: main | H4: ='Main CEA'!H149 -> - | I4: ='Main CEA'!I149 -> 22.604158 | J4: ='Main CEA'!J149 -> 15.907951 | K4: ='Main CEA'!K149 -> 8.5391703 | L4: ='Main CEA'!L149 -> 16.914533 | M4: ='Main CEA'!M149 -> 10.932207 | N4: ='Main CEA'!N149 -> 4.7974496 | O4: ='Main CEA'!O149 -> 15.912911 | ... AJ4: ='Main CEA'!AJ149 -> 6.3105992
A5: Costs
C7: GiveWell costs
E8: Grant size | F8: $ | G8: input | H8: 1000000 | I8: - | J8: - | K8: - | L8: - | M8: - | N8: - | O8: - | P8: - | Q8: - | R8: - | S8: - | T8: - | U8: - | V8: - | W8: - | X8: - | Y8: - | Z8: - | AA8: - | AB8: - | AC8: - | AD8: - | AE8: - | AF8: - | AG8: - | AH8: - | AI8: - | AJ8: - | AL8: Arbitrary value
C10: Cost breakdown
E11: Percentage of total costs covered by the grantee | F11: % | G11: input | H11: - | I11: 0.4310638 | J11: 0.6403403 | K11: 0.4659904 | L11: 0.4659904 | M11: 0.5527665 | N11: 0.4659904 | O11: 0.5983099 | P11: 0.4324667 | Q11: 0.3616872 | R11: 0.4659904 | S11: 0.4659904 | T11: 0.4659904 | U11: 0.4659904 | V11: 0.4659904 | W11: 0.4659904 | X11: 0.4659904 | Y11: 0.4659904 | Z11: 0.4659904 | AA11: 0.4659904 | AB11: 0.4659904 | AC11: 0.4659904 | AD11: 0.4659904 | AE11: 0.4659904 | AF11: 0.4659904 | AG11: 0.7 | AH11: 0.7 | AI11: 0.7 | AJ11: 0.7 | AL11: GW analysis | AM11: GiveWell's analysis of Helen Keller International's cost per supplement
E12: Percentage of total costs covered by Nutrition International (vitamin A capsule procurement) | F12: % | G12: input | H12: - | I12: 0.0642112 | J12: 0.0596597 | K12: 0.0697078 | L12: 0.0697078 | M12: 0.0486625 | N12: 0.0697078 | O12: 0.0697078 | P12: 0.0845829 | Q12: 0.078881 | R12: 0.0697078 | S12: 0.0697078 | T12: 0.0697078 | U12: 0.0697078 | V12: 0.0697078 | W12: 0.0697078 | X12: 0.0697078 | Y12: 0.0697078 | Z12: 0.0697078 | AA12: 0.0697078 | AB12: 0.0697078 | AC12: 0.0697078 | AD12: 0.0697078 | AE12: 0.0697078 | AF12: 0.0697078 | AG12: 0 | AH12: 0 | AI12: 0 | AJ12: 0 | AL12: GW analysis | AM12: GiveWell's analysis of Helen Keller International's cost per supplement
E13: Percentage of total costs covered by other philanthropic actors | F13: % | G13: input | H13: - | I13: 0.0565391 | J13: 0 | K13: 0.1323195 | L13: 0.1323195 | M13: 0.098571 | N13: 0.1323195 | O13: 0 | P13: 0.1829504 | Q13: 0.2594317 | R13: 0.1323195 | S13: 0.1323195 | T13: 0.1323195 | U13: 0.1323195 | V13: 0.1323195 | W13: 0.1323195 | X13: 0.1323195 | Y13: 0.1323195 | Z13: 0.1323195 | AA13: 0.1323195 | AB13: 0.1323195 | AC13: 0.1323195 | AD13: 0.1323195 | AE13: 0.1323195 | AF13: 0.1323195 | AG13: 0 | AH13: 0 | AI13: 0 | AJ13: 0 | AL13: GW analysis | AM13: GiveWell's analysis of Helen Keller International's cost per supplement
E14: Percentage of total costs covered by domestic governments (financial contributions) | F14: % | G14: input | H14: - | I14: 0.1481859 | J14: 0 | K14: 0.0319823 | L14: 0.0319823 | M14: 0 | N14: 0.0319823 | O14: 0.0319823 | P14: 0 | Q14: 0 | R14: 0.0319823 | S14: 0.0319823 | T14: 0.0319823 | U14: 0.0319823 | V14: 0.0319823 | W14: 0.0319823 | X14: 0.0319823 | Y14: 0.0319823 | Z14: 0.0319823 | AA14: 0.0319823 | AB14: 0.0319823 | AC14: 0.0319823 | AD14: 0.0319823 | AE14: 0.0319823 | AF14: 0.0319823 | AG14: 0 | AH14: 0 | AI14: 0 | AJ14: 0 | AL14: GW analysis | AM14: GiveWell's analysis of Helen Keller International's cost per supplement
E15: Percentage of total costs covered by domestic governments (in-kind contributions) | F15: % | G15: input | H15: - | I15: 0.3 | J15: 0.3 | K15: 0.3 | L15: 0.3 | M15: 0.3 | N15: 0.3 | O15: 0.3 | P15: 0.3 | Q15: 0.3 | R15: 0.3 | S15: 0.3 | T15: 0.3 | U15: 0.3 | V15: 0.3 | W15: 0.3 | X15: 0.3 | Y15: 0.3 | Z15: 0.3 | AA15: 0.3 | AB15: 0.3 | AC15: 0.3 | AD15: 0.3 | AE15: 0.3 | AF15: 0.3 | AG15: 0.3 | AH15: 0.3 | AI15: 0.3 | AJ15: 0.3 | AL15: GW analysis | AM15: GiveWell's analysis of Helen Keller International's cost per supplement
C17: Cost per child covered
E18: Cost per vitamin A supplement delivered | F18: $ | G18: input | H18: - | I18: 1.05602 | J18: 1.13658 | K18: 1.01732 | L18: 1.01732 | M18: 1.39344 | N18: 1.01732 | O18: 1.01732 | P18: 0.80168 | Q18: 0.85963 | R18: 1.01732 | S18: 1.01732 | T18: 1.01732 | U18: 1.01732 | V18: 1.01732 | W18: 1.01732 | X18: 1.01732 | Y18: 1.01732 | Z18: 1.01732 | AA18: 1.01732 | AB18: 1.01732 | AC18: 1.01732 | AD18: 1.01732 | AE18: 1.01732 | AF18: 1.01732 | AG18: =AJ18*1.5 -> 1.52598 | AH18: =AJ18*1.5 -> 1.52598 | AI18: 1.0895 | AJ18: 1.01732 | AL18: GW analysis | AM18: GiveWell's analysis of Helen Keller International's cost per supplement
E19: Supplementation rounds delivered per year | F19: # | G19: input | H19: 2 | I19: - | J19: - | K19: - | L19: - | M19: - | N19: - | O19: - | P19: - | Q19: - | R19: - | S19: - | T19: - | U19: - | V19: - | W19: - | X19: - | Y19: - | Z19: - | AA19: - | AB19: - | AC19: - | AD19: - | AE19: - | AF19: - | AG19: - | AH19: - | AI19: - | AJ19: - | AL19: Helen Keller International
A21: Counterfactual mortality
C23: Mortalities per year among people under five
E24: Total mortalities per year among people under age 5 | F24: # | G24: input | H24: - | I24: =IFERROR(__xludf.DUMMYFUNCTION("FILTER('GBD estimates'!$I$4:$I$1203,'GBD estimates'!$C$4:$C$1203=I$2,'GBD estimates'!$F$4:$F$1203=""All causes"",'GBD estimates'!$E$4:$E$1203=""<5 years"")"),98779.14033) -> 98779.14 | J24: =IFERROR(__xludf.DUMMYFUNCTION("FILTER('GBD estimates'!$I$4:$I$1203,'GBD estimates'!$C$4:$C$1203=J$2,'GBD estimates'!$F$4:$F$1203=""All causes"",'GBD estimates'!$E$4:$E$1203=""<5 years"")"),64035.00739) -> 64035.007 | K24: =IFERROR(__xludf.DUMMYFUNCTION("FILTER('GBD estimates'!$I$4:$I$1203,'GBD estimates'!$C$4:$C$1203=K$2,'GBD estimates'!$F$4:$F$1203=""All causes"",'GBD estimates'!$E$4:$E$1203=""<5 years"")"),64816.60409) -> 64816.604 | L24: =IFERROR(__xludf.DUMMYFUNCTION("FILTER('GBD estimates'!$I$4:$I$1203,'GBD estimates'!$C$4:$C$1203=L$2,'GBD estimates'!$F$4:$F$1203=""All causes"",'GBD estimates'!$E$4:$E$1203=""<5 years"")"),168468.4512) -> 168468.45 | M24: =IFERROR(__xludf.DUMMYFUNCTION("FILTER('GBD estimates'!$I$4:$I$1203,'GBD estimates'!$C$4:$C$1203=M$2,'GBD estimates'!$F$4:$F$1203=""All causes"",'GBD estimates'!$E$4:$E$1203=""<5 years"")"),45406.17471) -> 45406.175 | N24: =IFERROR(__xludf.DUMMYFUNCTION("FILTER('GBD estimates'!$I$4:$I$1203,'GBD estimates'!$C$4:$C$1203=N$2,'GBD estimates'!$F$4:$F$1203=""All causes"",'GBD estimates'!$E$4:$E$1203=""<5 years"")"),53344.7099) -> 53344.71 | O24: =IFERROR(__xludf.DUMMYFUNCTION("FILTER('GBD estimates'!$I$4:$I$1203,'GBD estimates'!$C$4:$C$1203=O$2,'GBD estimates'!$F$4:$F$1203=""All causes"",'GBD estimates'!$E$4:$E$1203=""<5 years"")"),48156.10418) -> 48156.104 | P24: =IFERROR(__xludf.DUMMYFUNCTION("FILTER('GBD estimates'!$I$4:$I$1203,'GBD estimates'!$C$4:$C$1203=P$2,'GBD estimates'!$F$4:$F$1203=""All causes"",'GBD estimates'!$E$4:$E$1203=""<5 years"")"),109642.6225) -> 109642.62 | Q24: =IFERROR(__xludf.DUMMYFUNCTION("FILTER('GBD estimates'!$I$4:$I$1203,'GBD estimates'!$C$4:$C$1203=Q$2,'GBD estimates'!$F$4:$F$1203=""All causes"",'GBD estimates'!$E$4:$E$1203=""<5 years"")"),120216.7235) -> 120216.72 | R24: =IFERROR(__xludf.DUMMYFUNCTION("FILTER('GBD estimates'!$AF$4:$AF$1203,'GBD estimates'!$AA$4:$AA$1203=R$3,'GBD estimates'!$X$4:$X$1203=""All causes"",'GBD estimates'!$Z$4:$Z$1203=""Under 5"")"),13907.73873) -> 13907.739 | S24: =IFERROR(__xludf.DUMMYFUNCTION("FILTER('GBD estimates'!$AF$4:$AF$1203,'GBD estimates'!$AA$4:$AA$1203=S$3,'GBD estimates'!$X$4:$X$1203=""All causes"",'GBD estimates'!$Z$4:$Z$1203=""Under 5"")"),3462.225164) -> 3462.2252 | T24: =IFERROR(__xludf.DUMMYFUNCTION("FILTER('GBD estimates'!$AF$4:$AF$1203,'GBD estimates'!$AA$4:$AA$1203=T$3,'GBD estimates'!$X$4:$X$1203=""All causes"",'GBD estimates'!$Z$4:$Z$1203=""Under 5"")"),7871.751135) -> 7871.7511 | U24: =IFERROR(__xludf.DUMMYFUNCTION("FILTER('GBD estimates'!$AF$4:$AF$1203,'GBD estimates'!$AA$4:$AA$1203=U$3,'GBD estimates'!$X$4:$X$1203=""All causes"",'GBD estimates'!$Z$4:$Z$1203=""Under 5"")"),26884.78566) -> 26884.786 | V24: =IFERROR(__xludf.DUMMYFUNCTION("FILTER('GBD estimates'!$AF$4:$AF$1203,'GBD estimates'!$AA$4:$AA$1203=V$3,'GBD estimates'!$X$4:$X$1203=""All causes"",'GBD estimates'!$Z$4:$Z$1203=""Under 5"")"),7861.21423) -> 7861.2142 | W24: =IFERROR(__xludf.DUMMYFUNCTION("FILTER('GBD estimates'!$AF$4:$AF$1203,'GBD estimates'!$AA$4:$AA$1203=W$3,'GBD estimates'!$X$4:$X$1203=""All causes"",'GBD estimates'!$Z$4:$Z$1203=""Under 5"")"),7938.591477) -> 7938.5915 | X24: =IFERROR(__xludf.DUMMYFUNCTION("FILTER('GBD estimates'!$AF$4:$AF$1203,'GBD estimates'!$AA$4:$AA$1203=X$3,'GBD estimates'!$X$4:$X$1203=""All causes"",'GBD estimates'!$Z$4:$Z$1203=""Under 5"")"),5408.39386) -> 5408.3939 | Y24: =IFERROR(__xludf.DUMMYFUNCTION("FILTER('GBD estimates'!$AF$4:$AF$1203,'GBD estimates'!$AA$4:$AA$1203=Y$3,'GBD estimates'!$X$4:$X$1203=""All causes"",'GBD estimates'!$Z$4:$Z$1203=""Under 5"")"),2631.649859) -> 2631.6499 | Z24: =IFERROR(__xludf.DUMMYFUNCTION("FILTER('GBD estimates'!$AF$4:$AF$1203,'GBD estimates'!$AA$4:$AA$1203=Z$3,'GBD estimates'!$X$4:$X$1203=""All causes"",'GBD estimates'!$Z$4:$Z$1203=""Under 5"")"),11380.79524) -> 11380.795 | AA24: =IFERROR(__xludf.DUMMYFUNCTION("FILTER('GBD estimates'!$AF$4:$AF$1203,'GBD estimates'!$AA$4:$AA$1203=AA$3,'GBD estimates'!$X$4:$X$1203=""All causes"",'GBD estimates'!$Z$4:$Z$1203=""Under 5"")"),3662.544731) -> 3662.5447 | AB24: =IFERROR(__xludf.DUMMYFUNCTION("FILTER('GBD estimates'!$AF$4:$AF$1203,'GBD estimates'!$AA$4:$AA$1203=AB$3,'GBD estimates'!$X$4:$X$1203=""All causes"",'GBD estimates'!$Z$4:$Z$1203=""Under 5"")"),13333.45365) -> 13333.454 | AC24: =IFERROR(__xludf.DUMMYFUNCTION("FILTER('GBD estimates'!$AF$4:$AF$1203,'GBD estimates'!$AA$4:$AA$1203=AC$3,'GBD estimates'!$X$4:$X$1203=""All causes"",'GBD estimates'!$Z$4:$Z$1203=""Under 5"")"),20448.01213) -> 20448.012 | AD24: =IFERROR(__xludf.DUMMYFUNCTION("FILTER('GBD estimates'!$AF$4:$AF$1203,'GBD estimates'!$AA$4:$AA$1203=AD$3,'GBD estimates'!$X$4:$X$1203=""All causes"",'GBD estimates'!$Z$4:$Z$1203=""Under 5"")"),4522.234854) -> 4522.2349 | AE24: =IFERROR(__xludf.DUMMYFUNCTION("FILTER('GBD estimates'!$AF$4:$AF$1203,'GBD estimates'!$AA$4:$AA$1203=AE$3,'GBD estimates'!$X$4:$X$1203=""All causes"",'GBD estimates'!$Z$4:$Z$1203=""Under 5"")"),6707.239581) -> 6707.2396 | AF24: =IFERROR(__xludf.DUMMYFUNCTION("FILTER('GBD estimates'!$AF$4:$AF$1203,'GBD estimates'!$AA$4:$AA$1203=AF$3,'GBD estimates'!$X$4:$X$1203=""All causes"",'GBD estimates'!$Z$4:$Z$1203=""Under 5"")"),34193.94716) -> 34193.947 | AG24: =IFERROR(__xludf.DUMMYFUNCTION("FILTER('GBD estimates'!$I$4:$I$1203,'GBD estimates'!$C$4:$C$1203=AG$2,'GBD estimates'!$F$4:$F$1203=""All causes"",'GBD estimates'!$E$4:$E$1203=""<5 years"")"),58764.73414) -> 58764.734 | AH24: =IFERROR(__xludf.DUMMYFUNCTION("FILTER('GBD estimates'!$I$4:$I$1203,'GBD estimates'!$C$4:$C$1203=AH$2,'GBD estimates'!$F$4:$F$1203=""All causes"",'GBD estimates'!$E$4:$E$1203=""<5 years"")"),85575.12265) -> 85575.123 | AI24: =IFERROR(__xludf.DUMMYFUNCTION("FILTER('GBD estimates'!$I$4:$I$1203,'GBD estimates'!$C$4:$C$1203=AI$2,'GBD estimates'!$F$4:$F$1203=""All causes"",'GBD estimates'!$E$4:$E$1203=""<5 years"")"),15010.42875) -> 15010.429 | AJ24: =IFERROR(__xludf.DUMMYFUNCTION("FILTER('GBD estimates'!$I$4:$I$1203,'GBD estimates'!$C$4:$C$1203=AJ$2,'GBD estimates'!$F$4:$F$1203=""All causes"",'GBD estimates'!$E$4:$E$1203=""<5 years"")"),91702.41553) -> 91702.416 | AL24: GBD 2019
