Workbook

Sheet Key
A1: Guide to interpreting this cost-effectiveness analysis
A2: Sheet descriptions
E4: Main CEA | F4: This sheet contains the primary calculations that result in final cost-effectiveness estimates. This sheet draws on inputs from the "Inputs" sheet and inputs calculated in the other supplemental sheets listed below.
E5: Counterfactual malaria | F5: This sheet contains our calculations of how high malaria mortality and prevalence rates would be in the absence of SMC campaigns.
E6: Leverage/Funging | F6: This sheet contains our calculations of the impact that crowding in and crowding out funding by other contributors has on the benefits of the program.
E7: Inputs | F7: This sheet contains all of the manually entered input values informing the CEA, along with the sources and reasoning supporting them. This sheet also contains inputs sourced from the "GBD estimates" sheet.
E8: GBD estimates | F8: This sheet contains disease burden and population datasets downloaded from the Institute of Health Metrics (IHME)'s Global Burden of Disease (GBD) project.
E9: Simple CEA | F9: This sheet contains a simplified version of the CEA that is designed to be comparable to our CEAs of other programs.
E10: Sensitivity analysis | F10: This sheet contains the outputs of a sensitivity analysis macro that tests the cost-effectiveness ranges that would result from updating certain inputs to their 25th or 75th percentile values.
A12: Terminology key
C14: Terms specific to this CEA
E15: SMC season | F15: The part of the year when SMC is delivered because malaria transmission is highest. In locations where GiveWell currently supports SMC, this is either four or five months each year.
E16: SMC cycle | F16: Refers to a monthly SMC treatment cycle, which consists of a three-day treatment regimen of SMC medication that provides protection from malaria for one month.
E17: SMC round | F17: Refers to a year's worth of SMC cycles, which are typically delievered over a period of four to five consecutive months during the rainy season.
E18: Sahel | F18: A subregion of Africa where malaria transmission tends to be highly seasonal. Historically, SMC was only delivered at large scale within the Sahel. Since 2020-21, SMC is now being piloted in locations outside the Sahel.
E19: Malaria-attributable mortality | F19: Deaths that could be averted by SMC, either directly (because they are malaria deaths) or indirectly (because malaria indirectly increases the risk of death from other causes).
E20: Indirect malaria deaths | F20: Deaths in which malaria plays a causal role, but are attributed to another cause. For example, malaria may increase the likelihood of death from malnutrition or other infectious diseases. Malaria control interventions often have a larger effect on all-cause mortality than would be expected exclusively from declines in malaria-specific mortality, which we interpret as evidence that averting malaria may also avert deaths attributed to other causes.
C22: Terms used across GiveWell's CEAs
E23: Internal validity | F23: Describes an adjustment we make to the treatment effect of an intervention to account for the possibility that the treatment effects found in studies may not represent the true effect the intervention had on the populations studied.
E24: External validity | F24: Describes an adjustment we make to the treatment effect of an intervention to account for differences in the program implementation or populations treated in studies from the program implementation or populations treated by grantee programs.
E25: Leverage | F25: Describes a situation where a grantee's spending on a program causes other organizations or governments to contribute more to the program than they otherwise would have. In most cases, accounting for leverage increases cost-effectiveness
E26: Funging | F26: Describes a situation where a grantee's spending on a program causes other organizations or governments to contribute less to the program than they otherwise would have. In most cases, accounting for funging decreases cost-effectiveness.
E27: Counterfactual | F27: In most cases, describes the state of the world that would exist if we did not provide funding to a grantee for a program. When discussing the "counterfactual value of other actors' spending," we are referring to how much benefit another organization's or government's spending would generate if it were spent on something other than the grantee program.
E28: Moral weights | F28: To compare cost-effectiveness across different programs, we use ‘moral weights’ to quantify the benefits of different program impacts (e.g. increased income vs reduced deaths). We benchmark the value of each benefit to a value of 1, which we define as the value of doubling someone’s consumption for one year.
E29: Philanthropic actors | F29: Non-governmental organizations (NGOs) providing funding to philanthropic programs.
A31: Unit and source key
C33: Unit labels used in the CEA
E34: # | F34: Number
E35: per 1k | F35: Rate per 1,000
E36: per 100k | F36: Rate per 100,000
E37: $ | F37: U.S. dollars
E38: ln($) | F38: The natural logarithm of a monetary value
E39: % | F39: Percentage
E40: ppt | F40: Percentage points
E41: UoV | F41: Units of value: an arbitrary unit GiveWell uses to compare the moral value of different types of outcomes, such as saving lives or increasing income
E42: xbenchmark | F42: Cost-effectiveness in terms of multiples of GiveWell's benchmark
C44: Source labels used in the CEA
E46: input | F46: A value pulled from the "Inputs" sheet
E47: calc | F47: A value calculated using other values in the same sheet
E48: supp | F48: A value pulled from one of the sheets hosting supplemental calculations
...

Sheet Main CEA
I1: Malaria Consortium | R1: Malaria Consortium
I2: Burkina Faso | J2: Chad | K2: DRC | L2: DRC | M2: DRC | N2: DRC | O2: Mozambique | P2: Nigeria | Q2: Nigeria | R2: Nigeria | S2: Nigeria | T2: Nigeria | U2: Nigeria | V2: Nigeria | W2: Nigeria | X2: Nigeria | Y2: Togo | Z2: Uganda
A3: Main calculations | F3: unit | G3: type | H3: Overall | K3: Haut-Katanga | L3: Haut-Lomami | M3: Lualaba | N3: Tanganyika | O3: Nampula | P3: Bauchi | Q3: Borno | R3: FCT (Abuja) | S3: Kebbi | T3: Kogi | U3: Nasarawa | V3: Oyo | W3: Plateau | X3: Sokoto | Z3: Karamoja
E4: Final cost-effectiveness estimate (pulled from below for visibility) | F4: =F191 -> xbenchmark | G4: feed | H4: =H191 -> - | I4: =I191 -> 18.017467 | J4: =J191 -> 8.0191284 | K4: =K191 -> 7.8521256 | L4: =L191 -> 9.2460297 | M4: =M191 -> 9.1012718 | N4: =N191 -> 12.57331 | O4: =O191 -> 11.495836 | ... Z4: =Z191 -> 10.360783
A5: Costs
C7: GiveWell costs
E8: Grant size | F8: =Inputs!F8 -> $ | G8: =Inputs!G8 -> input | H8: =Inputs!H8 -> 1000000 | I8: =Inputs!I8 -> - | J8: =Inputs!J8 -> - | K8: =Inputs!K8 -> - | L8: =Inputs!L8 -> - | M8: =Inputs!M8 -> - | ... Z8: =Inputs!Z8 -> -
C10: Cost breakdown
E11: Percentage of total costs covered by the grantee | F11: =Inputs!F11 -> % | G11: =Inputs!G11 -> input | H11: =Inputs!H11 -> - | I11: =Inputs!I11 -> 0.8872139 | J11: =Inputs!J11 -> 0.8943595 | K11: =Inputs!K11 -> 0.8943595 | L11: =Inputs!L11 -> 0.8943595 | M11: =Inputs!M11 -> 0.8943595 | ... Z11: =Inputs!Z11 -> 0.8943595
E12: Percentage of total costs covered by other philanthropic actors | F12: =Inputs!F12 -> % | G12: =Inputs!G12 -> input | H12: =Inputs!H12 -> - | I12: =Inputs!I12 -> 0.0081278 | J12: =Inputs!J12 -> 0 | K12: =Inputs!K12 -> 0 | L12: =Inputs!L12 -> 0 | M12: =Inputs!M12 -> 0 | ... Z12: =Inputs!Z12 -> 0
E13: Percentage of total costs covered by domestic governments | F13: =Inputs!F13 -> % | G13: =Inputs!G13 -> input | H13: =Inputs!H13 -> - | I13: =Inputs!I13 -> 0.1046583 | J13: =Inputs!J13 -> 0.1056405 | K13: =Inputs!K13 -> 0.1056405 | L13: =Inputs!L13 -> 0.1056405 | M13: =Inputs!M13 -> 0.1056405 | ... Z13: =Inputs!Z13 -> 0.1056405
C15: Total costs
E16: Total spending by all contributors | F16: $ | G16: calc | H16: - | I16: =IF(I8="-",$H8/I11,I8/I11) -> 1127123.9 | J16: =IF(J8="-",$H8/J11,J8/J11) -> 1118118.6 | K16: =IF(K8="-",$H8/K11,K8/K11) -> 1118118.6 | L16: =IF(L8="-",$H8/L11,L8/L11) -> 1118118.6 | M16: =IF(M8="-",$H8/M11,M8/M11) -> 1118118.6 | N16: =IF(N8="-",$H8/N11,N8/N11) -> 1118118.6 | O16: =IF(O8="-",$H8/O11,O8/O11) -> 1118118.6 | P16: =IF(P8="-",$H8/P11,P8/P11) -> 1162184.7 | ... Z16: =IF(Z8="-",$H8/Z11,Z8/Z11) -> 1118118.6
C18: Total spending attributable to different actors
E19: Total spending contributed by grantee | F19: $ | G19: calc | H19: - | I19: =I$16*I11 -> 1000000 | J19: =J$16*J11 -> 1000000 | K19: =K$16*K11 -> 1000000 | L19: =L$16*L11 -> 1000000 | M19: =M$16*M11 -> 1000000 | N19: =N$16*N11 -> 1000000 | O19: =O$16*O11 -> 1000000 | P19: =P$16*P11 -> 1000000 | ... Z19: =Z$16*Z11 -> 1000000
E20: Total spending contributed by other philanthropic actors | F20: $ | G20: calc | H20: - | I20: =I$16*I12 -> 9161.0377 | J20: =J$16*J12 -> 0 | K20: =K$16*K12 -> 0 | L20: =L$16*L12 -> 0 | M20: =M$16*M12 -> 0 | N20: =N$16*N12 -> 0 | O20: =O$16*O12 -> 0 | P20: =P$16*P12 -> 44631.497 | ... Z20: =Z$16*Z12 -> 0
E21: Total spending contributed by domestic governments | F21: $ | G21: calc | H21: - | I21: =I$16*I13 -> 117962.87 | J21: =J$16*J13 -> 118118.61 | K21: =K$16*K13 -> 118118.61 | L21: =L$16*L13 -> 118118.61 | M21: =M$16*M13 -> 118118.61 | N21: =N$16*N13 -> 118118.61 | O21: =O$16*O13 -> 118118.61 | P21: =P$16*P13 -> 117553.24 | ... Z21: =Z$16*Z13 -> 118118.61
C23: Upstream / downstream spending
E24: Total spending causally upstream of donations to grantee | F24: $ | G24: calc | H24: - | I24: =SUM(I19:I20) -> 1009161 | J24: =SUM(J19:J20) -> 1000000 | K24: =SUM(K19:K20) -> 1000000 | L24: =SUM(L19:L20) -> 1000000 | M24: =SUM(M19:M20) -> 1000000 | N24: =SUM(N19:N20) -> 1000000 | O24: =SUM(O19:O20) -> 1000000 | P24: =SUM(P19:P20) -> 1044631.5 | ... Z24: =SUM(Z19:Z20) -> 1000000
E25: Total spending causally downstream of donations to grantee | F25: $ | G25: calc | H25: - | I25: =I21 -> 117962.87 | J25: =J21 -> 118118.61 | K25: =K21 -> 118118.61 | L25: =L21 -> 118118.61 | M25: =M21 -> 118118.61 | N25: =N21 -> 118118.61 | O25: =O21 -> 118118.61 | P25: =P21 -> 117553.24 | ... Z25: =Z21 -> 118118.61
C27: Cost per child covered
E28: Cost per seasonal malaria chemoprevention (SMC) cycle administered | F28: =Inputs!F16 -> $ | G28: =Inputs!G16 -> input | H28: =Inputs!H16 -> - | I28: =Inputs!I16 -> 1.47763 | J28: =Inputs!J16 -> 1.81008 | K28: =Inputs!K16 -> 1.81008 | L28: =Inputs!L16 -> 1.81008 | M28: =Inputs!M16 -> 1.81008 | ... Z28: =Inputs!Z16 -> 1.81008
E29: Number of SMC cycles per year | F29: =Inputs!F17 -> # | G29: =Inputs!G17 -> input | H29: =Inputs!H17 -> - | I29: =Inputs!I17 -> 4.3 | J29: =Inputs!J17 -> 4 | K29: =Inputs!K17 -> 4 | L29: =Inputs!L17 -> 4 | M29: =Inputs!M17 -> 4 | ... Z29: =Inputs!Z17 -> 5
E30: Total cost per child treated with all cycles of SMC in a year | F30: $ | G30: calc | H30: - | I30: =I28*I29 -> 6.353809 | J30: =J28*J29 -> 7.24032 | K30: =K28*K29 -> 7.24032 | L30: =L28*L29 -> 7.24032 | M30: =M28*M29 -> 7.24032 | N30: =N28*N29 -> 7.24032 | O30: =O28*O29 -> 7.24032 | P30: =P28*P29 -> 5.6102 | ... Z30: =Z28*Z29 -> 9.0504
E31: Upstream costs per child treated with all cycles of SMC in a year | F31: $ | G31: calc | H31: - | I31: =(I24/I16)*I30 -> 5.6888302 | J31: =(J24/J16)*J30 -> 6.475449 | K31: =(K24/K16)*K30 -> 6.475449 | L31: =(L24/L16)*L30 -> 6.475449 | M31: =(M24/M16)*M30 -> 6.475449 | N31: =(N24/N16)*N30 -> 6.475449 | O31: =(O24/O16)*O30 -> 6.475449 | P31: =(P24/P16)*P30 -> 5.0427367 | ... Z31: =(Z24/Z16)*Z30 -> 8.0943112
A33: Outputs
C35: Total children covered
E36: Total people under age 5 receiving a year of SMC | F36: # | G36: calc | H36: - | I36: =I19/I31 -> 175783.06 | J36: =J19/J31 -> 154429.45 | K36: =K19/K31 -> 154429.45 | L36: =L19/L31 -> 154429.45 | M36: =M19/M31 -> 154429.45 | N36: =N19/N31 -> 154429.45 | O36: =O19/O31 -> 154429.45 | P36: =P19/P31 -> 198305.02 | ... Z36: =Z19/Z31 -> 123543.56
A38: Outcomes
C40: Mortality reduction among people under age 5 (treated population)
E41: Reduction in malaria incidence for children under age 5 targeted for SMC found in GiveWell's adjusted version of the Meremikwu et al. 2012 meta-analysis | F41: =Inputs!F45 -> % | G41: =Inputs!G45 -> input | H41: =Inputs!H45 -> 0.75 | I41: =Inputs!I45 -> - | J41: =Inputs!J45 -> - | K41: =Inputs!K45 -> - | L41: =Inputs!L45 -> - | M41: =Inputs!M45 -> - | ... Z41: =Inputs!Z45 -> -
E42: Estimated proportion of children targeted for SMC in trials that received SMC | F42: =Inputs!F46 -> % | G42: =Inputs!G46 -> input | H42: =Inputs!H46 -> 0.8977 | I42: - | J42: - | K42: - | L42: - | M42: - | N42: - | O42: - | P42: - | Q42: - | R42: - | S42: - | T42: - | U42: - | V42: - | W42: - | X42: - | Y42: - | Z42: -
E43: Implied reduction in malaria incidence among children under age 5 receiving SMC | F43: % | G43: calc | H43: =H41/H42 -> 0.83546842 | I43: - | J43: - | K43: - | L43: - | M43: - | N43: - | O43: - | P43: - | Q43: - | R43: - | S43: - | T43: - | U43: - | V43: - | W43: - | X43: - | Y43: - | Z43: -
E44: Internal validity adjustment | F44: =Inputs!F47 -> % | G44: =Inputs!G47 -> input | H44: =Inputs!H47 -> -0.05 | I44: =Inputs!I47 -> - | J44: =Inputs!J47 -> - | K44: =Inputs!K47 -> - | L44: =Inputs!L47 -> - | M44: =Inputs!M47 -> - | ... Z44: =Inputs!Z47 -> -
E45: External validity adjustment | F45: =Inputs!F48 -> % | G45: =Inputs!G48 -> input | H45: =Inputs!H48 -> 0 | I45: =Inputs!I48 -> - | J45: =Inputs!J48 -> - | K45: =Inputs!K48 -> - | L45: =Inputs!L48 -> - | M45: =Inputs!M48 -> - | ... Z45: =Inputs!Z48 -> -
E46: Adjustment for lower effectiveness outside the Sahel region of Africa | F46: =Inputs!F49 -> % | G46: =Inputs!G49 -> input | H46: =Inputs!H49 -> - | I46: =Inputs!I49 -> 0 | J46: =Inputs!J49 -> 0 | K46: =Inputs!K49 -> -0.1955888 | L46: =Inputs!L49 -> -0.1955888 | M46: =Inputs!M49 -> -0.1955888 | ... Z46: =Inputs!Z49 -> -0.1955888
E47: Expected reduction in malaria incidence among children under age 5 receiving SMC | F47: % | G47: calc | H47: - | I47: =$H43*(1+$H44)*(1+$H45)*(1+I46) -> 0.793695 | J47: =$H43*(1+$H44)*(1+$H45)*(1+J46) -> 0.793695 | K47: =$H43*(1+$H44)*(1+$H45)*(1+K46) -> 0.63845715 | L47: =$H43*(1+$H44)*(1+$H45)*(1+L46) -> 0.63845715 | M47: =$H43*(1+$H44)*(1+$H45)*(1+M46) -> 0.63845715 | N47: =$H43*(1+$H44)*(1+$H45)*(1+N46) -> 0.63845715 | O47: =$H43*(1+$H44)*(1+$H45)*(1+O46) -> 0.63845715 | P47: =$H43*(1+$H44)*(1+$H45)*(1+P46) -> 0.793695 | ... Z47: =$H43*(1+$H44)*(1+$H45)*(1+Z46) -> 0.63845715
E48: Ratio of the reduction in malaria mortality to the reduction in malaria incidence | F48: =Inputs!F50 -> % | G48: =Inputs!G50 -> input | H48: =Inputs!H50 -> 1 | I48: =Inputs!I50 -> - | J48: =Inputs!J50 -> - | K48: =Inputs!K50 -> - | L48: =Inputs!L50 -> - | M48: =Inputs!M50 -> - | ... Z48: =Inputs!Z50 -> -
E49: Expected reduction in malaria mortality among children under age 5 receiving SMC | F49: % | G49: calc | H49: - | I49: =I47*$H48 -> 0.793695 | J49: =J47*$H48 -> 0.793695 | K49: =K47*$H48 -> 0.63845715 | L49: =L47*$H48 -> 0.63845715 | M49: =M47*$H48 -> 0.63845715 | N49: =N47*$H48 -> 0.63845715 | O49: =O47*$H48 -> 0.63845715 | P49: =P47*$H48 -> 0.793695 | ... Z49: =Z47*$H48 -> 0.63845715
E50: Annual malaria mortality rate among 3-59-month-olds | F50: ='Counterfactual malaria'!F30 -> % | G50: supp | H50: ='Counterfactual malaria'!H30 -> - | I50: ='Counterfactual malaria'!I30 -> 0.0038458826 | J50: ='Counterfactual malaria'!J30 -> 0.0012832309 | K50: ='Counterfactual malaria'!K30 -> 0.001839785 | L50: ='Counterfactual malaria'!L30 -> 0.0021782154 | M50: ='Counterfactual malaria'!M30 -> 0.0021631673 | N50: ='Counterfactual malaria'!N30 -> 0.0032525987 | O50: ='Counterfactual malaria'!O30 -> 0.0027758991 | ... Z50: ='Counterfactual malaria'!Z30 -> 0.0030891296
...

Sheet Counterfactual malaria
I1: Malaria Consortium | R1: Malaria Consortium
I2: Burkina Faso | J2: Chad | K2: DRC | L2: DRC | M2: DRC | N2: DRC | O2: Mozambique | P2: Nigeria | Q2: Nigeria | R2: Nigeria | S2: Nigeria | T2: Nigeria | U2: Nigeria | V2: Nigeria | W2: Nigeria | X2: Nigeria | Y2: Togo | Z2: Uganda
A3: Supplemental calculations for counterfactual malaria mortality and prevalence rates | H3: Overall | K3: Haut-Katanga | L3: Haut-Lomami | M3: Lualaba | N3: Tanganyika | O3: Nampula | P3: Bauchi | Q3: Borno | R3: FCT (Abuja) | S3: Kebbi | T3: Kogi | U3: Nasarawa | V3: Oyo | W3: Plateau | X3: Sokoto | Z3: Karamoja
E4: Final cost-effectiveness estimate (pulled from "Main calcs" sheet for visibility) | F4: ='Main CEA'!F191 -> xbenchmark | G4: main | H4: ='Main CEA'!H191 -> - | I4: ='Main CEA'!I191 -> 18.017467 | J4: ='Main CEA'!J191 -> 8.0191284 | K4: ='Main CEA'!K191 -> 7.8521256 | L4: ='Main CEA'!L191 -> 9.2460297 | M4: ='Main CEA'!M191 -> 9.1012718 | N4: ='Main CEA'!N191 -> 12.57331 | O4: ='Main CEA'!O191 -> 11.495836 | ... Z4: ='Main CEA'!Z191 -> 10.360783
A5: Malaria mortality among the SMC-eligible population
C7: Malaria mortalities per year among people under age 5
E8: Malaria mortalities per year among people under age 5 | F8: =Inputs!F22 -> # | G8: =Inputs!G22 -> input | H8: =Inputs!H22 -> - | I8: =Inputs!I22 -> 16395.369 | J8: =Inputs!J22 -> 4525.7324 | K8: =Inputs!K22 -> 4108.1367 | L8: =Inputs!L22 -> 3604.3863 | M8: =Inputs!M22 -> 1046.9126 | ... Z8: =Inputs!Z22 -> 3723.9932
E9: Early neonatal malaria mortalities per year (babies under 7 days old) | F9: =Inputs!F23 -> # | G9: =Inputs!G23 -> input | H9: =Inputs!H23 -> - | I9: =Inputs!I23 -> 0 | J9: =Inputs!J23 -> 0 | K9: =Inputs!K23 -> 0 | L9: =Inputs!L23 -> 0 | M9: =Inputs!M23 -> 0 | ... Z9: =Inputs!Z23 -> 0
E10: Late neonatal malaria mortalities per year (babies between 7 and 27 days old) | F10: =Inputs!F24 -> # | G10: =Inputs!G24 -> input | H10: =Inputs!H24 -> - | I10: =Inputs!I24 -> 683.0121 | J10: =Inputs!J24 -> 207.98591 | K10: =Inputs!K24 -> 288.24933 | L10: =Inputs!L24 -> 252.90345 | M10: =Inputs!M24 -> 73.45711 | ... Z10: =Inputs!Z24 -> 214.2493
E11: Post-neonatal malaria mortalities per year (babies between 28 and 364 days old) | F11: =Inputs!F25 -> # | G11: =Inputs!G25 -> input | H11: =Inputs!H25 -> - | I11: =Inputs!I25 -> 5135.6144 | J11: =Inputs!J25 -> 1402.4717 | K11: =Inputs!K25 -> 1632.3436 | L11: =Inputs!L25 -> 1432.1813 | M11: =Inputs!M25 -> 415.98445 | ... Z11: =Inputs!Z25 -> 1595.4637
C13: Estimated malaria mortalities per year among the SMC-eligible population
E14: Number of post-neonatal months of life in which children are under 1 year old | F14: =Inputs!F26 -> # | G14: =Inputs!G26 -> input | H14: =Inputs!H26 -> 11 | I14: =Inputs!I26 -> - | J14: =Inputs!J26 -> - | K14: =Inputs!K26 -> - | L14: =Inputs!L26 -> - | M14: =Inputs!M26 -> - | ... Z14: =Inputs!Z26 -> -
E15: Number of post-neonatal months of life in which children are under 3 months old | F15: =Inputs!F27 -> # | G15: =Inputs!G27 -> input | H15: =Inputs!H27 -> 2 | I15: =Inputs!I27 -> - | J15: =Inputs!J27 -> - | K15: =Inputs!K27 -> - | L15: =Inputs!L27 -> - | M15: =Inputs!M27 -> - | ... Z15: =Inputs!Z27 -> -
E16: Proportion of post-neonatal malaria mortalities that are among 1-2-month-olds | F16: % | G16: calc | H16: =H15/H14 -> 0.18181818 | I16: - | J16: - | K16: - | L16: - | M16: - | N16: - | O16: - | P16: - | Q16: - | R16: - | S16: - | T16: - | U16: - | V16: - | W16: - | X16: - | Y16: - | Z16: -
E17: Estimated malaria mortalities per year among 1-2-month-olds | F17: # | G17: calc | H17: - | I17: =I11*$H16 -> 933.74807 | J17: =J11*$H16 -> 254.99485 | K17: =K11*$H16 -> 296.78974 | L17: =L11*$H16 -> 260.39661 | M17: =M11*$H16 -> 75.633536 | N17: =N11*$H16 -> 271.0651 | O17: =O11*$H16 -> 285.45557 | P17: =P11*$H16 -> 93.475062 | ... Z17: =Z11*$H16 -> 290.08431
E18: Total malaria mortalities per year among 3-59-month-olds | F18: # | G18: calc | H18: - | I18: =I8-SUM(I9:I10,I17) -> 14778.609 | J18: =J8-SUM(J9:J10,J17) -> 4062.7517 | K18: =K8-SUM(K9:K10,K17) -> 3523.0976 | L18: =L8-SUM(L9:L10,L17) -> 3091.0862 | M18: =M8-SUM(M9:M10,M17) -> 897.82192 | N18: =N8-SUM(N9:N10,N17) -> 3217.7285 | O18: =O8-SUM(O9:O10,O17) -> 2601.9125 | P18: =P8-SUM(P9:P10,P17) -> 3422.5386 | ... Z18: =Z8-SUM(Z9:Z10,Z17) -> 3219.6596
E19: Proportion of malaria mortalities among people under age 5 that occur among 3-59-month-olds | F19: % | G19: calc | H19: - | I19: =I18/I8 -> 0.90138922 | J19: =J18/J8 -> 0.89770037 | K19: =K18/K8 -> 0.85759016 | L19: =L18/L8 -> 0.85759016 | M19: =M18/M8 -> 0.85759016 | N19: =N18/N8 -> 0.85759016 | O19: =O18/O8 -> 0.86530585 | P19: =P18/P8 -> 0.95240497 | ... Z19: =Z18/Z8 -> 0.86457182
C21: Annual malaria mortality rate among the SMC-eligible population
E22: Annual malaria mortality rate among people under age 5 | F22: =Inputs!F30 -> per 100k | G22: =Inputs!G30 -> input | H22: =Inputs!H30 -> - | I22: =Inputs!I30 -> 405.32862 | J22: =Inputs!J30 -> 135.79914 | K22: =Inputs!K30 -> 203.80315 | L22: =Inputs!L30 -> 241.29295 | M22: =Inputs!M30 -> 239.62599 | ... Z22: =Inputs!Z30 -> 339.43659
E23: Implied population of people under age 5 | F23: # | G23: calc | H23: - | I23: =I8/I22*100000 -> 4044957.3 | J23: =J8/J22*100000 -> 3332666.6 | K23: =K8/K22*100000 -> 2015737.6 | L23: =L8/L22*100000 -> 1493780.2 | M23: =M8/M22*100000 -> 436894.42 | N23: =N8/N22*100000 -> 1041346.6 | O23: =O8/O22*100000 -> 986655.19 | P23: =P8/P22*100000 -> 1405633.4 | ... Z23: =Z8/Z22*100000 -> 1097110.1
E24: Total number of months of life in which children are under 5 years old | F24: =Inputs!F31 -> # | G24: =Inputs!G31 -> input | H24: =Inputs!H31 -> 60 | I24: =Inputs!I31 -> - | J24: =Inputs!J31 -> - | K24: =Inputs!K31 -> - | L24: =Inputs!L31 -> - | M24: =Inputs!M31 -> - | ... Z24: =Inputs!Z31 -> -
E25: =HYPERLINK(buildUrl(CELL("address", Inputs!E32)), Inputs!E32) -> #ERROR! | F25: =Inputs!F32 -> # | G25: =Inputs!G32 -> input | H25: =Inputs!H32 -> 3 | I25: =Inputs!I32 -> - | J25: =Inputs!J32 -> - | K25: =Inputs!K32 -> - | L25: =Inputs!L32 -> - | M25: =Inputs!M32 -> - | ... Z25: =Inputs!Z32 -> -
E26: Proportion of people under age 5 who are 3-59-month-olds | F26: % | G26: calc | H26: =(H24-H25)/H24 -> 0.95 | I26: - | J26: - | K26: - | L26: - | M26: - | N26: - | O26: - | P26: - | Q26: - | R26: - | S26: - | T26: - | U26: - | V26: - | W26: - | X26: - | Y26: - | Z26: -
E27: Estimated population of 3-59-month olds | F27: # | G27: calc | H27: - | I27: =I23*$H26 -> 3842709.4 | J27: =J23*$H26 -> 3166033.2 | K27: =K23*$H26 -> 1914950.7 | L27: =L23*$H26 -> 1419091.2 | M27: =M23*$H26 -> 415049.7 | N27: =N23*$H26 -> 989279.27 | O27: =O23*$H26 -> 937322.43 | P27: =P23*$H26 -> 1335351.8 | ... Z27: =Z23*$H26 -> 1042254.6
E28: Unadjusted annual malaria mortality rate among 3-59-month-olds | F28: % | G28: calc | H28: - | I28: =I18/I27 -> 0.0038458826 | J28: =J18/J27 -> 0.0012832309 | K28: =K18/K27 -> 0.001839785 | L28: =L18/L27 -> 0.0021782154 | M28: =M18/M27 -> 0.0021631673 | N28: =N18/N27 -> 0.0032525987 | O28: =O18/O27 -> 0.0027758991 | P28: =P18/P27 -> 0.002563024 | ... Z28: =Z18/Z27 -> 0.0030891296
E29: Adjustment for malaria averted by ITN distributions not accounted for in GBD 2019 | F29: =Inputs!F33 -> % | G29: =Inputs!G33 -> input | H29: =Inputs!H33 -> - | I29: =Inputs!I33 -> 0 | J29: =Inputs!J33 -> 0 | K29: =Inputs!K33 -> 0 | L29: =Inputs!L33 -> 0 | M29: =Inputs!M33 -> 0 | ... Z29: =Inputs!Z33 -> 0
E30: Annual malaria mortality rate among 3-59-month-olds | F30: % | G30: calc | H30: - | I30: =I28*(1+I29) -> 0.0038458826 | J30: =J28*(1+J29) -> 0.0012832309 | K30: =K28*(1+K29) -> 0.001839785 | L30: =L28*(1+L29) -> 0.0021782154 | M30: =M28*(1+M29) -> 0.0021631673 | N30: =N28*(1+N29) -> 0.0032525987 | O30: =O28*(1+O29) -> 0.0027758991 | P30: =P28*(1+P29) -> 0.0024348728 | ... Z30: =Z28*(1+Z29) -> 0.0030891296
C32: Proportion of malaria mortalities that are among the SMC-eligible population
E33: Total malaria mortalities per year | F33: =Inputs!F36 -> # | G33: =Inputs!G36 -> input | H33: =Inputs!H36 -> - | I33: =Inputs!I36 -> 26304.747 | J33: =Inputs!J36 -> 7194.1994 | K33: =Inputs!K36 -> 5327.419 | L33: =Inputs!L36 -> 4674.157 | M33: =Inputs!M36 -> 1357.633 | ... Z33: =Inputs!Z36 -> 4838
E34: Malaria mortalities per year among people over age 5 | F34: # | G34: calc | H34: - | I34: =I33-I8 -> 9909.3773 | J34: =J33-J8 -> 2668.467 | K34: =K33-K8 -> 1219.2823 | L34: =L33-L8 -> 1069.7707 | M34: =M33-M8 -> 310.72043 | N34: =N33-N8 -> 1113.5994 | O34: =O33-O8 -> 3883.0719 | P34: =P33-P8 -> 951.53154 | ... Z34: =Z33-Z8 -> 1114.0068
E35: Malaria mortalities among people over age 5 per malaria mortality among 3-59-month-olds | F35: # | G35: calc | H35: - | I35: =I34/I18 -> 0.67052164 | J35: =J34/J18 -> 0.65681272 | K35: =K34/K18 -> 0.34608247 | L35: =L34/L18 -> 0.34608247 | M35: =M34/M18 -> 0.34608247 | N35: =N34/N18 -> 0.34608247 | O35: =O34/O18 -> 1.4923914 | P35: =P34/P18 -> 0.27801922 | ... Z35: =Z34/Z18 -> 0.34600144
A37: Malaria incidence among the SMC-eligible population
C39: Malaria incidence among people under age 15
E40: Malaria incidence among people age 1 to 4 | F40: =Inputs!F39 -> per 100k | G40: =Inputs!G39 -> input | H40: =Inputs!H39 -> - | I40: =Inputs!I39 -> 60060.984 | J40: =Inputs!J39 -> 37423.266 | K40: =Inputs!K39 -> 30731.36 | L40: =Inputs!L39 -> 37447.9 | M40: =Inputs!M39 -> 35364.66 | ... Z40: =Inputs!Z39 -> 34522.23
E41: Malaria incidence among people age 5 to 14 | F41: =Inputs!F40 -> per 100k | G41: =Inputs!G40 -> input | H41: =Inputs!H40 -> - | I41: =Inputs!I40 -> 24693.609 | J41: =Inputs!J40 -> 16222.621 | K41: =Inputs!K40 -> 30731.36 | L41: =Inputs!L40 -> 37447.9 | M41: =Inputs!M40 -> 35364.66 | ... Z41: =Inputs!Z40 -> 34522.23
E42: Adjustment for malaria averted by ITN distributions not accounted for in GBD 2019 | F42: =Inputs!F33 -> % | G42: =Inputs!G33 -> input | H42: =Inputs!H33 -> - | I42: =Inputs!I33 -> 0 | J42: =Inputs!J33 -> 0 | K42: =Inputs!K33 -> 0 | L42: =Inputs!L33 -> 0 | M42: =Inputs!M33 -> 0 | ... Z42: =Inputs!Z33 -> 0
E43: Adjusted malaria incidence among people age 1 to 4 | F43: % | G43: calc | H43: - | I43: =(I40/100000)*(1+I42) -> 0.60060984 | J43: =(J40/100000)*(1+J42) -> 0.37423266 | K43: =(K40/100000)*(1+K42) -> 0.3073136 | L43: =(L40/100000)*(1+L42) -> 0.374479 | M43: =(M40/100000)*(1+M42) -> 0.3536466 | N43: =(N40/100000)*(1+N42) -> 0.3510289 | O43: =(O40/100000)*(1+O42) -> 0.3632733 | P43: =(P40/100000)*(1+P42) -> 0.45278811 | ... Z43: =(Z40/100000)*(1+Z42) -> 0.3452223
E44: Adjusted malaria incidence among people age 5 to 14 | F44: % | G44: calc | H44: - | I44: =(I41/100000)*(1+I42) -> 0.24693609 | J44: =(J41/100000)*(1+J42) -> 0.16222621 | K44: =(K41/100000)*(1+K42) -> 0.3073136 | L44: =(L41/100000)*(1+L42) -> 0.374479 | M44: =(M41/100000)*(1+M42) -> 0.3536466 | N44: =(N41/100000)*(1+N42) -> 0.3510289 | O44: =(O41/100000)*(1+O42) -> 0.3632733 | P44: =(P41/100000)*(1+P42) -> 0.18613491 | ... Z44: =(Z41/100000)*(1+Z42) -> 0.3452223

Sheet LeverageFunging
I1: Malaria Consortium | R1: Malaria Consortium
I2: Burkina Faso | J2: Chad | K2: DRC | L2: DRC | M2: DRC | N2: DRC | O2: Mozambique | P2: Nigeria | Q2: Nigeria | R2: Nigeria | S2: Nigeria | T2: Nigeria | U2: Nigeria | V2: Nigeria | W2: Nigeria | X2: Nigeria | Y2: Togo | Z2: Uganda
A3: Supplemental calculations for the leverage/funging adjustment | F3: unit | G3: type | H3: Overall | K3: Haut-Katanga | L3: Haut-Lomami | M3: Lualaba | N3: Tanganyika | O3: Nampula | P3: Bauchi | Q3: Borno | R3: FCT (Abuja) | S3: Kebbi | T3: Kogi | U3: Nasarawa | V3: Oyo | W3: Plateau | X3: Sokoto | Z3: Karamoja
E4: Final cost-effectiveness estimate (pulled from "Main calcs" sheet for visibility) | F4: ='Main CEA'!F191 -> xbenchmark | G4: main | H4: ='Main CEA'!H191 -> - | I4: ='Main CEA'!I191 -> 18.017467 | J4: ='Main CEA'!J191 -> 8.0191284 | K4: ='Main CEA'!K191 -> 7.8521256 | L4: ='Main CEA'!L191 -> 9.2460297 | M4: ='Main CEA'!M191 -> 9.1012718 | N4: ='Main CEA'!N191 -> 12.57331 | O4: ='Main CEA'!O191 -> 11.495836 | ... Z4: ='Main CEA'!Z191 -> 10.360783
A5: Costs
C7: GiveWell costs
E8: Grant size | F8: =Inputs!F8 -> $ | G8: =Inputs!G8 -> input | H8: =Inputs!H8 -> 1000000 | I8: =Inputs!I8 -> - | J8: =Inputs!J8 -> - | K8: =Inputs!K8 -> - | L8: =Inputs!L8 -> - | M8: =Inputs!M8 -> - | ... Z8: =Inputs!Z8 -> -
C10: Cost breakdown
E11: Percentage of total costs covered by the grantee | F11: =Inputs!F11 -> % | G11: =Inputs!G11 -> input | H11: =Inputs!H11 -> - | I11: =Inputs!I11 -> 0.8872139 | J11: =Inputs!J11 -> 0.8943595 | K11: =Inputs!K11 -> 0.8943595 | L11: =Inputs!L11 -> 0.8943595 | M11: =Inputs!M11 -> 0.8943595 | ... Z11: =Inputs!Z11 -> 0.8943595
E12: Percentage of total costs covered by other philanthropic actors | F12: =Inputs!F12 -> % | G12: =Inputs!G12 -> input | H12: =Inputs!H12 -> - | I12: =Inputs!I12 -> 0.0081278 | J12: =Inputs!J12 -> 0 | K12: =Inputs!K12 -> 0 | L12: =Inputs!L12 -> 0 | M12: =Inputs!M12 -> 0 | ... Z12: =Inputs!Z12 -> 0
E13: Percentage of total costs covered by domestic governments | F13: =Inputs!F13 -> % | G13: =Inputs!G13 -> input | H13: =Inputs!H13 -> - | I13: =Inputs!I13 -> 0.1046583 | J13: =Inputs!J13 -> 0.1056405 | K13: =Inputs!K13 -> 0.1056405 | L13: =Inputs!L13 -> 0.1056405 | M13: =Inputs!M13 -> 0.1056405 | ... Z13: =Inputs!Z13 -> 0.1056405
C15: Total costs
E16: Total spending by all contributors | F16: ='Main CEA'!F16 -> $ | G16: main | H16: ='Main CEA'!H16 -> - | I16: ='Main CEA'!I16 -> 1127123.9 | J16: ='Main CEA'!J16 -> 1118118.6 | K16: ='Main CEA'!K16 -> 1118118.6 | L16: ='Main CEA'!L16 -> 1118118.6 | M16: ='Main CEA'!M16 -> 1118118.6 | N16: ='Main CEA'!N16 -> 1118118.6 | O16: ='Main CEA'!O16 -> 1118118.6 | ... Z16: ='Main CEA'!Z16 -> 1118118.6
C18: Total spending attributable to different actors
E19: Total spending contributed by grantee | F19: ='Main CEA'!F19 -> $ | G19: main | H19: ='Main CEA'!H19 -> - | I19: ='Main CEA'!I19 -> 1000000 | J19: ='Main CEA'!J19 -> 1000000 | K19: ='Main CEA'!K19 -> 1000000 | L19: ='Main CEA'!L19 -> 1000000 | M19: ='Main CEA'!M19 -> 1000000 | N19: ='Main CEA'!N19 -> 1000000 | O19: ='Main CEA'!O19 -> 1000000 | ... Z19: ='Main CEA'!Z19 -> 1000000
E20: Total spending contributed by other philanthropic actors | F20: ='Main CEA'!F20 -> $ | G20: main | H20: ='Main CEA'!H20 -> - | I20: ='Main CEA'!I20 -> 9161.0377 | J20: ='Main CEA'!J20 -> 0 | K20: ='Main CEA'!K20 -> 0 | L20: ='Main CEA'!L20 -> 0 | M20: ='Main CEA'!M20 -> 0 | N20: ='Main CEA'!N20 -> 0 | O20: ='Main CEA'!O20 -> 0 | ... Z20: ='Main CEA'!Z20 -> 0
E21: Total spending contributed by domestic governments | F21: ='Main CEA'!F21 -> $ | G21: main | H21: ='Main CEA'!H21 -> - | I21: ='Main CEA'!I21 -> 117962.87 | J21: ='Main CEA'!J21 -> 118118.61 | K21: ='Main CEA'!K21 -> 118118.61 | L21: ='Main CEA'!L21 -> 118118.61 | M21: ='Main CEA'!M21 -> 118118.61 | N21: ='Main CEA'!N21 -> 118118.61 | O21: ='Main CEA'!O21 -> 118118.61 | ... Z21: ='Main CEA'!Z21 -> 118118.61
C23: Upstream / downstream spending
E24: Total spending causally upstream of donations to grantee | F24: ='Main CEA'!F24 -> $ | G24: main | H24: ='Main CEA'!H24 -> - | I24: ='Main CEA'!I24 -> 1009161 | J24: ='Main CEA'!J24 -> 1000000 | K24: ='Main CEA'!K24 -> 1000000 | L24: ='Main CEA'!L24 -> 1000000 | M24: ='Main CEA'!M24 -> 1000000 | N24: ='Main CEA'!N24 -> 1000000 | O24: ='Main CEA'!O24 -> 1000000 | ... Z24: ='Main CEA'!Z24 -> 1000000
E25: Total spending causally downstream of donations to grantee | F25: ='Main CEA'!F25 -> $ | G25: main | H25: ='Main CEA'!H25 -> - | I25: ='Main CEA'!I25 -> 117962.87 | J25: ='Main CEA'!J25 -> 118118.61 | K25: ='Main CEA'!K25 -> 118118.61 | L25: ='Main CEA'!L25 -> 118118.61 | M25: ='Main CEA'!M25 -> 118118.61 | N25: ='Main CEA'!N25 -> 118118.61 | O25: ='Main CEA'!O25 -> 118118.61 | ... Z25: ='Main CEA'!Z25 -> 118118.61
A27: Counterfactual funding scenarios
C29: Probability of scenarios in the absence of philanthropic funding
E30: Scenario 1: Domestic governments would replace the grantee's costs | F30: =Inputs!F113 -> % | G30: =Inputs!G113 -> input | H30: =Inputs!H113 -> - | I30: =Inputs!I113 -> 0 | J30: =Inputs!J113 -> 0 | K30: =Inputs!K113 -> 0 | L30: =Inputs!L113 -> 0 | M30: =Inputs!M113 -> 0 | ... Z30: =Inputs!Z113 -> 0
E31: Scenario 2: Global Fund and/or PMI would replace the grantee's costs | F31: =Inputs!F114 -> % | G31: =Inputs!G114 -> input | H31: =Inputs!H114 -> - | I31: =Inputs!I114 -> 0.5 | J31: =Inputs!J114 -> 0.45 | K31: =Inputs!K114 -> 0.15 | L31: =Inputs!L114 -> 0.15 | M31: =Inputs!M114 -> 0.15 | ... Z31: =Inputs!Z114 -> 0.3
E32: Scenario 3: Other actors' upstream costs would stay the same (downstream costs would shrink in proportion to the total size of the program) | F32: =Inputs!F115 -> % | G32: =Inputs!G115 -> input | H32: =Inputs!H115 -> - | I32: =Inputs!I115 -> 0 | J32: =Inputs!J115 -> 0 | K32: =Inputs!K115 -> 0 | L32: =Inputs!L115 -> 0 | M32: =Inputs!M115 -> 0 | ... Z32: =Inputs!Z115 -> 0
E33: Scenario 4: Distributions would go unfunded | F33: % | G33: calc | H33: - | I33: =1-SUM(I30:I32) -> 0.5 | J33: =1-SUM(J30:J32) -> 0.55 | K33: =1-SUM(K30:K32) -> 0.85 | L33: =1-SUM(L30:L32) -> 0.85 | M33: =1-SUM(M30:M32) -> 0.85 | N33: =1-SUM(N30:N32) -> 0.85 | O33: =1-SUM(O30:O32) -> 0.8 | P33: =1-SUM(P30:P32) -> 0.8 | ... Z33: =1-SUM(Z30:Z32) -> 0.7
C35: Proportion of the program that would still occur in each scenario
E36: Scenario 1: Domestic governments would replace the grantee's costs | F36: =Inputs!F118 -> % | G36: =Inputs!G118 -> input | H36: =Inputs!H118 -> 1 | I36: =Inputs!I118 -> - | J36: =Inputs!J118 -> - | K36: =Inputs!K118 -> - | L36: =Inputs!L118 -> - | M36: =Inputs!M118 -> - | ... Z36: =Inputs!Z118 -> -
E37: Scenario 2: Global Fund and/or PMI would replace the grantee's costs | F37: =Inputs!F119 -> % | G37: =Inputs!G119 -> input | H37: =Inputs!H119 -> 1 | I37: =Inputs!I119 -> - | J37: =Inputs!J119 -> - | K37: =Inputs!K119 -> - | L37: =Inputs!L119 -> - | M37: =Inputs!M119 -> - | ... Z37: =Inputs!Z119 -> -
E38: Scenario 3: Other actors' upstream costs would stay the same (downstream costs would shrink in proportion to the total size of the program) | F38: % | G38: calc | H38: - | I38: =I20/I24 -> 0.009077875 | J38: =J20/J24 -> 0 | K38: =K20/K24 -> 0 | L38: =L20/L24 -> 0 | M38: =M20/M24 -> 0 | N38: =N20/N24 -> 0 | O38: =O20/O24 -> 0 | P38: =P20/P24 -> 0.042724632 | ... Z38: =Z20/Z24 -> 0
E39: Scenario 4: Distributions would go unfunded | F39: =Inputs!F120 -> % | G39: =Inputs!G120 -> input | H39: =Inputs!H120 -> 0 | I39: =Inputs!I120 -> - | J39: =Inputs!J120 -> - | K39: =Inputs!K120 -> - | L39: =Inputs!L120 -> - | M39: =Inputs!M120 -> - | ... Z39: =Inputs!Z120 -> -
A41: Value of spending
C43: Cost-effectiveness of the program (before leverage and funging)
E44: Units of value generated per dollar (before final adjustments) | F44: ='Main CEA'!F132 -> UoV | G44: main | H44: ='Main CEA'!H132 -> - | I44: ='Main CEA'!I132 -> 0.095973306 | J44: ='Main CEA'!J132 -> 0.031989019 | K44: ='Main CEA'!K132 -> 0.024298028 | L44: ='Main CEA'!L132 -> 0.028931657 | M44: ='Main CEA'!M132 -> 0.028450451 | N44: ='Main CEA'!N132 -> 0.039992231 | O44: ='Main CEA'!O132 -> 0.037836008 | ... Z44: ='Main CEA'!Z132 -> 0.03671631
E45: Total supplemental grantee-level adjustment | F45: ='Main CEA'!F161 -> % | G45: main | H45: ='Main CEA'!H161 -> -0.08 | I45: ='Main CEA'!I161 -> - | J45: ='Main CEA'!J161 -> - | K45: ='Main CEA'!K161 -> - | L45: ='Main CEA'!L161 -> - | M45: ='Main CEA'!M161 -> - | N45: ='Main CEA'!N161 -> - | O45: ='Main CEA'!O161 -> - | ... Z45: ='Main CEA'!Z161 -> -
E46: Total supplemental intervention-level adjustment | F46: ='Main CEA'!F177 -> % | G46: main | H46: ='Main CEA'!H177 -> - | I46: ='Main CEA'!I177 -> 0.191 | J46: ='Main CEA'!J177 -> 0.241 | K46: ='Main CEA'!K177 -> 0.281 | L46: ='Main CEA'!L177 -> 0.281 | M46: ='Main CEA'!M177 -> 0.281 | N46: ='Main CEA'!N177 -> 0.281 | O46: ='Main CEA'!O177 -> 0.281 | ... Z46: ='Main CEA'!Z177 -> 0.281
E47: Units of value generated per dollar donated to grantee (after supplemental adjustments) | F47: UoV | G47: calc | H47: - | I47: =I44*(1+$H45)*(1+I46) -> 0.10515987 | J47: =J44*(1+$H45)*(1+J46) -> 0.036522503 | K47: =K44*(1+$H45)*(1+K46) -> 0.028635712 | L47: =L44*(1+$H45)*(1+L46) -> 0.034096536 | M47: =M44*(1+$H45)*(1+M46) -> 0.033529426 | N47: =N44*(1+$H45)*(1+N46) -> 0.047131645 | O47: =O44*(1+$H45)*(1+O46) -> 0.044590492 | P47: =P44*(1+$H45)*(1+P46) -> 0.085119308 | ... Z47: =Z44*(1+$H45)*(1+Z46) -> 0.043270906
C49: Lives saved by the program (before leverage and funging)
E50: Total lives saved (before final adjustments) | F50: ='Main CEA'!F143 -> # | G50: main | H50: ='Main CEA'!H143 -> - | I50: ='Main CEA'!I143 -> 716.26361 | J50: ='Main CEA'!J143 -> 209.60575 | K50: ='Main CEA'!K143 -> 171.05319 | L50: ='Main CEA'!L143 -> 202.5186 | M50: ='Main CEA'!M143 -> 201.11951 | N50: ='Main CEA'!N143 -> 302.40892 | O50: ='Main CEA'!O143 -> 295.91747 | ... Z50: ='Main CEA'!Z143 -> 276.61147
E51: Total supplemental grantee-level adjustment | F51: ='Main CEA'!F161 -> % | G51: main | H51: ='Main CEA'!H161 -> -0.08 | I51: ='Main CEA'!I161 -> - | J51: ='Main CEA'!J161 -> - | K51: ='Main CEA'!K161 -> - | L51: ='Main CEA'!L161 -> - | M51: ='Main CEA'!M161 -> - | N51: ='Main CEA'!N161 -> - | O51: ='Main CEA'!O161 -> - | ... Z51: ='Main CEA'!Z161 -> -
...

Sheet Inputs
I1: Malaria Consortium | R1: Malaria Consortium
I2: Burkina Faso | J2: Chad | K2: DRC | L2: DRC | M2: DRC | N2: DRC | O2: Mozambique | P2: Nigeria | Q2: Nigeria | R2: Nigeria | S2: Nigeria | T2: Nigeria | U2: Nigeria | V2: Nigeria | W2: Nigeria | X2: Nigeria | Y2: Togo | Z2: Uganda
A3: Inputs | F3: unit | G3: type | H3: Overall | K3: Haut-Katanga | L3: Haut-Lomami | M3: Lualaba | N3: Tanganyika | O3: Nampula | P3: Bauchi | Q3: Borno | R3: FCT (Abuja) | S3: Kebbi | T3: Kogi | U3: Nasarawa | V3: Oyo | W3: Plateau | X3: Sokoto | Z3: Karamoja | AB3: Source | AC3: GW analysis and discussion
E4: Final cost-effectiveness estimate (pulled from "Main calcs" sheet for visibility) | F4: ='Main CEA'!F191 -> xbenchmark | G4: main | H4: ='Main CEA'!H191 -> - | I4: ='Main CEA'!I191 -> 18.017467 | J4: ='Main CEA'!J191 -> 8.0191284 | K4: ='Main CEA'!K191 -> 7.8521256 | L4: ='Main CEA'!L191 -> 9.2460297 | M4: ='Main CEA'!M191 -> 9.1012718 | N4: ='Main CEA'!N191 -> 12.57331 | O4: ='Main CEA'!O191 -> 11.495836 | ... Z4: ='Main CEA'!Z191 -> 10.360783
A5: Costs
C7: GiveWell costs
E8: Grant size | F8: $ | G8: input | H8: 1000000 | I8: - | J8: - | K8: - | L8: - | M8: - | N8: - | O8: - | P8: - | Q8: - | R8: - | S8: - | T8: - | U8: - | V8: - | W8: - | X8: - | Y8: - | Z8: - | AB8: Arbitrary value
C10: Cost breakdown
E11: Percentage of total costs covered by the grantee | F11: % | G11: input | H11: - | I11: 0.8872139 | J11: 0.8943595 | K11: 0.8943595 | L11: 0.8943595 | M11: 0.8943595 | N11: 0.8943595 | O11: 0.8943595 | P11: 0.8604484 | Q11: 0.8604484 | R11: 0.8604484 | S11: 0.8604484 | T11: 0.8604484 | U11: 0.8604484 | V11: 0.8604484 | W11: 0.8604484 | X11: 0.8604484 | Y11: 0.874083 | Z11: 0.8943595 | AB11: GW analysis | AC11: GW's analysis of Malaria Consortium's cost per SMC cycle administration
E12: Percentage of total costs covered by other philanthropic actors | F12: % | G12: input | H12: - | I12: 0.0081278 | J12: 0 | K12: 0 | L12: 0 | M12: 0 | N12: 0 | O12: 0 | P12: 0.0384031 | Q12: 0.0384031 | R12: 0.0384031 | S12: 0.0384031 | T12: 0.0384031 | U12: 0.0384031 | V12: 0.0384031 | W12: 0.0384031 | X12: 0.0384031 | Y12: 0.0244652 | Z12: 0 | AB12: GW analysis | AC12: GW's analysis of Malaria Consortium's cost per SMC cycle administration
E13: Percentage of total costs covered by domestic governments | F13: % | G13: input | H13: - | I13: 0.1046583 | J13: 0.1056405 | K13: 0.1056405 | L13: 0.1056405 | M13: 0.1056405 | N13: 0.1056405 | O13: 0.1056405 | P13: 0.1011485 | Q13: 0.1011485 | R13: 0.1011485 | S13: 0.1011485 | T13: 0.1011485 | U13: 0.1011485 | V13: 0.1011485 | W13: 0.1011485 | X13: 0.1011485 | Y13: 0.1014518 | Z13: 0.1056405 | AB13: GW analysis | AC13: GW's analysis of Malaria Consortium's cost per SMC cycle administration
C15: Cost per child covered
E16: Cost per seasonal malaria chemoprevention (SMC) cycle administered | F16: $ | G16: input | H16: - | I16: 1.47763 | J16: 1.81008 | K16: 1.81008 | L16: 1.81008 | M16: 1.81008 | N16: 1.81008 | O16: 1.81008 | P16: 1.40255 | Q16: 1.40255 | R16: 1.40255 | S16: 1.40255 | T16: 1.40255 | U16: 1.40255 | V16: 1.40255 | W16: 1.40255 | X16: 1.40255 | Y16: 1.49507 | Z16: 1.81008 | AB16: GW analysis | AC16: GW's analysis of Malaria Consortium's cost per SMC cycle administration
E17: Number of SMC cycles per year | F17: # | G17: input | H17: - | I17: 4.3 | J17: 4 | K17: 4 | L17: 4 | M17: 4 | N17: 4 | O17: 4 | P17: 4 | Q17: 4 | R17: 5 | S17: 4 | T17: 5 | U17: 5 | V17: 5 | W17: 5 | X17: 4 | Y17: 4 | Z17: 5 | AB17: GW analysis | AC17: GW's analysis of the number of SMC cycles delivered per year
A19: Counterfactual malaria
C21: Malaria mortalities among the SMC-eligible population
E22: Malaria mortalities per year among people under age 5 | F22: # | G22: input | H22: - | I22: =IFERROR(__xludf.DUMMYFUNCTION("FILTER('GBD estimates'!$S$4:$S$309,'GBD estimates'!$M$4:$M$309=I$2,'GBD estimates'!$O$4:$O$309=""<5 years"")"),16395.3694901677) -> 16395.369 | J22: =IFERROR(__xludf.DUMMYFUNCTION("FILTER('GBD estimates'!$S$4:$S$309,'GBD estimates'!$M$4:$M$309=J$2,'GBD estimates'!$O$4:$O$309=""<5 years"")"),4525.73244604996) -> 4525.7324 | K22: 4108.1367 | L22: 3604.3863 | M22: 1046.9126 | N22: 3752.0586 | O22: 3006.9281 | P22: =IFERROR(__xludf.DUMMYFUNCTION("FILTER('GBD estimates'!$BA$4:$BA$258,'GBD estimates'!$AV$4:$AV$258=P$3,'GBD estimates'!$AU$4:$AU$258=""Under 5"")"),3593.574945) -> 3593.5749 | Q22: =IFERROR(__xludf.DUMMYFUNCTION("FILTER('GBD estimates'!$BA$4:$BA$258,'GBD estimates'!$AV$4:$AV$258=Q$3,'GBD estimates'!$AU$4:$AU$258=""Under 5"")"),1707.805365) -> 1707.8054 | R22: =IFERROR(__xludf.DUMMYFUNCTION("FILTER('GBD estimates'!$BA$4:$BA$258,'GBD estimates'!$AV$4:$AV$258=R$3,'GBD estimates'!$AU$4:$AU$258=""Under 5"")"),1882.032542) -> 1882.0325 | S22: =IFERROR(__xludf.DUMMYFUNCTION("FILTER('GBD estimates'!$BA$4:$BA$258,'GBD estimates'!$AV$4:$AV$258=S$3,'GBD estimates'!$AU$4:$AU$258=""Under 5"")"),3140.509316) -> 3140.5093 | T22: =IFERROR(__xludf.DUMMYFUNCTION("FILTER('GBD estimates'!$BA$4:$BA$258,'GBD estimates'!$AV$4:$AV$258=T$3,'GBD estimates'!$AU$4:$AU$258=""Under 5"")"),800.9679515) -> 800.96795 | U22: =IFERROR(__xludf.DUMMYFUNCTION("FILTER('GBD estimates'!$BA$4:$BA$258,'GBD estimates'!$AV$4:$AV$258=U$3,'GBD estimates'!$AU$4:$AU$258=""Under 5"")"),2258.288279) -> 2258.2883 | V22: =IFERROR(__xludf.DUMMYFUNCTION("FILTER('GBD estimates'!$BA$4:$BA$258,'GBD estimates'!$AV$4:$AV$258=V$3,'GBD estimates'!$AU$4:$AU$258=""Under 5"")"),1857.078678) -> 1857.0787 | W22: =IFERROR(__xludf.DUMMYFUNCTION("FILTER('GBD estimates'!$BA$4:$BA$258,'GBD estimates'!$AV$4:$AV$258=W$3,'GBD estimates'!$AU$4:$AU$258=""Under 5"")"),3181.704964) -> 3181.705 | X22: =IFERROR(__xludf.DUMMYFUNCTION("FILTER('GBD estimates'!$BA$4:$BA$258,'GBD estimates'!$AV$4:$AV$258=X$3,'GBD estimates'!$AU$4:$AU$258=""Under 5"")"),4918.708785) -> 4918.7088 | Y22: =IFERROR(__xludf.DUMMYFUNCTION("FILTER('GBD estimates'!$S$4:$S$309,'GBD estimates'!$M$4:$M$309=Y$2,'GBD estimates'!$O$4:$O$309=""<5 years"")"),1880.40794320354) -> 1880.4079 | Z22: 3723.9932 | AB22: GBD 2019
E23: Early neonatal malaria mortalities per year (babies under 7 days old) | F23: # | G23: input | H23: - | I23: =IFERROR(__xludf.DUMMYFUNCTION("FILTER('GBD estimates'!$S$4:$S$309,'GBD estimates'!$M$4:$M$309=I$2,'GBD estimates'!$O$4:$O$309=""0-6 days"")"),0.0) -> 0 | J23: =IFERROR(__xludf.DUMMYFUNCTION("FILTER('GBD estimates'!$S$4:$S$309,'GBD estimates'!$M$4:$M$309=J$2,'GBD estimates'!$O$4:$O$309=""0-6 days"")"),0.0) -> 0 | K23: 0 | L23: 0 | M23: 0 | N23: 0 | O23: 0 | P23: 0 | Q23: 0 | R23: 0 | S23: 0 | T23: 0 | U23: 0 | V23: 0 | W23: 0 | X23: 0 | Y23: =IFERROR(__xludf.DUMMYFUNCTION("FILTER('GBD estimates'!$S$4:$S$309,'GBD estimates'!$M$4:$M$309=Y$2,'GBD estimates'!$O$4:$O$309=""0-6 days"")"),0.0) -> 0 | Z23: 0 | AB23: GBD 2019
E24: Late neonatal malaria mortalities per year (babies between 7 and 27 days old) | F24: # | G24: input | H24: - | I24: =IFERROR(__xludf.DUMMYFUNCTION("FILTER('GBD estimates'!$S$4:$S$309,'GBD estimates'!$M$4:$M$309=I$2,'GBD estimates'!$O$4:$O$309=""7-27 days"")"),683.012100501328) -> 683.0121 | J24: =IFERROR(__xludf.DUMMYFUNCTION("FILTER('GBD estimates'!$S$4:$S$309,'GBD estimates'!$M$4:$M$309=J$2,'GBD estimates'!$O$4:$O$309=""7-27 days"")"),207.98591325582) -> 207.98591 | K24: 288.24933 | L24: 252.90345 | M24: 73.45711 | N24: 263.26495 | O24: 119.56005 | P24: =IFERROR(__xludf.DUMMYFUNCTION("FILTER('GBD estimates'!$BA$4:$BA$258,'GBD estimates'!$AV$4:$AV$258=P$3,'GBD estimates'!$AU$4:$AU$258=""7 to 27 days (late neonatal)"")"),77.56124047) -> 77.56124 | Q24: =IFERROR(__xludf.DUMMYFUNCTION("FILTER('GBD estimates'!$BA$4:$BA$258,'GBD estimates'!$AV$4:$AV$258=Q$3,'GBD estimates'!$AU$4:$AU$258=""7 to 27 days (late neonatal)"")"),67.45050889) -> 67.450509 | R24: =IFERROR(__xludf.DUMMYFUNCTION("FILTER('GBD estimates'!$BA$4:$BA$258,'GBD estimates'!$AV$4:$AV$258=R$3,'GBD estimates'!$AU$4:$AU$258=""7 to 27 days (late neonatal)"")"),112.9551112) -> 112.95511 | S24: =IFERROR(__xludf.DUMMYFUNCTION("FILTER('GBD estimates'!$BA$4:$BA$258,'GBD estimates'!$AV$4:$AV$258=S$3,'GBD estimates'!$AU$4:$AU$258=""7 to 27 days (late neonatal)"")"),84.23526307) -> 84.235263 | T24: =IFERROR(__xludf.DUMMYFUNCTION("FILTER('GBD estimates'!$BA$4:$BA$258,'GBD estimates'!$AV$4:$AV$258=T$3,'GBD estimates'!$AU$4:$AU$258=""7 to 27 days (late neonatal)"")"),49.43917069) -> 49.439171 | U24: =IFERROR(__xludf.DUMMYFUNCTION("FILTER('GBD estimates'!$BA$4:$BA$258,'GBD estimates'!$AV$4:$AV$258=U$3,'GBD estimates'!$AU$4:$AU$258=""7 to 27 days (late neonatal)"")"),97.97276234) -> 97.972762 | V24: =IFERROR(__xludf.DUMMYFUNCTION("FILTER('GBD estimates'!$BA$4:$BA$258,'GBD estimates'!$AV$4:$AV$258=V$3,'GBD estimates'!$AU$4:$AU$258=""7 to 27 days (late neonatal)"")"),155.6540484) -> 155.65405 | W24: =IFERROR(__xludf.DUMMYFUNCTION("FILTER('GBD estimates'!$BA$4:$BA$258,'GBD estimates'!$AV$4:$AV$258=W$3,'GBD estimates'!$AU$4:$AU$258=""7 to 27 days (late neonatal)"")"),160.3877065) -> 160.38771 | X24: =IFERROR(__xludf.DUMMYFUNCTION("FILTER('GBD estimates'!$BA$4:$BA$258,'GBD estimates'!$AV$4:$AV$258=X$3,'GBD estimates'!$AU$4:$AU$258=""7 to 27 days (late neonatal)"")"),107.7832724) -> 107.78327 | Y24: =IFERROR(__xludf.DUMMYFUNCTION("FILTER('GBD estimates'!$S$4:$S$309,'GBD estimates'!$M$4:$M$309=Y$2,'GBD estimates'!$O$4:$O$309=""7-27 days"")"),82.1438456374381) -> 82.143846 | Z24: 214.2493 | AB24: GBD 2019
E25: Post-neonatal malaria mortalities per year (babies between 28 and 364 days old) | F25: # | G25: input | H25: - | I25: =IFERROR(__xludf.DUMMYFUNCTION("FILTER('GBD estimates'!$S$4:$S$309,'GBD estimates'!$M$4:$M$309=I$2,'GBD estimates'!$O$4:$O$309=""28-364 days"")"),5135.61437005002) -> 5135.6144 | J25: =IFERROR(__xludf.DUMMYFUNCTION("FILTER('GBD estimates'!$S$4:$S$309,'GBD estimates'!$M$4:$M$309=J$2,'GBD estimates'!$O$4:$O$309=""28-364 days"")"),1402.47165898354) -> 1402.4717 | K25: 1632.3436 | L25: 1432.1813 | M25: 415.98445 | N25: 1490.858 | O25: 1570.0056 | P25: =IFERROR(__xludf.DUMMYFUNCTION("FILTER('GBD estimates'!$BA$4:$BA$258,'GBD estimates'!$AV$4:$AV$258=P$3,'GBD estimates'!$AU$4:$AU$258=""28 to 364 days (post neonatal)"")"),514.1128436) -> 514.11284 | Q25: =IFERROR(__xludf.DUMMYFUNCTION("FILTER('GBD estimates'!$BA$4:$BA$258,'GBD estimates'!$AV$4:$AV$258=Q$3,'GBD estimates'!$AU$4:$AU$258=""28 to 364 days (post neonatal)"")"),362.4923754) -> 362.49238 | R25: =IFERROR(__xludf.DUMMYFUNCTION("FILTER('GBD estimates'!$BA$4:$BA$258,'GBD estimates'!$AV$4:$AV$258=R$3,'GBD estimates'!$AU$4:$AU$258=""28 to 364 days (post neonatal)"")"),590.6183608) -> 590.61836 | S25: =IFERROR(__xludf.DUMMYFUNCTION("FILTER('GBD estimates'!$BA$4:$BA$258,'GBD estimates'!$AV$4:$AV$258=S$3,'GBD estimates'!$AU$4:$AU$258=""28 to 364 days (post neonatal)"")"),501.3440327) -> 501.34403 | T25: =IFERROR(__xludf.DUMMYFUNCTION("FILTER('GBD estimates'!$BA$4:$BA$258,'GBD estimates'!$AV$4:$AV$258=T$3,'GBD estimates'!$AU$4:$AU$258=""28 to 364 days (post neonatal)"")"),249.8757855) -> 249.87579 | U25: =IFERROR(__xludf.DUMMYFUNCTION("FILTER('GBD estimates'!$BA$4:$BA$258,'GBD estimates'!$AV$4:$AV$258=U$3,'GBD estimates'!$AU$4:$AU$258=""28 to 364 days (post neonatal)"")"),584.2162297) -> 584.21623 | V25: =IFERROR(__xludf.DUMMYFUNCTION("FILTER('GBD estimates'!$BA$4:$BA$258,'GBD estimates'!$AV$4:$AV$258=V$3,'GBD estimates'!$AU$4:$AU$258=""28 to 364 days (post neonatal)"")"),658.0187831) -> 658.01878 | W25: =IFERROR(__xludf.DUMMYFUNCTION("FILTER('GBD estimates'!$BA$4:$BA$258,'GBD estimates'!$AV$4:$AV$258=W$3,'GBD estimates'!$AU$4:$AU$258=""28 to 364 days (post neonatal)"")"),921.5288306) -> 921.52883 | X25: =IFERROR(__xludf.DUMMYFUNCTION("FILTER('GBD estimates'!$BA$4:$BA$258,'GBD estimates'!$AV$4:$AV$258=X$3,'GBD estimates'!$AU$4:$AU$258=""28 to 364 days (post neonatal)"")"),726.8852489) -> 726.88525 | Y25: =IFERROR(__xludf.DUMMYFUNCTION("FILTER('GBD estimates'!$S$4:$S$309,'GBD estimates'!$M$4:$M$309=Y$2,'GBD estimates'!$O$4:$O$309=""28-364 days"")"),575.084442435558) -> 575.08444 | Z25: 1595.4637 | AB25: GBD 2019
E26: Number of post-neonatal months of life in which children are under 1 year old | F26: # | G26: input | H26: 11 | I26: - | J26: - | K26: - | L26: - | M26: - | N26: - | O26: - | P26: - | Q26: - | R26: - | S26: - | T26: - | U26: - | V26: - | W26: - | X26: - | Y26: - | Z26: -
E27: Number of post-neonatal months of life in which children are under 3 months old | F27: # | G27: input | H27: 2 | I27: - | J27: - | K27: - | L27: - | M27: - | N27: - | O27: - | P27: - | Q27: - | R27: - | S27: - | T27: - | U27: - | V27: - | W27: - | X27: - | Y27: - | Z27: -
C29: Malaria mortality rate among the SMC-eligible population
E30: Annual malaria mortality rate among people under age 5 | F30: per 100k | G30: input | H30: - | I30: =IFERROR(__xludf.DUMMYFUNCTION("FILTER('GBD estimates'!$AD$4:$AD$54,'GBD estimates'!$X$4:$X$54=I$2)"),405.3286161) -> 405.32862 | J30: =IFERROR(__xludf.DUMMYFUNCTION("FILTER('GBD estimates'!$AD$4:$AD$54,'GBD estimates'!$X$4:$X$54=J$2)"),135.7991375) -> 135.79914 | K30: 203.80315 | L30: 241.29295 | M30: 239.62599 | N30: 360.30833 | O30: 304.75977 | P30: =IFERROR(__xludf.DUMMYFUNCTION("FILTER('GBD estimates'!$BN$4:$BN$54,'GBD estimates'!$BI$4:$BI$54=P$3)"),255.6551987) -> 255.6552 | Q30: =IFERROR(__xludf.DUMMYFUNCTION("FILTER('GBD estimates'!$BN$4:$BN$54,'GBD estimates'!$BI$4:$BI$54=Q$3)"),178.1742523) -> 178.17425 | R30: =IFERROR(__xludf.DUMMYFUNCTION("FILTER('GBD estimates'!$BN$4:$BN$54,'GBD estimates'!$BI$4:$BI$54=R$3)"),288.3183134) -> 288.31831 | S30: =IFERROR(__xludf.DUMMYFUNCTION("FILTER('GBD estimates'!$BN$4:$BN$54,'GBD estimates'!$BI$4:$BI$54=S$3)"),331.5302296) -> 331.53023 | T30: =IFERROR(__xludf.DUMMYFUNCTION("FILTER('GBD estimates'!$BN$4:$BN$54,'GBD estimates'!$BI$4:$BI$54=T$3)"),240.036585) -> 240.03659 | U30: =IFERROR(__xludf.DUMMYFUNCTION("FILTER('GBD estimates'!$BN$4:$BN$54,'GBD estimates'!$BI$4:$BI$54=U$3)"),298.6653229) -> 298.66532 | V30: =IFERROR(__xludf.DUMMYFUNCTION("FILTER('GBD estimates'!$BN$4:$BN$54,'GBD estimates'!$BI$4:$BI$54=V$3)"),261.8332491) -> 261.83325 | W30: =IFERROR(__xludf.DUMMYFUNCTION("FILTER('GBD estimates'!$BN$4:$BN$54,'GBD estimates'!$BI$4:$BI$54=W$3)"),210.2157784) -> 210.21578 | X30: =IFERROR(__xludf.DUMMYFUNCTION("FILTER('GBD estimates'!$BN$4:$BN$54,'GBD estimates'!$BI$4:$BI$54=X$3)"),361.0521294) -> 361.05213 | Y30: =IFERROR(__xludf.DUMMYFUNCTION("FILTER('GBD estimates'!$AD$4:$AD$54,'GBD estimates'!$X$4:$X$54=Y$2)"),168.6683554) -> 168.66836 | Z30: 339.43659 | AB30: GBD 2019
E31: Total number of months of life in which children are under 5 years old | F31: # | G31: input | H31: 60 | I31: - | J31: - | K31: - | L31: - | M31: - | N31: - | O31: - | P31: - | Q31: - | R31: - | S31: - | T31: - | U31: - | V31: - | W31: - | X31: - | Y31: - | Z31: -
E32: Number of months of life in which children are under 3 months old | F32: # | G32: input | H32: 3 | I32: - | J32: - | K32: - | L32: - | M32: - | N32: - | O32: - | P32: - | Q32: - | R32: - | S32: - | T32: - | U32: - | V32: - | W32: - | X32: - | Y32: - | Z32: -
E33: Adjustment for malaria averted by ITN distributions not accounted for in GBD 2019 | F33: % | G33: input | H33: - | I33: 0 | J33: 0 | K33: 0 | L33: 0 | M33: 0 | N33: 0 | O33: 0 | P33: -0.05 | Q33: -0.05 | R33: -0.3512063 | S33: -0.05 | T33: -0.05 | U33: -0.05 | V33: -0.05 | W33: -0.05 | X33: -0.05 | Y33: 0 | Z33: 0 | AB33: GW guesstimate
C35: Proportion of malaria mortalities that are among the SMC-eligible population
E36: Total malaria mortalities per year | F36: # | G36: input | H36: - | I36: =IFERROR(__xludf.DUMMYFUNCTION("FILTER('GBD estimates'!$S$4:$S$309,'GBD estimates'!$M$4:$M$309=I$2,'GBD estimates'!$O$4:$O$309=""All ages"")"),26304.7468000016) -> 26304.747 | J36: =IFERROR(__xludf.DUMMYFUNCTION("FILTER('GBD estimates'!$S$4:$S$309,'GBD estimates'!$M$4:$M$309=J$2,'GBD estimates'!$O$4:$O$309=""All ages"")"),7194.19944040964) -> 7194.1994 | K36: 5327.419 | L36: 4674.157 | M36: 1357.633 | N36: 4865.658 | O36: 6890 | P36: =IFERROR(__xludf.DUMMYFUNCTION("FILTER('GBD estimates'!$BA$4:$BA$258,'GBD estimates'!$AV$4:$AV$258=P$3,'GBD estimates'!$AU$4:$AU$258=""All ages"")"),4545.106485) -> 4545.1065 | Q36: =IFERROR(__xludf.DUMMYFUNCTION("FILTER('GBD estimates'!$BA$4:$BA$258,'GBD estimates'!$AV$4:$AV$258=Q$3,'GBD estimates'!$AU$4:$AU$258=""All ages"")"),3093.504749) -> 3093.5047 | R36: =IFERROR(__xludf.DUMMYFUNCTION("FILTER('GBD estimates'!$BA$4:$BA$258,'GBD estimates'!$AV$4:$AV$258=R$3,'GBD estimates'!$AU$4:$AU$258=""All ages"")"),4417.546406) -> 4417.5464 | S36: =IFERROR(__xludf.DUMMYFUNCTION("FILTER('GBD estimates'!$BA$4:$BA$258,'GBD estimates'!$AV$4:$AV$258=S$3,'GBD estimates'!$AU$4:$AU$258=""All ages"")"),4606.794083) -> 4606.7941 | T36: =IFERROR(__xludf.DUMMYFUNCTION("FILTER('GBD estimates'!$BA$4:$BA$258,'GBD estimates'!$AV$4:$AV$258=T$3,'GBD estimates'!$AU$4:$AU$258=""All ages"")"),2471.067612) -> 2471.0676 | U36: =IFERROR(__xludf.DUMMYFUNCTION("FILTER('GBD estimates'!$BA$4:$BA$258,'GBD estimates'!$AV$4:$AV$258=U$3,'GBD estimates'!$AU$4:$AU$258=""All ages"")"),4449.598839) -> 4449.5988 | V36: =IFERROR(__xludf.DUMMYFUNCTION("FILTER('GBD estimates'!$BA$4:$BA$258,'GBD estimates'!$AV$4:$AV$258=V$3,'GBD estimates'!$AU$4:$AU$258=""All ages"")"),7026.505839) -> 7026.5058 | W36: =IFERROR(__xludf.DUMMYFUNCTION("FILTER('GBD estimates'!$BA$4:$BA$258,'GBD estimates'!$AV$4:$AV$258=W$3,'GBD estimates'!$AU$4:$AU$258=""All ages"")"),6892.924992) -> 6892.925 | X36: =IFERROR(__xludf.DUMMYFUNCTION("FILTER('GBD estimates'!$BA$4:$BA$258,'GBD estimates'!$AV$4:$AV$258=X$3,'GBD estimates'!$AU$4:$AU$258=""All ages"")"),6247.24128) -> 6247.2413 | Y36: =IFERROR(__xludf.DUMMYFUNCTION("FILTER('GBD estimates'!$S$4:$S$309,'GBD estimates'!$M$4:$M$309=Y$2,'GBD estimates'!$O$4:$O$309=""All ages"")"),5436.18786097608) -> 5436.1879 | Z36: 4838 | AB36: GBD 2019
C38: Malaria incidence among people under age 15
E39: Malaria incidence among people age 1 to 4 | F39: per 100k | G39: input | H39: - | I39: =IFERROR(__xludf.DUMMYFUNCTION("FILTER('GBD estimates'!$AO$4:$AO$105,'GBD estimates'!$AI$4:$AI$105=I$2,'GBD estimates'!$AK$4:$AK$105=""1-4 years"")"),60060.98378) -> 60060.984 | J39: =IFERROR(__xludf.DUMMYFUNCTION("FILTER('GBD estimates'!$AO$4:$AO$105,'GBD estimates'!$AI$4:$AI$105=J$2,'GBD estimates'!$AK$4:$AK$105=""1-4 years"")"),37423.26557) -> 37423.266 | K39: 30731.36 | L39: 37447.9 | M39: 35364.66 | N39: 35102.89 | O39: 36327.33 | P39: =IFERROR(__xludf.DUMMYFUNCTION("FILTER('GBD estimates'!$CA$4:$CA$105,'GBD estimates'!$BV$4:$BV$105=P$3,'GBD estimates'!$BU$4:$BU$105=""1 to 4"")"),47661.90624) -> 47661.906 | Q39: =IFERROR(__xludf.DUMMYFUNCTION("FILTER('GBD estimates'!$CA$4:$CA$105,'GBD estimates'!$BV$4:$BV$105=Q$3,'GBD estimates'!$BU$4:$BU$105=""1 to 4"")"),49206.23234) -> 49206.232 | R39: =IFERROR(__xludf.DUMMYFUNCTION("FILTER('GBD estimates'!$CA$4:$CA$105,'GBD estimates'!$BV$4:$BV$105=R$3,'GBD estimates'!$BU$4:$BU$105=""1 to 4"")"),81529.9384) -> 81529.938 | S39: =IFERROR(__xludf.DUMMYFUNCTION("FILTER('GBD estimates'!$CA$4:$CA$105,'GBD estimates'!$BV$4:$BV$105=S$3,'GBD estimates'!$BU$4:$BU$105=""1 to 4"")"),85869.02616) -> 85869.026 | T39: =IFERROR(__xludf.DUMMYFUNCTION("FILTER('GBD estimates'!$CA$4:$CA$105,'GBD estimates'!$BV$4:$BV$105=T$3,'GBD estimates'!$BU$4:$BU$105=""1 to 4"")"),76182.96693) -> 76182.967 | U39: =IFERROR(__xludf.DUMMYFUNCTION("FILTER('GBD estimates'!$CA$4:$CA$105,'GBD estimates'!$BV$4:$BV$105=U$3,'GBD estimates'!$BU$4:$BU$105=""1 to 4"")"),89798.63281) -> 89798.633 | V39: =IFERROR(__xludf.DUMMYFUNCTION("FILTER('GBD estimates'!$CA$4:$CA$105,'GBD estimates'!$BV$4:$BV$105=V$3,'GBD estimates'!$BU$4:$BU$105=""1 to 4"")"),130288.462) -> 130288.46 | W39: =IFERROR(__xludf.DUMMYFUNCTION("FILTER('GBD estimates'!$CA$4:$CA$105,'GBD estimates'!$BV$4:$BV$105=W$3,'GBD estimates'!$BU$4:$BU$105=""1 to 4"")"),63655.29509) -> 63655.295 | X39: =IFERROR(__xludf.DUMMYFUNCTION("FILTER('GBD estimates'!$CA$4:$CA$105,'GBD estimates'!$BV$4:$BV$105=X$3,'GBD estimates'!$BU$4:$BU$105=""1 to 4"")"),69580.73086) -> 69580.731 | Y39: =IFERROR(__xludf.DUMMYFUNCTION("FILTER('GBD estimates'!$AO$4:$AO$105,'GBD estimates'!$AI$4:$AI$105=Y$2,'GBD estimates'!$AK$4:$AK$105=""1-4 years"")"),79106.01535) -> 79106.015 | Z39: 34522.23 | AB39: GBD 2019
E40: Malaria incidence among people age 5 to 14 | F40: per 100k | G40: input | H40: - | I40: =IFERROR(__xludf.DUMMYFUNCTION("FILTER('GBD estimates'!$AO$4:$AO$105,'GBD estimates'!$AI$4:$AI$105=I$2,'GBD estimates'!$AK$4:$AK$105=""5-14 years"")"),24693.60871) -> 24693.609 | J40: =IFERROR(__xludf.DUMMYFUNCTION("FILTER('GBD estimates'!$AO$4:$AO$105,'GBD estimates'!$AI$4:$AI$105=J$2,'GBD estimates'!$AK$4:$AK$105=""5-14 years"")"),16222.6214) -> 16222.621 | K40: 30731.36 | L40: 37447.9 | M40: 35364.66 | N40: 35102.89 | O40: 36327.33 | P40: =IFERROR(__xludf.DUMMYFUNCTION("FILTER('GBD estimates'!$CA$4:$CA$105,'GBD estimates'!$BV$4:$BV$105=P$3,'GBD estimates'!$BU$4:$BU$105=""5 to 14"")"),19593.14817) -> 19593.148 | Q40: =IFERROR(__xludf.DUMMYFUNCTION("FILTER('GBD estimates'!$CA$4:$CA$105,'GBD estimates'!$BV$4:$BV$105=Q$3,'GBD estimates'!$BU$4:$BU$105=""5 to 14"")"),20783.80124) -> 20783.801 | R40: =IFERROR(__xludf.DUMMYFUNCTION("FILTER('GBD estimates'!$CA$4:$CA$105,'GBD estimates'!$BV$4:$BV$105=R$3,'GBD estimates'!$BU$4:$BU$105=""5 to 14"")"),31209.9027) -> 31209.903 | S40: =IFERROR(__xludf.DUMMYFUNCTION("FILTER('GBD estimates'!$CA$4:$CA$105,'GBD estimates'!$BV$4:$BV$105=S$3,'GBD estimates'!$BU$4:$BU$105=""5 to 14"")"),33795.62909) -> 33795.629 | T40: =IFERROR(__xludf.DUMMYFUNCTION("FILTER('GBD estimates'!$CA$4:$CA$105,'GBD estimates'!$BV$4:$BV$105=T$3,'GBD estimates'!$BU$4:$BU$105=""5 to 14"")"),29812.0385) -> 29812.038 | U40: =IFERROR(__xludf.DUMMYFUNCTION("FILTER('GBD estimates'!$CA$4:$CA$105,'GBD estimates'!$BV$4:$BV$105=U$3,'GBD estimates'!$BU$4:$BU$105=""5 to 14"")"),33528.33274) -> 33528.333 | V40: =IFERROR(__xludf.DUMMYFUNCTION("FILTER('GBD estimates'!$CA$4:$CA$105,'GBD estimates'!$BV$4:$BV$105=V$3,'GBD estimates'!$BU$4:$BU$105=""5 to 14"")"),48687.08739) -> 48687.087 | W40: =IFERROR(__xludf.DUMMYFUNCTION("FILTER('GBD estimates'!$CA$4:$CA$105,'GBD estimates'!$BV$4:$BV$105=W$3,'GBD estimates'!$BU$4:$BU$105=""5 to 14"")"),25166.99536) -> 25166.995 | X40: =IFERROR(__xludf.DUMMYFUNCTION("FILTER('GBD estimates'!$CA$4:$CA$105,'GBD estimates'!$BV$4:$BV$105=X$3,'GBD estimates'!$BU$4:$BU$105=""5 to 14"")"),28680.35419) -> 28680.354 | Y40: =IFERROR(__xludf.DUMMYFUNCTION("FILTER('GBD estimates'!$AO$4:$AO$105,'GBD estimates'!$AI$4:$AI$105=Y$2,'GBD estimates'!$AK$4:$AK$105=""5-14 years"")"),30845.0741) -> 30845.074 | Z40: 34522.23 | AB40: GBD 2019
A42: Outcomes
C44: Mortality reduction among people under age 5
