Workbook

Sheet How we think about moral weight
B2: How GiveWell thinks about moral weights GiveWell's "moral weights" are a set of subjective numerical values that represent how much value we place on different types of outcomes achieved by the programs we fund, like increasing consumption and averting mortalities. We use moral weights so we can directly compare the cost-effectiveness of programs that achieve different types of outcomes. You can read more about how we arrived at the moral weights we use in our cost-effectiveness analyses in this write-up: GiveWell's 2020 moral weights. You can read more about how we use cost-effectiveness estimates in our grantmaking on this page: How We Use Cost-Effectiveness Estimates in Our Grantmaking.
B11: Important! After you've made a copy of this workbook, you may need to click on the "#REF" cell to the right of this textbox and select "Allow access" | H11: ➞ | I11: =IFERROR(__xludf.DUMMYFUNCTION("IMPORTRANGE(""https://docs.google.com/spreadsheets/d/1LyeZB70UrgDgyjoBvDr9VsAwuvcesheuM08g2qeYr94/edit?usp=sharing"",""How we think about moral weights (start here)!I11"")"),"Nice. You're all set!") -> Nice. You're all set!

Sheet Your moral weights
B2: How to use this tool: This tool lets you to explore how cost-effective GiveWell's top charity programs would be if our analyses were build on your intuitions about moral weights instead of ours. There are two major factors informing our framework for moral weights: (1) how highly we value averting deaths relative to increasing consumption, and (2) how highly we value averting deaths at different ages. In the leftmost table, you will see three options for turning your moral intuitions in moral weight values that can be plugged into our cost-effectiveness analysis. We recommend using Option 1 if you're mostly interested in updating how highly deaths averted are weighted relative to increasing consumption. For Option 1, you just need to enter a value into Cell C9 in the leftmost table. We recommend Option 2 if you'd prefer to enter all of your moral weight values for different interventions and age groups manually. We've also included an Option 3 if you're interested in changing how deaths averted are weighted at different ages at a more granular level. For Option 3, you should enter your moral weights into the center table. The default option is Option 1. If you'd like to input your moral weights using Options 2 or 3, scroll down to the bottom of the leftmost table and select your desired option from the dropdown in the bottom row. Once you've entered your moral weights, the rightmost table will populate with the cost-effectiveness of GiveWell's top charity programs using your chosen moral weights! You can sort the programs by charity, country, or cost-effectiveness using the filters in the header row.
B4: Description | C4: Your value | D4: GW's value | E4: Explanation | G4: Value of averting mortalities by age | M4: How GiveWell's top charity programs stack up using your moral weights
B5: Increasing consumption | G5: Age | H5: Your moral weights | I5: GW's moral weights | J5: % of malaria deaths | K5: % of deaths for VAS | M5: Charity | N5: Country | O5: Region | P5: Cost-effectiveness in "x cash" using GW weights | Q5: Cost-effectiveness in "x cash" using your weights
B6: Value of doubling one person's consumption for one year | C6: 1 | D6: 1 | E6: It's best to leave this value at 1, as it will be the benchmark for the rest of your moral weights! | G6: <1 week | I6: 83.6 | J6: 0 | K6: - | M6: Helen Keller International | N6: Niger | P6: ='Cost-effectiveness of top chari'!$AL40 -> 58.9 | Q6: ='Cost-effectiveness of top chari'!$AL41 -> 0
B7: Derived value of increasing ln(consumption) by one unit | C7: =C6/ln(2) -> 1.442695 | D7: =D6/ln(2) -> 1.442695 | E7: This value is calculated. No need to update! | G7: 1 week to 1 month | I7: 84.5 | J7: 0.0308 | K7: - | M7: New Incentives | N7: Nigeria | O7: Sokoto | P7: ='Cost-effectiveness of top chari'!$BI40 -> 41.6 | Q7: ='Cost-effectiveness of top chari'!$BI41 -> 0
B8: Averting mortalities (Option 1: Using a simple comparison between income and mortality) | G8: 1 month to 1 year | I8: 100.7 | J8: 0.1912 | K8: 0.32 | M8: New Incentives | N8: Nigeria | O8: Zamfara | P8: ='Cost-effectiveness of top chari'!$BJ40 -> 32.7 | Q8: ='Cost-effectiveness of top chari'!$BJ41 -> 0
B9: Desired ratio of your moral weights for mortalities averted relative to consumpion increases compared to GiveWell's | D9: - | E9: I would like to value consumption increases at ___x what GiveWell does | G9: 1-4 years | I9: 127.3 | J9: 0.3577 | K9: 0.68 | M9: Helen Keller International | N9: Mali | P9: ='Cost-effectiveness of top chari'!$AK40 -> 32.6 | Q9: ='Cost-effectiveness of top chari'!$AK41 -> 0
B10: Value of averting the death of a person under age 5 for malaria interventions | C10: =IF(C$9="","-",D10*(1/C$9)) -> - | D10: 116.25 | E10: For option 1, these values are calculated. No need to update! | G10: 5-9 years | I10: 134.3 | J10: 0.0326 | K10: - | M10: New Incentives | N10: Nigeria | O10: Kebbi | P10: ='Cost-effectiveness of top chari'!$BH40 -> 31.4 | Q10: ='Cost-effectiveness of top chari'!$BH41 -> 0
B11: Value of averting the death of a person under age 5 for vitamin A supplementation | C11: =IF(C$9="","-",D11*(1/C$9)) -> - | D11: 118.73 | G11: 10-14 years | I11: 133.1 | J11: 0.0178 | K11: - | M11: Malaria Consortium | N11: Nigeria | O11: Sokoto | P11: ='Cost-effectiveness of top chari'!$AA40 -> 29.6 | Q11: ='Cost-effectiveness of top chari'!$AA41 -> 0
B12: Value of averting the death of a person age 5 or older for malaria interventions | C12: =IF(C$9="","-",D12*(1/C$9)) -> - | D12: 73.19 | G12: 15-19 years | I12: 126.3 | J12: 0.0215 | K12: - | M12: Malaria Consortium | N12: Nigeria | O12: Kebbi | P12: ='Cost-effectiveness of top chari'!$V40 -> 29.2 | Q12: ='Cost-effectiveness of top chari'!$V41 -> 0
B13: Value of averting the death of a person age 5 through 14 for vaccine interventions | C13: =IF(C$9="","-",D13*(1/C$9)) -> - | D13: 133.7 | G13: 20-24 years | I13: 118 | J13: 0.0221 | K13: - | M13: Helen Keller International | N13: Nigeria | O13: Taraba | P13: ='Cost-effectiveness of top chari'!$BA40 -> 28.7 | Q13: ='Cost-effectiveness of top chari'!$BA41 -> 0
B14: Value of averting the death of a person age 15 through 49 for vaccine interventions | C14: =IF(C$9="","-",D14*(1/C$9)) -> - | D14: 103.59 | G14: 25-29 years | I14: 112.7 | J14: 0.019 | K14: - | M14: Malaria Consortium | N14: Nigeria | O14: Oyo | P14: ='Cost-effectiveness of top chari'!$Y40 -> 24.2 | Q14: ='Cost-effectiveness of top chari'!$Y41 -> 0
B15: Value of averting the death of a person age 50 through 74 for vaccine interventions | C15: =IF(C$9="","-",D15*(1/C$9)) -> - | D15: 42.44 | G15: 30-34 years | I15: 106.3 | J15: 0.0189 | K15: - | M15: New Incentives | N15: Nigeria | O15: Bauchi | P15: ='Cost-effectiveness of top chari'!$BB40 -> 21.4 | Q15: ='Cost-effectiveness of top chari'!$BB41 -> 0
B16: Averting mortalities (Option 2: Using all manual inputs) | G16: 35-39 years | I16: 99.7 | J16: 0.0209 | K16: - | M16: Against Malaria Foundation | N16: Guinea | P16: ='Cost-effectiveness of top chari'!$F40 -> 22.6 | Q16: ='Cost-effectiveness of top chari'!$F41 -> 0
B17: Value of averting the death of a person under age 5 for malaria interventions | D17: 116.25 | E17: Averting one of these deaths is morally equivalent to doubling ___ people's consumption for one year. | G17: 40-44 years | I17: 86.4 | J17: 0.0248 | K17: - | M17: Helen Keller International | N17: Burkina Faso | P17: ='Cost-effectiveness of top chari'!$AD40 -> 22.4 | Q17: ='Cost-effectiveness of top chari'!$AD41 -> 0
B18: Value of averting the death of a person under age 5 for vitamin A supplementation | D18: 118.73 | G18: 45-49 years | I18: 75.7 | J18: 0.0271 | K18: - | M18: Malaria Consortium | N18: Nigeria | O18: Nasarawa | P18: ='Cost-effectiveness of top chari'!$X40 -> 22.2 | Q18: ='Cost-effectiveness of top chari'!$X41 -> 0
B19: Value of averting the death of a person age 5 or older for malaria interventions | D19: 73.19 | G19: 50-54 years | I19: 65.2 | J19: 0.0329 | K19: - | M19: Helen Keller International | N19: Nigeria | O19: Adamawa | P19: ='Cost-effectiveness of top chari'!$AM40 -> 21.3 | Q19: ='Cost-effectiveness of top chari'!$AM41 -> 0
B20: Value of averting the death of a person age 5 through 14 for vaccine interventions | D20: 133.7 | G20: 55-59 years | I20: 54.8 | J20: 0.0369 | K20: - | M20: Malaria Consortium | N20: Nigeria | O20: Bauchi | P20: ='Cost-effectiveness of top chari'!$S40 -> 21.1 | Q20: ='Cost-effectiveness of top chari'!$S41 -> 0
B21: Value of averting the death of a person age 15 through 49 for vaccine interventions | D21: 103.59 | G21: 60-64 years | I21: 39.6 | J21: 0.0416 | K21: - | M21: Malaria Consortium | N21: Nigeria | O21: Kogi | P21: ='Cost-effectiveness of top chari'!$W40 -> 20.9 | Q21: ='Cost-effectiveness of top chari'!$W41 -> 0
B22: Value of averting the death of a person age 50 through 74 for vaccine interventions | D22: 42.44 | G22: 65-69 years | I22: 31.4 | J22: 0.0374 | K22: - | M22: New Incentives | N22: Nigeria | O22: Katsina | P22: ='Cost-effectiveness of top chari'!$BG40 -> 17.8 | Q22: ='Cost-effectiveness of top chari'!$BG41 -> 0
B23: Averting mortalities (Option 3: Using a custom age breakdown) | G23: 70-74 years | I23: 21.2 | J23: 0.0407 | K23: - | M23: New Incentives | N23: Nigeria | O23: Jigawa | P23: ='Cost-effectiveness of top chari'!$BD40 -> 19.5 | Q23: ='Cost-effectiveness of top chari'!$BD41 -> 0
B24: Value of averting the death of a person under age 5 for malaria interventions | C24: =IF(H9="","-",SUMPRODUCT(H6:H9,J6:J9)/SUM(J6:J9)) -> - | D24: 116.25 | E24: For option 3, these values are calculated using the values you enter in the age breakdown table to the right. No need to update! | G24: 75-79 yeras | I24: 16.5 | J24: 0.0182 | K24: - | M24: Malaria Consortium | N24: Nigeria | O24: Borno | P24: ='Cost-effectiveness of top chari'!$T40 -> 17.9 | Q24: ='Cost-effectiveness of top chari'!$T41 -> 0
B25: Value of averting the death of a person under age 5 for vitamin A supplementation | C25: =IF(H9="","-",SUMPRODUCT(H8:H9,K8:K9)/SUM(K8:K9)) -> - | D25: 118.73 | G25: 80-84 years | I25: 12.4 | J25: 0.0065 | K25: - | M25: Malaria Consortium | N25: Burkina Faso | P25: ='Cost-effectiveness of top chari'!$L40 -> 17.9 | Q25: ='Cost-effectiveness of top chari'!$L41 -> 0
B26: Value of averting the death of a person age 5 or older for malaria interventions | C26: =IF(H9="","-",SUMPRODUCT(H10:H26,J10:J26)/SUM(J10:J26)) -> - | D26: 73.19 | G26: >85 years | I26: 12.4 | J26: 0.0013 | K26: - | M26: Helen Keller International | N26: DRC | P26: ='Cost-effectiveness of top chari'!$AG40 -> 16.8 | Q26: ='Cost-effectiveness of top chari'!$AG41 -> 0
B27: Value of averting the death of a person age 5 through 14 for vaccine interventions | C27: =IFERROR(AVERAGE(H10:H11),"-") -> - | D27: 133.7 | M27: Against Malaria Foundation | N27: Nigeria | O27: GF states | P27: ='Cost-effectiveness of top chari'!$G40 -> 16.7 | Q27: ='Cost-effectiveness of top chari'!$G41 -> 0
B28: Value of averting the death of a person age 15 through 49 for vaccine interventions | C28: =IFERROR(AVERAGE(H12:H18),"-") -> - | D28: 103.59 | M28: Malaria Consortium | N28: Nigeria | O28: FCT (Abuja) | P28: ='Cost-effectiveness of top chari'!$U40 -> 16 | Q28: ='Cost-effectiveness of top chari'!$U41 -> 0
B29: Value of averting the death of a person age 50 through 74 for vaccine interventions | C29: =IFERROR(AVERAGE(H19:H23),"-") -> - | D29: 42.44 | M29: Malaria Consortium | N29: Nigeria | O29: Plateau | P29: ='Cost-effectiveness of top chari'!$Z40 -> 15.9 | Q29: ='Cost-effectiveness of top chari'!$Z41 -> 0
B30: Which of the above options did you use? | E30: Option 1 | M30: Helen Keller International | N30: Cameroon | P30: ='Cost-effectiveness of top chari'!$AE40 -> 15.8 | Q30: ='Cost-effectiveness of top chari'!$AE41 -> 0
M31: Helen Keller International | N31: Madagascar | P31: ='Cost-effectiveness of top chari'!$AJ40 -> 15.8 | Q31: ='Cost-effectiveness of top chari'!$AJ41 -> 0
M32: Against Malaria Foundation | N32: Uganda | P32: ='Cost-effectiveness of top chari'!$K40 -> 15.5 | Q32: ='Cost-effectiveness of top chari'!$K41 -> 0
M33: Against Malaria Foundation | N33: DRC | P33: ='Cost-effectiveness of top chari'!$E40 -> 14.5 | Q33: ='Cost-effectiveness of top chari'!$E41 -> 0
M34: Helen Keller International | N34: Nigeria | O34: Ebonyi | P34: ='Cost-effectiveness of top chari'!$AR40 -> 13.4 | Q34: ='Cost-effectiveness of top chari'!$AR41 -> 0
M35: New Incentives | N35: Nigeria | O35: Kano | P35: ='Cost-effectiveness of top chari'!$BF40 -> 13.3 | Q35: ='Cost-effectiveness of top chari'!$BF41 -> 0
M36: Against Malaria Foundation | N36: Nigeria | O36: PMI states | P36: ='Cost-effectiveness of top chari'!$H40 -> 13.2 | Q36: ='Cost-effectiveness of top chari'!$H41 -> 0
M37: Malaria Consortium | N37: DRC | O37: Tanganyika | P37: ='Cost-effectiveness of top chari'!$Q40 -> 12.5 | Q37: ='Cost-effectiveness of top chari'!$Q41 -> 0
M38: Helen Keller International | N38: Nigeria | O38: Nasarawa | P38: ='Cost-effectiveness of top chari'!$AW40 -> 11.9 | Q38: ='Cost-effectiveness of top chari'!$AW41 -> 0
M39: Malaria Consortium | N39: Mozambique | O39: Nampula | P39: ='Cost-effectiveness of top chari'!$R40 -> 11.4 | Q39: ='Cost-effectiveness of top chari'!$R41 -> 0
M40: New Incentives | N40: Nigeria | O40: Gombe | P40: ='Cost-effectiveness of top chari'!$BC40 -> 10.8 | Q40: ='Cost-effectiveness of top chari'!$BC41 -> 0
M41: Helen Keller International | N41: Guinea | P41: ='Cost-effectiveness of top chari'!$AH40 -> 10.9 | Q41: ='Cost-effectiveness of top chari'!$AH41 -> 0
M42: Malaria Consortium | N42: Togo | P42: ='Cost-effectiveness of top chari'!$AB40 -> 10.5 | Q42: ='Cost-effectiveness of top chari'!$AB41 -> 0
...

Sheet Cost-effectiveness of top chari
C2: https://docs.google.com/spreadsheets/d/1VEtie59TgRvZSEVjfG7qcKBKcQyJn8zO91Lau9YNqXc/edit?usp=sharing | D2: Against Malaria Foundation CEA
C3: https://docs.google.com/spreadsheets/d/1fUZFe-pDvRqXdZVnyvCUdKYs7BgX9S7a5qBEVwwqrzQ/edit?usp=sharing | D3: Malaria Consortium CEA
C4: https://docs.google.com/spreadsheets/d/1NcR1RR3WyCqSjbqgPHuafNXtm4hSeIz66eZlX69k_80/edit?usp=sharing | D4: Helen Keller International CEA
C5: https://docs.google.com/spreadsheets/d/11WUg59i_kWye42fO45cpMmD-O0wFX_CioJl0D19Suyg/edit?usp=sharing | D5: New Incentives CEA
D7: Against Malaria Foundation | L7: Malaria Consortium | U7: Malaria Consortium | AD7: Helen Keller International | AL7: Helen Keller International | AT7: Helen Keller International | BB7: New Incentives – current states of operation | BK7: New Incentives – prospective states | BT7: New Incentives – prospective states | CC7: New Incentives – prospective states
D8: =$C2 -> https://docs.google.com/spreadsheets/d/1VEtie59TgRvZSEVjfG7qcKBKcQyJn8zO91Lau9YNqXc/edit?usp=sharing | E8: =$C2 -> https://docs.google.com/spreadsheets/d/1VEtie59TgRvZSEVjfG7qcKBKcQyJn8zO91Lau9YNqXc/edit?usp=sharing | F8: =$C2 -> https://docs.google.com/spreadsheets/d/1VEtie59TgRvZSEVjfG7qcKBKcQyJn8zO91Lau9YNqXc/edit?usp=sharing | G8: =$C2 -> https://docs.google.com/spreadsheets/d/1VEtie59TgRvZSEVjfG7qcKBKcQyJn8zO91Lau9YNqXc/edit?usp=sharing | H8: =$C2 -> https://docs.google.com/spreadsheets/d/1VEtie59TgRvZSEVjfG7qcKBKcQyJn8zO91Lau9YNqXc/edit?usp=sharing | I8: =$C2 -> https://docs.google.com/spreadsheets/d/1VEtie59TgRvZSEVjfG7qcKBKcQyJn8zO91Lau9YNqXc/edit?usp=sharing | J8: =$C2 -> https://docs.google.com/spreadsheets/d/1VEtie59TgRvZSEVjfG7qcKBKcQyJn8zO91Lau9YNqXc/edit?usp=sharing | K8: =$C2 -> https://docs.google.com/spreadsheets/d/1VEtie59TgRvZSEVjfG7qcKBKcQyJn8zO91Lau9YNqXc/edit?usp=sharing | L8: =$C3 -> https://docs.google.com/spreadsheets/d/1fUZFe-pDvRqXdZVnyvCUdKYs7BgX9S7a5qBEVwwqrzQ/edit?usp=sharing | M8: =$C3 -> https://docs.google.com/spreadsheets/d/1fUZFe-pDvRqXdZVnyvCUdKYs7BgX9S7a5qBEVwwqrzQ/edit?usp=sharing | N8: =$C3 -> https://docs.google.com/spreadsheets/d/1fUZFe-pDvRqXdZVnyvCUdKYs7BgX9S7a5qBEVwwqrzQ/edit?usp=sharing | O8: =$C3 -> https://docs.google.com/spreadsheets/d/1fUZFe-pDvRqXdZVnyvCUdKYs7BgX9S7a5qBEVwwqrzQ/edit?usp=sharing | P8: =$C3 -> https://docs.google.com/spreadsheets/d/1fUZFe-pDvRqXdZVnyvCUdKYs7BgX9S7a5qBEVwwqrzQ/edit?usp=sharing | Q8: =$C3 -> https://docs.google.com/spreadsheets/d/1fUZFe-pDvRqXdZVnyvCUdKYs7BgX9S7a5qBEVwwqrzQ/edit?usp=sharing | R8: =$C3 -> https://docs.google.com/spreadsheets/d/1fUZFe-pDvRqXdZVnyvCUdKYs7BgX9S7a5qBEVwwqrzQ/edit?usp=sharing | S8: =$C3 -> https://docs.google.com/spreadsheets/d/1fUZFe-pDvRqXdZVnyvCUdKYs7BgX9S7a5qBEVwwqrzQ/edit?usp=sharing | ... AC8: =$C3 -> https://docs.google.com/spreadsheets/d/1fUZFe-pDvRqXdZVnyvCUdKYs7BgX9S7a5qBEVwwqrzQ/edit?usp=sharing | AD8: =$C4 -> https://docs.google.com/spreadsheets/d/1NcR1RR3WyCqSjbqgPHuafNXtm4hSeIz66eZlX69k_80/edit?usp=sharing | AE8: =$C4 -> https://docs.google.com/spreadsheets/d/1NcR1RR3WyCqSjbqgPHuafNXtm4hSeIz66eZlX69k_80/edit?usp=sharing | AF8: =$C4 -> https://docs.google.com/spreadsheets/d/1NcR1RR3WyCqSjbqgPHuafNXtm4hSeIz66eZlX69k_80/edit?usp=sharing | AG8: =$C4 -> https://docs.google.com/spreadsheets/d/1NcR1RR3WyCqSjbqgPHuafNXtm4hSeIz66eZlX69k_80/edit?usp=sharing | AH8: =$C4 -> https://docs.google.com/spreadsheets/d/1NcR1RR3WyCqSjbqgPHuafNXtm4hSeIz66eZlX69k_80/edit?usp=sharing | AI8: =$C4 -> https://docs.google.com/spreadsheets/d/1NcR1RR3WyCqSjbqgPHuafNXtm4hSeIz66eZlX69k_80/edit?usp=sharing | AJ8: =$C4 -> https://docs.google.com/spreadsheets/d/1NcR1RR3WyCqSjbqgPHuafNXtm4hSeIz66eZlX69k_80/edit?usp=sharing | AK8: =$C4 -> https://docs.google.com/spreadsheets/d/1NcR1RR3WyCqSjbqgPHuafNXtm4hSeIz66eZlX69k_80/edit?usp=sharing | ... BA8: =$C4 -> https://docs.google.com/spreadsheets/d/1NcR1RR3WyCqSjbqgPHuafNXtm4hSeIz66eZlX69k_80/edit?usp=sharing | BB8: =$C5 -> https://docs.google.com/spreadsheets/d/11WUg59i_kWye42fO45cpMmD-O0wFX_CioJl0D19Suyg/edit?usp=sharing | BC8: =$C5 -> https://docs.google.com/spreadsheets/d/11WUg59i_kWye42fO45cpMmD-O0wFX_CioJl0D19Suyg/edit?usp=sharing | BD8: =$C5 -> https://docs.google.com/spreadsheets/d/11WUg59i_kWye42fO45cpMmD-O0wFX_CioJl0D19Suyg/edit?usp=sharing | BE8: =$C5 -> https://docs.google.com/spreadsheets/d/11WUg59i_kWye42fO45cpMmD-O0wFX_CioJl0D19Suyg/edit?usp=sharing | BF8: =$C5 -> https://docs.google.com/spreadsheets/d/11WUg59i_kWye42fO45cpMmD-O0wFX_CioJl0D19Suyg/edit?usp=sharing | BG8: =$C5 -> https://docs.google.com/spreadsheets/d/11WUg59i_kWye42fO45cpMmD-O0wFX_CioJl0D19Suyg/edit?usp=sharing | BH8: =$C5 -> https://docs.google.com/spreadsheets/d/11WUg59i_kWye42fO45cpMmD-O0wFX_CioJl0D19Suyg/edit?usp=sharing | BI8: =$C5 -> https://docs.google.com/spreadsheets/d/11WUg59i_kWye42fO45cpMmD-O0wFX_CioJl0D19Suyg/edit?usp=sharing | ... CL8: =$C5 -> https://docs.google.com/spreadsheets/d/11WUg59i_kWye42fO45cpMmD-O0wFX_CioJl0D19Suyg/edit?usp=sharing
D9: Chad | E9: DRC | F9: Guinea | G9: Nigeria | H9: Nigeria | I9: South Sudan | J9: Togo | K9: Uganda | L9: Burkina Faso | M9: Chad | N9: DRC | O9: DRC | P9: DRC | Q9: DRC | R9: Mozambique | S9: Nigeria | T9: Nigeria | U9: Nigeria | V9: Nigeria | W9: Nigeria | X9: Nigeria | Y9: Nigeria | Z9: Nigeria | AA9: Nigeria | AB9: Togo | AC9: Uganda | AD9: Burkina Faso | AE9: Cameroon | AF9: Côte d'Ivoire | AG9: DRC | AH9: Guinea | AI9: Kenya | AJ9: Madagascar | AK9: Mali | AL9: Niger | AM9: Nigeria | AN9: Nigeria | AO9: Nigeria | AP9: Nigeria | AQ9: Nigeria | AR9: Nigeria | AS9: Nigeria | AT9: Nigeria | AU9: Nigeria | AV9: Nigeria | AW9: Nigeria | AX9: Nigeria | AY9: Nigeria | AZ9: Nigeria | BA9: Nigeria | BB9: Nigeria | BC9: Nigeria | BD9: Nigeria | BE9: Nigeria | BF9: Nigeria | BG9: Nigeria | BH9: Nigeria | BI9: Nigeria | BJ9: Nigeria | BK9: Nigeria | BL9: Nigeria | BM9: Nigeria | BN9: Nigeria | BO9: Nigeria | BP9: Nigeria | BQ9: Nigeria | BR9: Nigeria | BS9: Nigeria | BT9: Nigeria | BU9: Nigeria | BV9: Nigeria | BW9: Nigeria | BX9: Nigeria | BY9: Nigeria | BZ9: Nigeria | CA9: Nigeria | CB9: Nigeria | CC9: Nigeria | CD9: Nigeria | CE9: Nigeria | CF9: Nigeria | CG9: Nigeria | CH9: Nigeria | CI9: Nigeria | CJ9: Nigeria | CK9: Nigeria | CL9: Nigeria
G10: GF states | H10: PMI states | N10: Haut-Katanga | O10: Haut-Lomami | P10: Lualaba | Q10: Tanganyika | R10: Nampula | S10: Bauchi | T10: Borno | U10: FCT (Abuja) | V10: Kebbi | W10: Kogi | X10: Nasarawa | Y10: Oyo | Z10: Plateau | AA10: Sokoto | AC10: Karamoja | AM10: Adamawa | AN10: Akwa Ibom | AO10: Anambra | AP10: Benue | AQ10: Delta | AR10: Ebonyi | AS10: Edo | AT10: Ekiti | AU10: Imo | AV10: Kogi | AW10: Nasarawa | AX10: Ogun | AY10: Osun | AZ10: Rivers | BA10: Taraba | BB10: Bauchi | BC10: Gombe | BD10: Jigawa | BE10: Kaduna | BF10: Kano | BG10: Katsina | BH10: Kebbi | BI10: Sokoto | BJ10: Zamfara | BK10: Abia | BL10: Adamawa | BM10: Akwa Ibom | BN10: Anambra | BO10: Bayelsa | BP10: Benue | BQ10: Borno | BR10: Cross River | BS10: Delta | BT10: Ebonyi | BU10: Edo | BV10: Ekiti | BW10: Enugu | BX10: FCT | BY10: Imo | BZ10: Kogi | CA10: Kwara | CB10: Lagos | CC10: Nasarawa | CD10: Niger | CE10: Ogun | CF10: Ondo | CG10: Osun | CH10: Oyo | CI10: Plateau | CJ10: Rivers | CK10: Taraba | CL10: Yobe
B11: Outcomes achieved by a $1,000,000 donation
C12: Mortalities averted among people under age 5 | D12: =IFERROR(__xludf.DUMMYFUNCTION("IMPORTRANGE(""https://docs.google.com/spreadsheets/d/1LyeZB70UrgDgyjoBvDr9VsAwuvcesheuM08g2qeYr94/edit?usp=sharing"",""Cost-effectiveness of top charities!D12:CZ17"")"),46.885377698110965) -> 46.885378 | E12: =IFERROR(__xludf.DUMMYFUNCTION("""COMPUTED_VALUE"""),202.56718831757746) -> 202.56719 | F12: =IFERROR(__xludf.DUMMYFUNCTION("""COMPUTED_VALUE"""),449.49716586675163) -> 449.49717 | G12: =IFERROR(__xludf.DUMMYFUNCTION("""COMPUTED_VALUE"""),247.7577552670049) -> 247.75776 | H12: =IFERROR(__xludf.DUMMYFUNCTION("""COMPUTED_VALUE"""),144.59212183507148) -> 144.59212 | I12: =IFERROR(__xludf.DUMMYFUNCTION("""COMPUTED_VALUE"""),100.82951624477387) -> 100.82952 | J12: =IFERROR(__xludf.DUMMYFUNCTION("""COMPUTED_VALUE"""),103.76416677051493) -> 103.76417 | K12: =IFERROR(__xludf.DUMMYFUNCTION("""COMPUTED_VALUE"""),293.5615278698572) -> 293.56153 | L12: =IFERROR(__xludf.DUMMYFUNCTION("""COMPUTED_VALUE"""),657.2987183147902) -> 657.29872 | M12: =IFERROR(__xludf.DUMMYFUNCTION("""COMPUTED_VALUE"""),192.67468450436527) -> 192.67468 | N12: =IFERROR(__xludf.DUMMYFUNCTION("""COMPUTED_VALUE"""),163.48361145883115) -> 163.48361 | O12: =IFERROR(__xludf.DUMMYFUNCTION("""COMPUTED_VALUE"""),193.55659047481834) -> 193.55659 | P12: =IFERROR(__xludf.DUMMYFUNCTION("""COMPUTED_VALUE"""),192.2194149384282) -> 192.21941 | Q12: =IFERROR(__xludf.DUMMYFUNCTION("""COMPUTED_VALUE"""),289.02647924049046) -> 289.02648 | R12: =IFERROR(__xludf.DUMMYFUNCTION("""COMPUTED_VALUE"""),246.66686626747847) -> 246.66687 | S12: =IFERROR(__xludf.DUMMYFUNCTION("""COMPUTED_VALUE"""),469.46121983346785) -> 469.46122 | T12: =IFERROR(__xludf.DUMMYFUNCTION("""COMPUTED_VALUE"""),316.7073189313168) -> 316.70732 | U12: =IFERROR(__xludf.DUMMYFUNCTION("""COMPUTED_VALUE"""),268.1588581102266) -> 268.15886 | V12: =IFERROR(__xludf.DUMMYFUNCTION("""COMPUTED_VALUE"""),603.5160859709083) -> 603.51609 | W12: =IFERROR(__xludf.DUMMYFUNCTION("""COMPUTED_VALUE"""),326.39235917506767) -> 326.39236 | X12: =IFERROR(__xludf.DUMMYFUNCTION("""COMPUTED_VALUE"""),419.0243330841049) -> 419.02433 | Y12: =IFERROR(__xludf.DUMMYFUNCTION("""COMPUTED_VALUE"""),343.9975353403757) -> 343.99754 | Z12: =IFERROR(__xludf.DUMMYFUNCTION("""COMPUTED_VALUE"""),290.8287102754498) -> 290.82871 | AA12: =IFERROR(__xludf.DUMMYFUNCTION("""COMPUTED_VALUE"""),662.1759943067584) -> 662.17599 | AB12: =IFERROR(__xludf.DUMMYFUNCTION("""COMPUTED_VALUE"""),289.3490723843428) -> 289.34907 | AC12: =IFERROR(__xludf.DUMMYFUNCTION("""COMPUTED_VALUE"""),264.3733772335192) -> 264.37338 | AD12: =IFERROR(__xludf.DUMMYFUNCTION("""COMPUTED_VALUE"""),553.3609059255817) -> 553.36091 | AE12: =IFERROR(__xludf.DUMMYFUNCTION("""COMPUTED_VALUE"""),423.8240432452461) -> 423.82404 | AF12: =IFERROR(__xludf.DUMMYFUNCTION("""COMPUTED_VALUE"""),239.4659697918627) -> 239.46597 | AG12: =IFERROR(__xludf.DUMMYFUNCTION("""COMPUTED_VALUE"""),371.17265221450236) -> 371.17265 | AH12: =IFERROR(__xludf.DUMMYFUNCTION("""COMPUTED_VALUE"""),313.4678109438447) -> 313.46781 | AI12: =IFERROR(__xludf.DUMMYFUNCTION("""COMPUTED_VALUE"""),128.442649335433) -> 128.44265 | AJ12: =IFERROR(__xludf.DUMMYFUNCTION("""COMPUTED_VALUE"""),364.9105493684752) -> 364.91055 | AK12: =IFERROR(__xludf.DUMMYFUNCTION("""COMPUTED_VALUE"""),877.5247341851735) -> 877.52473 | AL12: =IFERROR(__xludf.DUMMYFUNCTION("""COMPUTED_VALUE"""),1474.6063933109253) -> 1474.6064 | AM12: =IFERROR(__xludf.DUMMYFUNCTION("""COMPUTED_VALUE"""),503.0902230633486) -> 503.09022 | AN12: =IFERROR(__xludf.DUMMYFUNCTION("""COMPUTED_VALUE"""),108.4653177054305) -> 108.46532 | AO12: =IFERROR(__xludf.DUMMYFUNCTION("""COMPUTED_VALUE"""),59.72991425214574) -> 59.729914 | AP12: =IFERROR(__xludf.DUMMYFUNCTION("""COMPUTED_VALUE"""),226.745843244873) -> 226.74584 | AQ12: =IFERROR(__xludf.DUMMYFUNCTION("""COMPUTED_VALUE"""),126.60132706628637) -> 126.60133 | AR12: =IFERROR(__xludf.DUMMYFUNCTION("""COMPUTED_VALUE"""),319.02763663338715) -> 319.02764 | AS12: =IFERROR(__xludf.DUMMYFUNCTION("""COMPUTED_VALUE"""),94.56369089735739) -> 94.563691 | AT12: =IFERROR(__xludf.DUMMYFUNCTION("""COMPUTED_VALUE"""),142.71902996992773) -> 142.71903 | AU12: =IFERROR(__xludf.DUMMYFUNCTION("""COMPUTED_VALUE"""),79.3790982334187) -> 79.379098 | AV12: =IFERROR(__xludf.DUMMYFUNCTION("""COMPUTED_VALUE"""),103.24776178535474) -> 103.24776 | AW12: =IFERROR(__xludf.DUMMYFUNCTION("""COMPUTED_VALUE"""),283.34664557176984) -> 283.34665 | AX12: =IFERROR(__xludf.DUMMYFUNCTION("""COMPUTED_VALUE"""),118.05087364846959) -> 118.05087 | AY12: =IFERROR(__xludf.DUMMYFUNCTION("""COMPUTED_VALUE"""),60.24523330610385) -> 60.245233 | AZ12: =IFERROR(__xludf.DUMMYFUNCTION("""COMPUTED_VALUE"""),184.1408931682676) -> 184.14089 | BA12: =IFERROR(__xludf.DUMMYFUNCTION("""COMPUTED_VALUE"""),676.1169046444968) -> 676.1169 | BB12: =IFERROR(__xludf.DUMMYFUNCTION("""COMPUTED_VALUE"""),322.3745514899519) -> 322.37455 | BC12: =IFERROR(__xludf.DUMMYFUNCTION("""COMPUTED_VALUE"""),158.0315502708618) -> 158.03155 | BD12: =IFERROR(__xludf.DUMMYFUNCTION("""COMPUTED_VALUE"""),293.8932709759836) -> 293.89327 | BE12: =IFERROR(__xludf.DUMMYFUNCTION("""COMPUTED_VALUE"""),144.79502221395813) -> 144.79502 | BF12: =IFERROR(__xludf.DUMMYFUNCTION("""COMPUTED_VALUE"""),200.91648939578454) -> 200.91649 | BG12: =IFERROR(__xludf.DUMMYFUNCTION("""COMPUTED_VALUE"""),264.7158419887238) -> 264.71584 | BH12: =IFERROR(__xludf.DUMMYFUNCTION("""COMPUTED_VALUE"""),476.75055375487085) -> 476.75055 | BI12: =IFERROR(__xludf.DUMMYFUNCTION("""COMPUTED_VALUE"""),630.7510964217241) -> 630.7511 | BJ12: =IFERROR(__xludf.DUMMYFUNCTION("""COMPUTED_VALUE"""),500.0547059897596) -> 500.05471 | BK12: =IFERROR(__xludf.DUMMYFUNCTION("""COMPUTED_VALUE"""),17.53083822755919) -> 17.530838 | BL12: =IFERROR(__xludf.DUMMYFUNCTION("""COMPUTED_VALUE"""),60.767777265520664) -> 60.767777 | BM12: =IFERROR(__xludf.DUMMYFUNCTION("""COMPUTED_VALUE"""),15.303122774807234) -> 15.303123 | BN12: =IFERROR(__xludf.DUMMYFUNCTION("""COMPUTED_VALUE"""),19.98244808196295) -> 19.982448 | BO12: =IFERROR(__xludf.DUMMYFUNCTION("""COMPUTED_VALUE"""),34.73268052956662) -> 34.732681 | BP12: =IFERROR(__xludf.DUMMYFUNCTION("""COMPUTED_VALUE"""),41.61851038635296) -> 41.61851 | BQ12: =IFERROR(__xludf.DUMMYFUNCTION("""COMPUTED_VALUE"""),80.46795240484954) -> 80.467952 | BR12: =IFERROR(__xludf.DUMMYFUNCTION("""COMPUTED_VALUE"""),10.006940181166964) -> 10.00694 | BS12: =IFERROR(__xludf.DUMMYFUNCTION("""COMPUTED_VALUE"""),26.25373936838709) -> 26.253739 | BT12: =IFERROR(__xludf.DUMMYFUNCTION("""COMPUTED_VALUE"""),1.9130286564676697) -> 1.9130287 | BU12: =IFERROR(__xludf.DUMMYFUNCTION("""COMPUTED_VALUE"""),14.000681305110765) -> 14.000681 | BV12: =IFERROR(__xludf.DUMMYFUNCTION("""COMPUTED_VALUE"""),6.200453288960891) -> 6.2004533 | BW12: =IFERROR(__xludf.DUMMYFUNCTION("""COMPUTED_VALUE"""),2.4099383179013643) -> 2.4099383 | BX12: =IFERROR(__xludf.DUMMYFUNCTION("""COMPUTED_VALUE"""),10.977680988361008) -> 10.977681 | BY12: =IFERROR(__xludf.DUMMYFUNCTION("""COMPUTED_VALUE"""),5.358708087546049) -> 5.3587081 | BZ12: =IFERROR(__xludf.DUMMYFUNCTION("""COMPUTED_VALUE"""),88.52066032011936) -> 88.52066 | CA12: =IFERROR(__xludf.DUMMYFUNCTION("""COMPUTED_VALUE"""),24.73232165838524) -> 24.732322 | CB12: =IFERROR(__xludf.DUMMYFUNCTION("""COMPUTED_VALUE"""),24.796996688499448) -> 24.796997 | CC12: =IFERROR(__xludf.DUMMYFUNCTION("""COMPUTED_VALUE"""),4.7530168699295) -> 4.7530169 | CD12: =IFERROR(__xludf.DUMMYFUNCTION("""COMPUTED_VALUE"""),48.59051573756678) -> 48.590516 | CE12: =IFERROR(__xludf.DUMMYFUNCTION("""COMPUTED_VALUE"""),124.0646420320433) -> 124.06464 | CF12: =IFERROR(__xludf.DUMMYFUNCTION("""COMPUTED_VALUE"""),34.235500229389004) -> 34.2355 | CG12: =IFERROR(__xludf.DUMMYFUNCTION("""COMPUTED_VALUE"""),29.798536908858924) -> 29.798537 | CH12: =IFERROR(__xludf.DUMMYFUNCTION("""COMPUTED_VALUE"""),5.931869451285145) -> 5.9318695 | CI12: =IFERROR(__xludf.DUMMYFUNCTION("""COMPUTED_VALUE"""),20.11896060976271) -> 20.118961 | CJ12: =IFERROR(__xludf.DUMMYFUNCTION("""COMPUTED_VALUE"""),26.77212071382839) -> 26.772121 | CK12: =IFERROR(__xludf.DUMMYFUNCTION("""COMPUTED_VALUE"""),13.888993203311713) -> 13.888993 | CL12: =IFERROR(__xludf.DUMMYFUNCTION("""COMPUTED_VALUE"""),122.26859133696485) -> 122.26859 | CM12: =IFERROR(__xludf.DUMMYFUNCTION("""COMPUTED_VALUE"""),178.11291579159564) -> 178.11292
C13: Mortalities averted among people over age 5 | D13: =IFERROR(__xludf.DUMMYFUNCTION("""COMPUTED_VALUE"""),22.115683484420074) -> 22.115683 | E13: =IFERROR(__xludf.DUMMYFUNCTION("""COMPUTED_VALUE"""),48.097080627802605) -> 48.097081 | F13: =IFERROR(__xludf.DUMMYFUNCTION("""COMPUTED_VALUE"""),138.6945309083385) -> 138.69453 | G13: =IFERROR(__xludf.DUMMYFUNCTION("""COMPUTED_VALUE"""),144.4130593813866) -> 144.41306 | H13: =IFERROR(__xludf.DUMMYFUNCTION("""COMPUTED_VALUE"""),99.19132592591055) -> 99.191326 | I13: =IFERROR(__xludf.DUMMYFUNCTION("""COMPUTED_VALUE"""),22.10557874056967) -> 22.105579 | J13: =IFERROR(__xludf.DUMMYFUNCTION("""COMPUTED_VALUE"""),156.97127499768277) -> 156.97127 | K13: =IFERROR(__xludf.DUMMYFUNCTION("""COMPUTED_VALUE"""),70.2534620954568) -> 70.253462 | L13: =IFERROR(__xludf.DUMMYFUNCTION("""COMPUTED_VALUE"""),58.964895501795986) -> 58.964895 | M13: =IFERROR(__xludf.DUMMYFUNCTION("""COMPUTED_VALUE"""),16.931060603211463) -> 16.931061 | N13: =IFERROR(__xludf.DUMMYFUNCTION("""COMPUTED_VALUE"""),7.569579932779925) -> 7.5695799 | O13: =IFERROR(__xludf.DUMMYFUNCTION("""COMPUTED_VALUE"""),8.962011944031033) -> 8.9620119 | P13: =IFERROR(__xludf.DUMMYFUNCTION("""COMPUTED_VALUE"""),8.900098345358339) -> 8.9000983 | Q13: =IFERROR(__xludf.DUMMYFUNCTION("""COMPUTED_VALUE"""),13.382436431949545) -> 13.382436 | R13: =IFERROR(__xludf.DUMMYFUNCTION("""COMPUTED_VALUE"""),49.25059920814965) -> 49.250599 | S13: =IFERROR(__xludf.DUMMYFUNCTION("""COMPUTED_VALUE"""),17.461940428973598) -> 17.46194 | T13: =IFERROR(__xludf.DUMMYFUNCTION("""COMPUTED_VALUE"""),37.29211266164688) -> 37.292113 | U13: =IFERROR(__xludf.DUMMYFUNCTION("""COMPUTED_VALUE"""),54.7426085095439) -> 54.742609 | V13: =IFERROR(__xludf.DUMMYFUNCTION("""COMPUTED_VALUE"""),39.92847867867102) -> 39.928479 | W13: =IFERROR(__xludf.DUMMYFUNCTION("""COMPUTED_VALUE"""),103.28471775427025) -> 103.28472 | X13: =IFERROR(__xludf.DUMMYFUNCTION("""COMPUTED_VALUE"""),59.80544570525671) -> 59.805446 | Y13: =IFERROR(__xludf.DUMMYFUNCTION("""COMPUTED_VALUE"""),150.40708376787455) -> 150.40708 | Z13: =IFERROR(__xludf.DUMMYFUNCTION("""COMPUTED_VALUE"""),50.6003460777243) -> 50.600346 | AA13: =IFERROR(__xludf.DUMMYFUNCTION("""COMPUTED_VALUE"""),25.155466390872764) -> 25.155466 | AB13: =IFERROR(__xludf.DUMMYFUNCTION("""COMPUTED_VALUE"""),81.2713712644736) -> 81.271371 | AC13: =IFERROR(__xludf.DUMMYFUNCTION("""COMPUTED_VALUE"""),12.238087993236512) -> 12.238088 | AD13: =IFERROR(__xludf.DUMMYFUNCTION("""COMPUTED_VALUE"""),"-") -> - | AE13: =IFERROR(__xludf.DUMMYFUNCTION("""COMPUTED_VALUE"""),"-") -> - | AF13: =IFERROR(__xludf.DUMMYFUNCTION("""COMPUTED_VALUE"""),"-") -> - | AG13: =IFERROR(__xludf.DUMMYFUNCTION("""COMPUTED_VALUE"""),"-") -> - | AH13: =IFERROR(__xludf.DUMMYFUNCTION("""COMPUTED_VALUE"""),"-") -> - | AI13: =IFERROR(__xludf.DUMMYFUNCTION("""COMPUTED_VALUE"""),"-") -> - | AJ13: =IFERROR(__xludf.DUMMYFUNCTION("""COMPUTED_VALUE"""),"-") -> - | AK13: =IFERROR(__xludf.DUMMYFUNCTION("""COMPUTED_VALUE"""),"-") -> - | ... CM13: =IFERROR(__xludf.DUMMYFUNCTION("""COMPUTED_VALUE"""),"-") -> -
C14: Mortalities averted among people age 5 through 14 | D14: =IFERROR(__xludf.DUMMYFUNCTION("""COMPUTED_VALUE"""),"-") -> - | E14: =IFERROR(__xludf.DUMMYFUNCTION("""COMPUTED_VALUE"""),"-") -> - | F14: =IFERROR(__xludf.DUMMYFUNCTION("""COMPUTED_VALUE"""),"-") -> - | G14: =IFERROR(__xludf.DUMMYFUNCTION("""COMPUTED_VALUE"""),"-") -> - | H14: =IFERROR(__xludf.DUMMYFUNCTION("""COMPUTED_VALUE"""),"-") -> - | I14: =IFERROR(__xludf.DUMMYFUNCTION("""COMPUTED_VALUE"""),"-") -> - | J14: =IFERROR(__xludf.DUMMYFUNCTION("""COMPUTED_VALUE"""),"-") -> - | K14: =IFERROR(__xludf.DUMMYFUNCTION("""COMPUTED_VALUE"""),"-") -> - | ... BA14: =IFERROR(__xludf.DUMMYFUNCTION("""COMPUTED_VALUE"""),"-") -> - | BB14: =IFERROR(__xludf.DUMMYFUNCTION("""COMPUTED_VALUE"""),22.235256712443828) -> 22.235257 | BC14: =IFERROR(__xludf.DUMMYFUNCTION("""COMPUTED_VALUE"""),10.51239373983941) -> 10.512394 | BD14: =IFERROR(__xludf.DUMMYFUNCTION("""COMPUTED_VALUE"""),19.072270230810854) -> 19.07227 | BE14: =IFERROR(__xludf.DUMMYFUNCTION("""COMPUTED_VALUE"""),9.647646017188215) -> 9.647646 | BF14: =IFERROR(__xludf.DUMMYFUNCTION("""COMPUTED_VALUE"""),13.795234577124772) -> 13.795235 | BG14: =IFERROR(__xludf.DUMMYFUNCTION("""COMPUTED_VALUE"""),19.638964633130826) -> 19.638965 | BH14: =IFERROR(__xludf.DUMMYFUNCTION("""COMPUTED_VALUE"""),34.88051015345627) -> 34.88051 | BI14: =IFERROR(__xludf.DUMMYFUNCTION("""COMPUTED_VALUE"""),46.980875698022494) -> 46.980876 | BJ14: =IFERROR(__xludf.DUMMYFUNCTION("""COMPUTED_VALUE"""),33.63611531793335) -> 33.636115 | BK14: =IFERROR(__xludf.DUMMYFUNCTION("""COMPUTED_VALUE"""),1.0873993504775321) -> 1.0873994 | BL14: =IFERROR(__xludf.DUMMYFUNCTION("""COMPUTED_VALUE"""),3.7422793232844676) -> 3.7422793 | BM14: =IFERROR(__xludf.DUMMYFUNCTION("""COMPUTED_VALUE"""),1.1829891129474137) -> 1.1829891 | BN14: =IFERROR(__xludf.DUMMYFUNCTION("""COMPUTED_VALUE"""),1.614568502814873) -> 1.6145685 | BO14: =IFERROR(__xludf.DUMMYFUNCTION("""COMPUTED_VALUE"""),2.3844527057666514) -> 2.3844527 | BP14: =IFERROR(__xludf.DUMMYFUNCTION("""COMPUTED_VALUE"""),3.5285982831326512) -> 3.5285983 | BQ14: =IFERROR(__xludf.DUMMYFUNCTION("""COMPUTED_VALUE"""),7.816195107619986) -> 7.8161951 | BR14: =IFERROR(__xludf.DUMMYFUNCTION("""COMPUTED_VALUE"""),0.8404624618681458) -> 0.84046246 | BS14: =IFERROR(__xludf.DUMMYFUNCTION("""COMPUTED_VALUE"""),2.071969129611924) -> 2.0719691 | BT14: =IFERROR(__xludf.DUMMYFUNCTION("""COMPUTED_VALUE"""),0.13609025862533336) -> 0.13609026 | BU14: =IFERROR(__xludf.DUMMYFUNCTION("""COMPUTED_VALUE"""),0.8103413843728494) -> 0.81034138 | BV14: =IFERROR(__xludf.DUMMYFUNCTION("""COMPUTED_VALUE"""),0.40876128007097906) -> 0.40876128 | BW14: =IFERROR(__xludf.DUMMYFUNCTION("""COMPUTED_VALUE"""),0.21419367421401406) -> 0.21419367 | BX14: =IFERROR(__xludf.DUMMYFUNCTION("""COMPUTED_VALUE"""),0.8530685582979204) -> 0.85306856 | BY14: =IFERROR(__xludf.DUMMYFUNCTION("""COMPUTED_VALUE"""),0.4456199718667396) -> 0.44561997 | BZ14: =IFERROR(__xludf.DUMMYFUNCTION("""COMPUTED_VALUE"""),5.898103283649649) -> 5.8981033 | CA14: =IFERROR(__xludf.DUMMYFUNCTION("""COMPUTED_VALUE"""),2.1324431659454186) -> 2.1324432 | CB14: =IFERROR(__xludf.DUMMYFUNCTION("""COMPUTED_VALUE"""),2.7174217746467906) -> 2.7174218 | CC14: =IFERROR(__xludf.DUMMYFUNCTION("""COMPUTED_VALUE"""),0.5056071781039587) -> 0.50560718 | CD14: =IFERROR(__xludf.DUMMYFUNCTION("""COMPUTED_VALUE"""),4.239604478946348) -> 4.2396045 | CE14: =IFERROR(__xludf.DUMMYFUNCTION("""COMPUTED_VALUE"""),9.778051668914108) -> 9.7780517 | CF14: =IFERROR(__xludf.DUMMYFUNCTION("""COMPUTED_VALUE"""),3.3528184489403237) -> 3.3528184 | CG14: =IFERROR(__xludf.DUMMYFUNCTION("""COMPUTED_VALUE"""),2.63386828693475) -> 2.6338683 | CH14: =IFERROR(__xludf.DUMMYFUNCTION("""COMPUTED_VALUE"""),0.5593941580987752) -> 0.55939416 | CI14: =IFERROR(__xludf.DUMMYFUNCTION("""COMPUTED_VALUE"""),1.7494479943357428) -> 1.749448 | CJ14: =IFERROR(__xludf.DUMMYFUNCTION("""COMPUTED_VALUE"""),2.6992599293511894) -> 2.6992599 | CK14: =IFERROR(__xludf.DUMMYFUNCTION("""COMPUTED_VALUE"""),0.9281429648727519) -> 0.92814296 | CL14: =IFERROR(__xludf.DUMMYFUNCTION("""COMPUTED_VALUE"""),7.801710062124809) -> 7.8017101 | CM14: =IFERROR(__xludf.DUMMYFUNCTION("""COMPUTED_VALUE"""),14.157619087005525) -> 14.157619
C15: Mortalities averted among people age 15 through age 49 | D15: =IFERROR(__xludf.DUMMYFUNCTION("""COMPUTED_VALUE"""),"-") -> - | E15: =IFERROR(__xludf.DUMMYFUNCTION("""COMPUTED_VALUE"""),"-") -> - | F15: =IFERROR(__xludf.DUMMYFUNCTION("""COMPUTED_VALUE"""),"-") -> - | G15: =IFERROR(__xludf.DUMMYFUNCTION("""COMPUTED_VALUE"""),"-") -> - | H15: =IFERROR(__xludf.DUMMYFUNCTION("""COMPUTED_VALUE"""),"-") -> - | I15: =IFERROR(__xludf.DUMMYFUNCTION("""COMPUTED_VALUE"""),"-") -> - | J15: =IFERROR(__xludf.DUMMYFUNCTION("""COMPUTED_VALUE"""),"-") -> - | K15: =IFERROR(__xludf.DUMMYFUNCTION("""COMPUTED_VALUE"""),"-") -> - | ... BA15: =IFERROR(__xludf.DUMMYFUNCTION("""COMPUTED_VALUE"""),"-") -> - | BB15: =IFERROR(__xludf.DUMMYFUNCTION("""COMPUTED_VALUE"""),22.670758328710487) -> 22.670758 | BC15: =IFERROR(__xludf.DUMMYFUNCTION("""COMPUTED_VALUE"""),9.388933469550235) -> 9.3889335 | BD15: =IFERROR(__xludf.DUMMYFUNCTION("""COMPUTED_VALUE"""),19.913845667785633) -> 19.913846 | BE15: =IFERROR(__xludf.DUMMYFUNCTION("""COMPUTED_VALUE"""),9.515241096541017) -> 9.5152411 | BF15: =IFERROR(__xludf.DUMMYFUNCTION("""COMPUTED_VALUE"""),11.76591548467665) -> 11.765915 | BG15: =IFERROR(__xludf.DUMMYFUNCTION("""COMPUTED_VALUE"""),22.01692430249219) -> 22.016924 | BH15: =IFERROR(__xludf.DUMMYFUNCTION("""COMPUTED_VALUE"""),36.53178114343006) -> 36.531781 | BI15: =IFERROR(__xludf.DUMMYFUNCTION("""COMPUTED_VALUE"""),53.37953878269617) -> 53.379539 | BJ15: =IFERROR(__xludf.DUMMYFUNCTION("""COMPUTED_VALUE"""),30.20159415858746) -> 30.201594 | BK15: =IFERROR(__xludf.DUMMYFUNCTION("""COMPUTED_VALUE"""),1.46269757876029) -> 1.4626976 | BL15: =IFERROR(__xludf.DUMMYFUNCTION("""COMPUTED_VALUE"""),3.7223211204275892) -> 3.7223211 | BM15: =IFERROR(__xludf.DUMMYFUNCTION("""COMPUTED_VALUE"""),2.051711251671184) -> 2.0517113 | BN15: =IFERROR(__xludf.DUMMYFUNCTION("""COMPUTED_VALUE"""),2.485924372491213) -> 2.4859244 | BO15: =IFERROR(__xludf.DUMMYFUNCTION("""COMPUTED_VALUE"""),3.720663689513822) -> 3.7206637 | BP15: =IFERROR(__xludf.DUMMYFUNCTION("""COMPUTED_VALUE"""),4.844297894361171) -> 4.8442979 | BQ15: =IFERROR(__xludf.DUMMYFUNCTION("""COMPUTED_VALUE"""),10.025475027797373) -> 10.025475 | BR15: =IFERROR(__xludf.DUMMYFUNCTION("""COMPUTED_VALUE"""),1.5691105439378292) -> 1.5691105 | BS15: =IFERROR(__xludf.DUMMYFUNCTION("""COMPUTED_VALUE"""),2.987955522081749) -> 2.9879555 | BT15: =IFERROR(__xludf.DUMMYFUNCTION("""COMPUTED_VALUE"""),0.17192946430943437) -> 0.17192946 | BU15: =IFERROR(__xludf.DUMMYFUNCTION("""COMPUTED_VALUE"""),1.3824060490883028) -> 1.382406 | BV15: =IFERROR(__xludf.DUMMYFUNCTION("""COMPUTED_VALUE"""),0.6771852403426135) -> 0.67718524 | BW15: =IFERROR(__xludf.DUMMYFUNCTION("""COMPUTED_VALUE"""),0.394284889849876) -> 0.39428489 | BX15: =IFERROR(__xludf.DUMMYFUNCTION("""COMPUTED_VALUE"""),1.0781312241129415) -> 1.0781312 | BY15: =IFERROR(__xludf.DUMMYFUNCTION("""COMPUTED_VALUE"""),0.7712319421269598) -> 0.77123194 | BZ15: =IFERROR(__xludf.DUMMYFUNCTION("""COMPUTED_VALUE"""),5.817157331046364) -> 5.8171573 | CA15: =IFERROR(__xludf.DUMMYFUNCTION("""COMPUTED_VALUE"""),2.7893618011279013) -> 2.7893618 | CB15: =IFERROR(__xludf.DUMMYFUNCTION("""COMPUTED_VALUE"""),5.6633229598840655) -> 5.663323 | CC15: =IFERROR(__xludf.DUMMYFUNCTION("""COMPUTED_VALUE"""),0.7389240753102964) -> 0.73892408 | CD15: =IFERROR(__xludf.DUMMYFUNCTION("""COMPUTED_VALUE"""),6.156239467198286) -> 6.1562395 | CE15: =IFERROR(__xludf.DUMMYFUNCTION("""COMPUTED_VALUE"""),13.30730619760112) -> 13.307306 | CF15: =IFERROR(__xludf.DUMMYFUNCTION("""COMPUTED_VALUE"""),6.023016703547505) -> 6.0230167 | CG15: =IFERROR(__xludf.DUMMYFUNCTION("""COMPUTED_VALUE"""),4.124125945256102) -> 4.1241259 | CH15: =IFERROR(__xludf.DUMMYFUNCTION("""COMPUTED_VALUE"""),1.0230311106346714) -> 1.0230311 | CI15: =IFERROR(__xludf.DUMMYFUNCTION("""COMPUTED_VALUE"""),3.326282848571396) -> 3.3262828 | CJ15: =IFERROR(__xludf.DUMMYFUNCTION("""COMPUTED_VALUE"""),4.421086810799636) -> 4.4210868 | CK15: =IFERROR(__xludf.DUMMYFUNCTION("""COMPUTED_VALUE"""),1.4058556550126846) -> 1.4058557 | CL15: =IFERROR(__xludf.DUMMYFUNCTION("""COMPUTED_VALUE"""),8.815184020832847) -> 8.815184 | CM15: =IFERROR(__xludf.DUMMYFUNCTION("""COMPUTED_VALUE"""),17.5005950607499) -> 17.500595
C16: Mortalities averted among people age 50 through age 74 | D16: =IFERROR(__xludf.DUMMYFUNCTION("""COMPUTED_VALUE"""),"-") -> - | E16: =IFERROR(__xludf.DUMMYFUNCTION("""COMPUTED_VALUE"""),"-") -> - | F16: =IFERROR(__xludf.DUMMYFUNCTION("""COMPUTED_VALUE"""),"-") -> - | G16: =IFERROR(__xludf.DUMMYFUNCTION("""COMPUTED_VALUE"""),"-") -> - | H16: =IFERROR(__xludf.DUMMYFUNCTION("""COMPUTED_VALUE"""),"-") -> - | I16: =IFERROR(__xludf.DUMMYFUNCTION("""COMPUTED_VALUE"""),"-") -> - | J16: =IFERROR(__xludf.DUMMYFUNCTION("""COMPUTED_VALUE"""),"-") -> - | K16: =IFERROR(__xludf.DUMMYFUNCTION("""COMPUTED_VALUE"""),"-") -> - | ... BA16: =IFERROR(__xludf.DUMMYFUNCTION("""COMPUTED_VALUE"""),"-") -> - | BB16: =IFERROR(__xludf.DUMMYFUNCTION("""COMPUTED_VALUE"""),38.37434981135112) -> 38.37435 | BC16: =IFERROR(__xludf.DUMMYFUNCTION("""COMPUTED_VALUE"""),19.0000596260896) -> 19.00006 | BD16: =IFERROR(__xludf.DUMMYFUNCTION("""COMPUTED_VALUE"""),28.810835180775527) -> 28.810835 | BE16: =IFERROR(__xludf.DUMMYFUNCTION("""COMPUTED_VALUE"""),14.507643302548802) -> 14.507643 | BF16: =IFERROR(__xludf.DUMMYFUNCTION("""COMPUTED_VALUE"""),18.81499431993802) -> 18.814994 | BG16: =IFERROR(__xludf.DUMMYFUNCTION("""COMPUTED_VALUE"""),33.786796798859655) -> 33.786797 | BH16: =IFERROR(__xludf.DUMMYFUNCTION("""COMPUTED_VALUE"""),64.71094050805588) -> 64.710941 | BI16: =IFERROR(__xludf.DUMMYFUNCTION("""COMPUTED_VALUE"""),71.30818878284502) -> 71.308189 | BJ16: =IFERROR(__xludf.DUMMYFUNCTION("""COMPUTED_VALUE"""),54.123419029182884) -> 54.123419 | BK16: =IFERROR(__xludf.DUMMYFUNCTION("""COMPUTED_VALUE"""),2.5297058289648455) -> 2.5297058 | BL16: =IFERROR(__xludf.DUMMYFUNCTION("""COMPUTED_VALUE"""),6.499108209025617) -> 6.4991082 | BM16: =IFERROR(__xludf.DUMMYFUNCTION("""COMPUTED_VALUE"""),3.574503823177632) -> 3.5745038 | BN16: =IFERROR(__xludf.DUMMYFUNCTION("""COMPUTED_VALUE"""),4.014877899845496) -> 4.0148779 | BO16: =IFERROR(__xludf.DUMMYFUNCTION("""COMPUTED_VALUE"""),6.264619158226943) -> 6.2646192 | BP16: =IFERROR(__xludf.DUMMYFUNCTION("""COMPUTED_VALUE"""),7.819625987915114) -> 7.819626 | BQ16: =IFERROR(__xludf.DUMMYFUNCTION("""COMPUTED_VALUE"""),19.117294621336903) -> 19.117295 | BR16: =IFERROR(__xludf.DUMMYFUNCTION("""COMPUTED_VALUE"""),2.7988805535469004) -> 2.7988806 | BS16: =IFERROR(__xludf.DUMMYFUNCTION("""COMPUTED_VALUE"""),4.279432534930564) -> 4.2794325 | BT16: =IFERROR(__xludf.DUMMYFUNCTION("""COMPUTED_VALUE"""),0.27760790811594743) -> 0.27760791 | BU16: =IFERROR(__xludf.DUMMYFUNCTION("""COMPUTED_VALUE"""),1.894403370059948) -> 1.8944034 | BV16: =IFERROR(__xludf.DUMMYFUNCTION("""COMPUTED_VALUE"""),1.1359584439379218) -> 1.1359584 | BW16: =IFERROR(__xludf.DUMMYFUNCTION("""COMPUTED_VALUE"""),0.6974651274245552) -> 0.69746513 | BX16: =IFERROR(__xludf.DUMMYFUNCTION("""COMPUTED_VALUE"""),1.3905689036342157) -> 1.3905689 | BY16: =IFERROR(__xludf.DUMMYFUNCTION("""COMPUTED_VALUE"""),1.279352998284332) -> 1.279353 | BZ16: =IFERROR(__xludf.DUMMYFUNCTION("""COMPUTED_VALUE"""),8.869270125410283) -> 8.8692701 | CA16: =IFERROR(__xludf.DUMMYFUNCTION("""COMPUTED_VALUE"""),5.126005991241977) -> 5.126006 | CB16: =IFERROR(__xludf.DUMMYFUNCTION("""COMPUTED_VALUE"""),8.468634479850161) -> 8.4686345 | CC16: =IFERROR(__xludf.DUMMYFUNCTION("""COMPUTED_VALUE"""),1.104926994377144) -> 1.104927 | CD16: =IFERROR(__xludf.DUMMYFUNCTION("""COMPUTED_VALUE"""),7.55884025835579) -> 7.5588403 | CE16: =IFERROR(__xludf.DUMMYFUNCTION("""COMPUTED_VALUE"""),20.31559008762993) -> 20.31559 | CF16: =IFERROR(__xludf.DUMMYFUNCTION("""COMPUTED_VALUE"""),9.988222226894006) -> 9.9882222 | CG16: =IFERROR(__xludf.DUMMYFUNCTION("""COMPUTED_VALUE"""),7.189209591010099) -> 7.1892096 | CH16: =IFERROR(__xludf.DUMMYFUNCTION("""COMPUTED_VALUE"""),2.1423271316907355) -> 2.1423271 | CI16: =IFERROR(__xludf.DUMMYFUNCTION("""COMPUTED_VALUE"""),5.3671504958277305) -> 5.3671505 | CJ16: =IFERROR(__xludf.DUMMYFUNCTION("""COMPUTED_VALUE"""),5.380958840389657) -> 5.3809588 | CK16: =IFERROR(__xludf.DUMMYFUNCTION("""COMPUTED_VALUE"""),2.210267800863415) -> 2.2102678 | CL16: =IFERROR(__xludf.DUMMYFUNCTION("""COMPUTED_VALUE"""),10.642075436350671) -> 10.642075 | CM16: =IFERROR(__xludf.DUMMYFUNCTION("""COMPUTED_VALUE"""),27.62599824212151) -> 27.625998
C17: Increases in lifetime consumption measured in ln($) | D17: =IFERROR(__xludf.DUMMYFUNCTION("""COMPUTED_VALUE"""),2983.82175756697) -> 2983.8218 | E17: =IFERROR(__xludf.DUMMYFUNCTION("""COMPUTED_VALUE"""),9224.723501570259) -> 9224.7235 | F17: =IFERROR(__xludf.DUMMYFUNCTION("""COMPUTED_VALUE"""),13650.610456603123) -> 13650.61 | G17: =IFERROR(__xludf.DUMMYFUNCTION("""COMPUTED_VALUE"""),10715.559162415528) -> 10715.559 | H17: =IFERROR(__xludf.DUMMYFUNCTION("""COMPUTED_VALUE"""),8458.160061631539) -> 8458.1601 | I17: =IFERROR(__xludf.DUMMYFUNCTION("""COMPUTED_VALUE"""),4199.321029614229) -> 4199.321 | J17: =IFERROR(__xludf.DUMMYFUNCTION("""COMPUTED_VALUE"""),10050.828573728639) -> 10050.829 | K17: =IFERROR(__xludf.DUMMYFUNCTION("""COMPUTED_VALUE"""),12858.518947045457) -> 12858.519 | L17: =IFERROR(__xludf.DUMMYFUNCTION("""COMPUTED_VALUE"""),10566.948956809487) -> 10566.949 | M17: =IFERROR(__xludf.DUMMYFUNCTION("""COMPUTED_VALUE"""),5788.385157201596) -> 5788.3852 | N17: =IFERROR(__xludf.DUMMYFUNCTION("""COMPUTED_VALUE"""),3284.5483109550355) -> 3284.5483 | O17: =IFERROR(__xludf.DUMMYFUNCTION("""COMPUTED_VALUE"""),4002.4078561382585) -> 4002.4079 | P17: =IFERROR(__xludf.DUMMYFUNCTION("""COMPUTED_VALUE"""),3779.7524831474784) -> 3779.7525 | Q17: =IFERROR(__xludf.DUMMYFUNCTION("""COMPUTED_VALUE"""),3751.7746711873597) -> 3751.7747 | R17: =IFERROR(__xludf.DUMMYFUNCTION("""COMPUTED_VALUE"""),3850.86127609751) -> 3850.8613 | S17: =IFERROR(__xludf.DUMMYFUNCTION("""COMPUTED_VALUE"""),9107.859720406428) -> 9107.8597 | T17: =IFERROR(__xludf.DUMMYFUNCTION("""COMPUTED_VALUE"""),9431.771374796874) -> 9431.7714 | U17: =IFERROR(__xludf.DUMMYFUNCTION("""COMPUTED_VALUE"""),8446.781975683767) -> 8446.782 | V17: =IFERROR(__xludf.DUMMYFUNCTION("""COMPUTED_VALUE"""),16331.041434520077) -> 16331.041 | W17: =IFERROR(__xludf.DUMMYFUNCTION("""COMPUTED_VALUE"""),11584.008111837842) -> 11584.008 | X17: =IFERROR(__xludf.DUMMYFUNCTION("""COMPUTED_VALUE"""),13587.52030823564) -> 13587.52 | Y17: =IFERROR(__xludf.DUMMYFUNCTION("""COMPUTED_VALUE"""),19715.7749906278) -> 19715.775 | Z17: =IFERROR(__xludf.DUMMYFUNCTION("""COMPUTED_VALUE"""),9689.77864234763) -> 9689.7786 | AA17: =IFERROR(__xludf.DUMMYFUNCTION("""COMPUTED_VALUE"""),13300.368715315682) -> 13300.369 | AB17: =IFERROR(__xludf.DUMMYFUNCTION("""COMPUTED_VALUE"""),14853.920600987376) -> 14853.921 | AC17: =IFERROR(__xludf.DUMMYFUNCTION("""COMPUTED_VALUE"""),3525.6858858386277) -> 3525.6859 | AD17: =IFERROR(__xludf.DUMMYFUNCTION("""COMPUTED_VALUE"""),11165.555604660502) -> 11165.556 | AE17: =IFERROR(__xludf.DUMMYFUNCTION("""COMPUTED_VALUE"""),8551.798420836116) -> 8551.7984 | AF17: =IFERROR(__xludf.DUMMYFUNCTION("""COMPUTED_VALUE"""),4831.874771967673) -> 4831.8748 | AG17: =IFERROR(__xludf.DUMMYFUNCTION("""COMPUTED_VALUE"""),7489.413948204879) -> 7489.4139 | AH17: =IFERROR(__xludf.DUMMYFUNCTION("""COMPUTED_VALUE"""),6325.062424694316) -> 6325.0624 | AI17: =IFERROR(__xludf.DUMMYFUNCTION("""COMPUTED_VALUE"""),2591.6784648273574) -> 2591.6785 | AJ17: =IFERROR(__xludf.DUMMYFUNCTION("""COMPUTED_VALUE"""),7363.059056161202) -> 7363.0591 | AK17: =IFERROR(__xludf.DUMMYFUNCTION("""COMPUTED_VALUE"""),17706.439159486203) -> 17706.439 | AL17: =IFERROR(__xludf.DUMMYFUNCTION("""COMPUTED_VALUE"""),29754.179421043646) -> 29754.179 | AM17: =IFERROR(__xludf.DUMMYFUNCTION("""COMPUTED_VALUE"""),10151.20836984156) -> 10151.208 | AN17: =IFERROR(__xludf.DUMMYFUNCTION("""COMPUTED_VALUE"""),2188.581670747846) -> 2188.5817 | AO17: =IFERROR(__xludf.DUMMYFUNCTION("""COMPUTED_VALUE"""),1205.2128578335582) -> 1205.2129 | AP17: =IFERROR(__xludf.DUMMYFUNCTION("""COMPUTED_VALUE"""),4575.211753785769) -> 4575.2118 | AQ17: =IFERROR(__xludf.DUMMYFUNCTION("""COMPUTED_VALUE"""),2554.5247989971563) -> 2554.5248 | AR17: =IFERROR(__xludf.DUMMYFUNCTION("""COMPUTED_VALUE"""),6437.246972290735) -> 6437.247 | AS17: =IFERROR(__xludf.DUMMYFUNCTION("""COMPUTED_VALUE"""),1908.0786835316624) -> 1908.0787 | AT17: =IFERROR(__xludf.DUMMYFUNCTION("""COMPUTED_VALUE"""),2879.743125884542) -> 2879.7431 | AU17: =IFERROR(__xludf.DUMMYFUNCTION("""COMPUTED_VALUE"""),1601.688383986128) -> 1601.6884 | AV17: =IFERROR(__xludf.DUMMYFUNCTION("""COMPUTED_VALUE"""),2083.3033431280305) -> 2083.3033 | AW17: =IFERROR(__xludf.DUMMYFUNCTION("""COMPUTED_VALUE"""),5717.2863002199465) -> 5717.2863 | AX17: =IFERROR(__xludf.DUMMYFUNCTION("""COMPUTED_VALUE"""),2381.996233897308) -> 2381.9962 | AY17: =IFERROR(__xludf.DUMMYFUNCTION("""COMPUTED_VALUE"""),1215.6108160006356) -> 1215.6108 | AZ17: =IFERROR(__xludf.DUMMYFUNCTION("""COMPUTED_VALUE"""),3715.5414481677267) -> 3715.5414 | BA17: =IFERROR(__xludf.DUMMYFUNCTION("""COMPUTED_VALUE"""),13642.490485358432) -> 13642.49 | BB17: =IFERROR(__xludf.DUMMYFUNCTION("""COMPUTED_VALUE"""),10306.742370943788) -> 10306.742 | BC17: =IFERROR(__xludf.DUMMYFUNCTION("""COMPUTED_VALUE"""),5915.290628702003) -> 5915.2906 | BD17: =IFERROR(__xludf.DUMMYFUNCTION("""COMPUTED_VALUE"""),9513.554001516559) -> 9513.554 | BE17: =IFERROR(__xludf.DUMMYFUNCTION("""COMPUTED_VALUE"""),5563.850062364274) -> 5563.8501 | BF17: =IFERROR(__xludf.DUMMYFUNCTION("""COMPUTED_VALUE"""),7067.586039212312) -> 7067.586 | BG17: =IFERROR(__xludf.DUMMYFUNCTION("""COMPUTED_VALUE"""),8809.103057282204) -> 8809.1031 | BH17: =IFERROR(__xludf.DUMMYFUNCTION("""COMPUTED_VALUE"""),14478.253266299782) -> 14478.253 | BI17: =IFERROR(__xludf.DUMMYFUNCTION("""COMPUTED_VALUE"""),18625.016358918336) -> 18625.016 | BJ17: =IFERROR(__xludf.DUMMYFUNCTION("""COMPUTED_VALUE"""),15018.413951943387) -> 15018.414 | BK17: =IFERROR(__xludf.DUMMYFUNCTION("""COMPUTED_VALUE"""),2177.895110065442) -> 2177.8951 | BL17: =IFERROR(__xludf.DUMMYFUNCTION("""COMPUTED_VALUE"""),3321.048156278367) -> 3321.0482 | BM17: =IFERROR(__xludf.DUMMYFUNCTION("""COMPUTED_VALUE"""),2125.595866114443) -> 2125.5959 | BN17: =IFERROR(__xludf.DUMMYFUNCTION("""COMPUTED_VALUE"""),2253.4108697378497) -> 2253.4109 | BO17: =IFERROR(__xludf.DUMMYFUNCTION("""COMPUTED_VALUE"""),2639.538573715783) -> 2639.5386 | BP17: =IFERROR(__xludf.DUMMYFUNCTION("""COMPUTED_VALUE"""),2842.0819616344806) -> 2842.082 | BQ17: =IFERROR(__xludf.DUMMYFUNCTION("""COMPUTED_VALUE"""),3923.2561862860075) -> 3923.2562 | BR17: =IFERROR(__xludf.DUMMYFUNCTION("""COMPUTED_VALUE"""),1985.076616823205) -> 1985.0766 | BS17: =IFERROR(__xludf.DUMMYFUNCTION("""COMPUTED_VALUE"""),2421.273350522307) -> 2421.2734 | BT17: =IFERROR(__xludf.DUMMYFUNCTION("""COMPUTED_VALUE"""),1765.189546524961) -> 1765.1895 | BU17: =IFERROR(__xludf.DUMMYFUNCTION("""COMPUTED_VALUE"""),2082.84785035553) -> 2082.8479 | BV17: =IFERROR(__xludf.DUMMYFUNCTION("""COMPUTED_VALUE"""),1878.8131794592086) -> 1878.8132 | BW17: =IFERROR(__xludf.DUMMYFUNCTION("""COMPUTED_VALUE"""),1779.6791551248532) -> 1779.6792 | BX17: =IFERROR(__xludf.DUMMYFUNCTION("""COMPUTED_VALUE"""),2009.4074069842236) -> 2009.4074 | BY17: =IFERROR(__xludf.DUMMYFUNCTION("""COMPUTED_VALUE"""),1859.072858132918) -> 1859.0729 | BZ17: =IFERROR(__xludf.DUMMYFUNCTION("""COMPUTED_VALUE"""),4067.643453760177) -> 4067.6435 | CA17: =IFERROR(__xludf.DUMMYFUNCTION("""COMPUTED_VALUE"""),2385.4190124226334) -> 2385.419 | CB17: =IFERROR(__xludf.DUMMYFUNCTION("""COMPUTED_VALUE"""),2403.630532092215) -> 2403.6305 | CC17: =IFERROR(__xludf.DUMMYFUNCTION("""COMPUTED_VALUE"""),1845.8188534762971) -> 1845.8189 | CD17: =IFERROR(__xludf.DUMMYFUNCTION("""COMPUTED_VALUE"""),3034.451614426188) -> 3034.4516 | CE17: =IFERROR(__xludf.DUMMYFUNCTION("""COMPUTED_VALUE"""),5055.610390921246) -> 5055.6104 | CF17: =IFERROR(__xludf.DUMMYFUNCTION("""COMPUTED_VALUE"""),2654.763716825555) -> 2654.7637 | CG17: =IFERROR(__xludf.DUMMYFUNCTION("""COMPUTED_VALUE"""),2524.772120585085) -> 2524.7721 | CH17: =IFERROR(__xludf.DUMMYFUNCTION("""COMPUTED_VALUE"""),1876.4586352552517) -> 1876.4586 | CI17: =IFERROR(__xludf.DUMMYFUNCTION("""COMPUTED_VALUE"""),2260.612888616818) -> 2260.6129 | CJ17: =IFERROR(__xludf.DUMMYFUNCTION("""COMPUTED_VALUE"""),2451.8910289656123) -> 2451.891 | CK17: =IFERROR(__xludf.DUMMYFUNCTION("""COMPUTED_VALUE"""),2083.435434271257) -> 2083.4354 | CL17: =IFERROR(__xludf.DUMMYFUNCTION("""COMPUTED_VALUE"""),4955.125008216966) -> 4955.125 | CM17: =IFERROR(__xludf.DUMMYFUNCTION("""COMPUTED_VALUE"""),6514.736768384144) -> 6514.7368
B18: Moral weights GiveWell assigns to each outcome
C19: Mortalities averted among people under age 5 | D19: 116.25 | E19: 116.25 | F19: 116.25 | G19: 116.25 | H19: 116.25 | I19: 116.25 | J19: 116.25 | K19: 116.25 | L19: 116.25 | M19: 116.25 | N19: 116.25 | O19: 116.25 | P19: 116.25 | Q19: 116.25 | R19: 116.25 | S19: 116.25 | T19: 116.25 | U19: 116.25 | V19: 116.25 | W19: 116.25 | X19: 116.25 | Y19: 116.25 | Z19: 116.25 | AA19: 116.25 | AB19: 116.25 | AC19: 116.25 | AD19: 118.73 | AE19: 118.73 | AF19: 118.73 | AG19: 118.73 | AH19: 118.73 | AI19: 118.73 | AJ19: 118.73 | AK19: 118.73 | AL19: 118.73 | AM19: 118.73 | AN19: 118.73 | AO19: 118.73 | AP19: 118.73 | AQ19: 118.73 | AR19: 118.73 | AS19: 118.73 | AT19: 118.73 | AU19: 118.73 | AV19: 118.73 | AW19: 118.73 | AX19: 118.73 | AY19: 118.73 | AZ19: 118.73 | BA19: 118.73 | BB19: 116.25 | BC19: 116.25 | BD19: 116.25 | BE19: 116.25 | BF19: 116.25 | BG19: 116.25 | BH19: 116.25 | BI19: 116.25 | BJ19: 116.25 | BK19: 116.25 | BL19: 116.25 | BM19: 116.25 | BN19: 116.25 | BO19: 116.25 | BP19: 116.25 | BQ19: 116.25 | BR19: 116.25 | BS19: 116.25 | BT19: 116.25 | BU19: 116.25 | BV19: 116.25 | BW19: 116.25 | BX19: 116.25 | BY19: 116.25 | BZ19: 116.25 | CA19: 116.25 | CB19: 116.25 | CC19: 116.25 | CD19: 116.25 | CE19: 116.25 | CF19: 116.25 | CG19: 116.25 | CH19: 116.25 | CI19: 116.25 | CJ19: 116.25 | CK19: 116.25 | CL19: 116.25
C20: Mortalities averted among people over age 5 | D20: 73.19 | E20: 73.19 | F20: 73.19 | G20: 73.19 | H20: 73.19 | I20: 73.19 | J20: 73.19 | K20: 73.19 | L20: 73.19 | M20: 73.19 | N20: 73.19 | O20: 73.19 | P20: 73.19 | Q20: 73.19 | R20: 73.19 | S20: 73.19 | T20: 73.19 | U20: 73.19 | V20: 73.19 | W20: 73.19 | X20: 73.19 | Y20: 73.19 | Z20: 73.19 | AA20: 73.19 | AB20: 73.19 | AC20: 73.19 | AD20: 73.19 | AE20: 73.19 | AF20: 73.19 | AG20: 73.19 | AH20: 73.19 | AI20: 73.19 | AJ20: 73.19 | AK20: 73.19 | AL20: 73.19 | AM20: 73.19 | AN20: 73.19 | AO20: 73.19 | AP20: 73.19 | AQ20: 73.19 | AR20: 73.19 | AS20: 73.19 | AT20: 73.19 | AU20: 73.19 | AV20: 73.19 | AW20: 73.19 | AX20: 73.19 | AY20: 73.19 | AZ20: 73.19 | BA20: 73.19 | BB20: 73.19 | BC20: 73.19 | BD20: 73.19 | BE20: 73.19 | BF20: 73.19 | BG20: 73.19 | BH20: 73.19 | BI20: 73.19 | BJ20: 73.19 | BK20: 73.19 | BL20: 73.19 | BM20: 73.19 | BN20: 73.19 | BO20: 73.19 | BP20: 73.19 | BQ20: 73.19 | BR20: 73.19 | BS20: 73.19 | BT20: 73.19 | BU20: 73.19 | BV20: 73.19 | BW20: 73.19 | BX20: 73.19 | BY20: 73.19 | BZ20: 73.19 | CA20: 73.19 | CB20: 73.19 | CC20: 73.19 | CD20: 73.19 | CE20: 73.19 | CF20: 73.19 | CG20: 73.19 | CH20: 73.19 | CI20: 73.19 | CJ20: 73.19 | CK20: 73.19 | CL20: 73.19
C21: Mortalities averted among people age 5 through 14 | D21: 133.7 | E21: 133.7 | F21: 133.7 | G21: 133.7 | H21: 133.7 | I21: 133.7 | J21: 133.7 | K21: 133.7 | L21: 133.7 | M21: 133.7 | N21: 133.7 | O21: 133.7 | P21: 133.7 | Q21: 133.7 | R21: 133.7 | S21: 133.7 | T21: 133.7 | U21: 133.7 | V21: 133.7 | W21: 133.7 | X21: 133.7 | Y21: 133.7 | Z21: 133.7 | AA21: 133.7 | AB21: 133.7 | AC21: 133.7 | AD21: 133.7 | AE21: 133.7 | AF21: 133.7 | AG21: 133.7 | AH21: 133.7 | AI21: 133.7 | AJ21: 133.7 | AK21: 133.7 | AL21: 133.7 | AM21: 133.7 | AN21: 133.7 | AO21: 133.7 | AP21: 133.7 | AQ21: 133.7 | AR21: 133.7 | AS21: 133.7 | AT21: 133.7 | AU21: 133.7 | AV21: 133.7 | AW21: 133.7 | AX21: 133.7 | AY21: 133.7 | AZ21: 133.7 | BA21: 133.7 | BB21: 133.7 | BC21: 133.7 | BD21: 133.7 | BE21: 133.7 | BF21: 133.7 | BG21: 133.7 | BH21: 133.7 | BI21: 133.7 | BJ21: 133.7 | BK21: 133.7 | BL21: 133.7 | BM21: 133.7 | BN21: 133.7 | BO21: 133.7 | BP21: 133.7 | BQ21: 133.7 | BR21: 133.7 | BS21: 133.7 | BT21: 133.7 | BU21: 133.7 | BV21: 133.7 | BW21: 133.7 | BX21: 133.7 | BY21: 133.7 | BZ21: 133.7 | CA21: 133.7 | CB21: 133.7 | CC21: 133.7 | CD21: 133.7 | CE21: 133.7 | CF21: 133.7 | CG21: 133.7 | CH21: 133.7 | CI21: 133.7 | CJ21: 133.7 | CK21: 133.7 | CL21: 133.7
C22: Mortalities averted among people age 15 through age 49 | D22: 103.59 | E22: 103.59 | F22: 103.59 | G22: 103.59 | H22: 103.59 | I22: 103.59 | J22: 103.59 | K22: 103.59 | L22: 103.59 | M22: 103.59 | N22: 103.59 | O22: 103.59 | P22: 103.59 | Q22: 103.59 | R22: 103.59 | S22: 103.59 | T22: 103.59 | U22: 103.59 | V22: 103.59 | W22: 103.59 | X22: 103.59 | Y22: 103.59 | Z22: 103.59 | AA22: 103.59 | AB22: 103.59 | AC22: 103.59 | AD22: 103.59 | AE22: 103.59 | AF22: 103.59 | AG22: 103.59 | AH22: 103.59 | AI22: 103.59 | AJ22: 103.59 | AK22: 103.59 | AL22: 103.59 | AM22: 103.59 | AN22: 103.59 | AO22: 103.59 | AP22: 103.59 | AQ22: 103.59 | AR22: 103.59 | AS22: 103.59 | AT22: 103.59 | AU22: 103.59 | AV22: 103.59 | AW22: 103.59 | AX22: 103.59 | AY22: 103.59 | AZ22: 103.59 | BA22: 103.59 | BB22: 103.59 | BC22: 103.59 | BD22: 103.59 | BE22: 103.59 | BF22: 103.59 | BG22: 103.59 | BH22: 103.59 | BI22: 103.59 | BJ22: 103.59 | BK22: 103.59 | BL22: 103.59 | BM22: 103.59 | BN22: 103.59 | BO22: 103.59 | BP22: 103.59 | BQ22: 103.59 | BR22: 103.59 | BS22: 103.59 | BT22: 103.59 | BU22: 103.59 | BV22: 103.59 | BW22: 103.59 | BX22: 103.59 | BY22: 103.59 | BZ22: 103.59 | CA22: 103.59 | CB22: 103.59 | CC22: 103.59 | CD22: 103.59 | CE22: 103.59 | CF22: 103.59 | CG22: 103.59 | CH22: 103.59 | CI22: 103.59 | CJ22: 103.59 | CK22: 103.59 | CL22: 103.59
