Workbook

Sheet Key
A1: [April
A2: Sheet descriptions
E4: Main CEA | F4: This sheet contains the primary calculations that result in final cost-effectiveness estimates. This sheet draws on inputs from the "Inputs" sheet and inputs calculated in the other supplemental sheets listed below.
E5: Aggregation across vaccines | F5: This sheet contains our calculations for pulling CEA parameters from other supplementary sheets and aggregating them across vaccines before entering them in the "Main CEA" sheet.
E6: Treatment effect | F6: This sheet contains our calculations of the effect of New Incentives' program on vaccine uptake.
E7: Disease burden | F7: This sheet contains our calculations of vaccine-preventable disease burden among New Incentives' target population.
E8: Vaccine coverage | F8: This sheet contains our calculations of baseline vaccination coverage among New Incentives' target population, as well as vaccination coverage among populations represented by GBD disease burden estimates.
E9: Vaccine efficacy | F9: This sheet contains our calculations of the effect of vaccination on disease incidence for each vaccine incentivized by New Incentives' program.
E10: Leverage/Funging | F10: This sheet contains our calculations of the impact that crowding in and crowding out funding by other contributors has on the benefits of the program.
E11: Inputs | F11: This sheet contains all of the manually entered input values informing the CEA, along with the sources and reasoning supporting them. This sheet also contains inputs sourced from the "GBD estimates" sheet.
E12: GBD estimates | F12: This sheet contains disease burden and population datasets downloaded from the Institute of Health Metrics (IHME)'s Global Burden of Disease (GBD) project.
E13: Simple CEA | F13: This sheet contains a simplified version of the CEA that is designed to be comparable to our CEAs of other programs.
E14: Sensitivity analysis | F14: This sheet contains the outputs of a sensitivity analysis macro that tests the cost-effectiveness ranges that would result from updating certain inputs to their 25th or 75th percentile values.
A16: Terminology key
C18: Terms specific to this CEA
E19: BCG vaccine | F19: The Bacillus Calmette-Guerin (BCG) vaccine is designed to prevent tuberculosis and other mycobacterial infections. BCG is one of the vaccines directly incentivized by New Incentives' program.
E20: Penta vaccine | F20: The pentavalent vaccine (referred to as Penta in this CEA) is a 5-in-1 vaccine that is designed to prevent diphtheria, pertussis, tetanus, hepatitis B, and H. influenza type B infections. Penta is one of the vaccines directly incentivized by New Incentives' program.
E21: DTP vaccine | F21: The DTP vaccine is designed to prevent diphtheria, pertussis, and tetanus. In Nigeria, the DTP vaccine is typically delivered as part of the Penta vaccine, which is one of the vaccines directly incentivized by New Incentives' program.
E22: Hib vaccine | F22: The HiB vaccine is designed to prevent H. influenzae type B (Hib) infections. In Nigeria, the Hib vaccine is typically delivered as part of the Penta vaccine, which is one of the vaccines directly incentivized by New Incentives' program.
E23: PCV vaccine | F23: The pneumococcal conjugate vaccine (PCV) is designed to prevent pneumococcal infections. PCV is one of the vaccines directly incentivized by New Incentives' program.
E24: Vaccine efficacy | F24: The efficacy rate of a vaccine refers to the reduction in vaccine-targeted disease incidence among people who receive the vaccine compared to those who do not receive the vaccine.
E25: Vaccine-preventable causes | F25: In this CEA, we use "vaccine-preventable causes" to refer to causes of disease incidence and mortality that are addressable by the specific set of vaccines directly incentivized by New Incentives' program.
E26: Vaccine-preventable mortalities | F26: In this CEA, we use "vaccine-preventable mortalities" to refer to mortalities that we expect would be averted if all children were fully vaccinated with the set of vaccines directly incentivized by New Incentives' program. Because vaccines are not 100% effective, the number of "vaccine-preventable mortalities" will always represent a subset of "mortalities from vaccine-preventable causes."
E27: MICS survey | F27: Multiple Indicator Cluster Surveys (MICS) are standardized household surveys implemented in many countries to collect data on a variety of indicators, including child vaccination rates.
C29: Terms used across GiveWell's CEAs
E30: Internal validity | F30: Describes an adjustment we make to the treatment effect of an intervention to account for the possibility that the treatment effects found in studies may not represent the true effect the intervention had on the populations studied.
E31: External validity | F31: Describes an adjustment we make to the treatment effect of an intervention to account for differences in the program implementation or populations treated in studies from the program implementation or populations treated by grantee programs.
E32: Leverage | F32: Describes a situation where a grantee's spending on a program causes other organizations or governments to contribute more to the program than they otherwise would have. In most cases, accounting for leverage increases cost-effectiveness
E33: Funging | F33: Describes a situation where a grantee's spending on a program causes other organizations or governments to contribute less to the program than they otherwise would have. In most cases, accounting for funging decreases cost-effectiveness.
E34: Counterfactual | F34: In most cases, describes the state of the world that would exist if we did not provide funding to a grantee for a program. When discussing the "counterfactual value of other actors' spending," we are referring to how much benefit another organization's or government's spending would generate if it were spent on something other than the grantee program.
E35: Moral weights | F35: To compare cost-effectiveness across different programs, we use ‘moral weights’ to quantify the benefits of different program impacts (e.g. increased income vs reduced deaths). We benchmark the value of each benefit to a value of 1, which we define as the value of doubling someone’s consumption for one year.
E36: Philanthropic actors | F36: Non-governmental organizations (NGOs) providing funding to philanthropic programs.
A38: Unit and source key
C40: Unit labels used in the CEA
E41: # | F41: Number
E42: per 1k | F42: Rate per 1,000
E43: per 100k | F43: Rate per 100,000
E44: $ | F44: U.S. dollars
E45: ln($) | F45: The natural logarithm of a monetary value
E46: % | F46: Percentage
...

Sheet Main CEA
I1: New Incentives – current states of operation | R1: New Incentives – prospective states | AF1: New Incentives – prospective states
I2: Nigeria | J2: Nigeria | K2: Nigeria | L2: Nigeria | M2: Nigeria | N2: Nigeria | O2: Nigeria | P2: Nigeria | Q2: Nigeria | R2: Nigeria | S2: Nigeria | T2: Nigeria | U2: Nigeria | V2: Nigeria | W2: Nigeria | X2: Nigeria | Y2: Nigeria | Z2: Nigeria | AA2: Nigeria | AB2: Nigeria | AC2: Nigeria | AD2: Nigeria | AE2: Nigeria | AF2: Nigeria | AG2: Nigeria | AH2: Nigeria | AI2: Nigeria | AJ2: Nigeria | AK2: Nigeria | AL2: Nigeria | AM2: Nigeria | AN2: Nigeria | AO2: Nigeria | AP2: Nigeria | AQ2: Nigeria | AR2: Nigeria | AS2: Nigeria
A3: Main calculations | F3: unit | G3: type | H3: Overall | I3: Bauchi | J3: Gombe | K3: Jigawa | L3: Kaduna | M3: Kano | N3: Katsina | O3: Kebbi | P3: Sokoto | Q3: Zamfara | R3: Abia | S3: Adamawa | T3: Akwa Ibom | U3: Anambra | V3: Bayelsa | W3: Benue | X3: Borno | Y3: Cross River | Z3: Delta | AA3: Ebonyi | AB3: Edo | AC3: Ekiti | AD3: Enugu | AE3: FCT | AF3: Imo | AG3: Kogi | AH3: Kwara | AI3: Lagos | AJ3: Nasarawa | AK3: Niger | AL3: Ogun | AM3: Ondo | AN3: Osun | AO3: Oyo | AP3: Plateau | AQ3: Rivers | AR3: Taraba | AS3: Yobe
E4: Final cost-effectiveness estimate (pulled from below for visibility) | F4: =F241 -> xcash | G4: feed | H4: =H241 -> - | I4: =I241 -> 23.798889 | J4: =J241 -> 10.800641 | K4: =K241 -> 19.899944 | L4: =L241 -> 5.6568275 | M4: =M241 -> 13.129176 | N4: =N241 -> 20.329812 | O4: =O241 -> 31.532139 | ... AS4: =AS241 -> 6.7228331
A5: Grantee costs
C7: GiveWell costs
E8: Grant size | F8: =Inputs!F8 -> $ | G8: =Inputs!G8 -> input | H8: =Inputs!H8 -> 1000000 | I8: =Inputs!I8 -> - | J8: =Inputs!J8 -> - | K8: =Inputs!K8 -> - | L8: =Inputs!L8 -> - | M8: =Inputs!M8 -> - | ... AS8: =Inputs!AS8 -> -
C10: Spending attributable to grantee
E11: Total spending contributed by grantee | F11: $ | G11: calc | H11: - | I11: =IF(I8="-",$H8,I8) -> 1000000 | J11: =IF(J8="-",$H8,J8) -> 1000000 | K11: =IF(K8="-",$H8,K8) -> 1000000 | L11: =IF(L8="-",$H8,L8) -> 1000000 | M11: =IF(M8="-",$H8,M8) -> 1000000 | N11: =IF(N8="-",$H8,N8) -> 1000000 | O11: =IF(O8="-",$H8,O8) -> 1000000 | P11: =IF(P8="-",$H8,P8) -> 1000000 | ... AS11: =IF(AS8="-",$H8,AS8) -> 1000000
C13: Cost per child enrolled
E14: Cost per infant enrolled in the program | F14: =Inputs!F11 -> $ | G14: =Inputs!G11 -> input | H14: =Inputs!H11 -> 21.27455 | I14: =Inputs!I11 -> - | J14: =Inputs!J11 -> - | K14: =Inputs!K11 -> - | L14: =Inputs!L11 -> - | M14: =Inputs!M11 -> - | ... AS14: =Inputs!AS11 -> -
A16: Outputs
C18: Total children enrolled
E19: Total children enrolled in the program | F19: # | G19: calc | H19: - | I19: =I11/$H14 -> 47004.519 | J19: =J11/$H14 -> 47004.519 | K19: =K11/$H14 -> 47004.519 | L19: =L11/$H14 -> 47004.519 | M19: =M11/$H14 -> 47004.519 | N19: =N11/$H14 -> 47004.519 | O19: =O11/$H14 -> 47004.519 | P19: =P11/$H14 -> 47004.519 | ... AS19: =AS11/$H14 -> 47004.519
C21: Total children vaccinated
E22: Proportion of vaccinated children who are enrolled in New Incentives' program | F22: =Inputs!F220 -> % | G22: =Inputs!G220 -> input | H22: =Inputs!H220 -> 0.95 | I22: =Inputs!I220 -> - | J22: =Inputs!J220 -> - | K22: =Inputs!K220 -> - | L22: =Inputs!L220 -> - | M22: =Inputs!M220 -> - | ... AS22: =Inputs!AS220 -> -
E23: Total children vaccinated in program areas | F23: % | G23: calc | H23: - | I23: =I19/$H22 -> 49478.442 | J23: =J19/$H22 -> 49478.442 | K23: =K19/$H22 -> 49478.442 | L23: =L19/$H22 -> 49478.442 | M23: =M19/$H22 -> 49478.442 | N23: =N19/$H22 -> 49478.442 | O23: =O19/$H22 -> 49478.442 | P23: =P19/$H22 -> 49478.442 | ... AS23: =AS19/$H22 -> 49478.442
C25: Counterfactual vaccination coverage
E26: Proportion of children in the target population who would be vaccinated in the absence of the program, aggregated across vaccines | F26: ='Aggregation across vaccines'!F32 -> % | G26: supp | H26: ='Aggregation across vaccines'!H32 -> - | I26: ='Aggregation across vaccines'!I32 -> 0.47613003 | J26: ='Aggregation across vaccines'!J32 -> 0.62518435 | K26: ='Aggregation across vaccines'!K32 -> 0.55281297 | L26: ='Aggregation across vaccines'!L32 -> 0.69332916 | M26: ='Aggregation across vaccines'!M32 -> 0.53428802 | N26: ='Aggregation across vaccines'!N32 -> 0.43954496 | O26: ='Aggregation across vaccines'!O32 -> 0.32205884 | ... AS26: ='Aggregation across vaccines'!AS32 -> 0.71672388
E27: Corresponding proportion of children who would not be vaccinated in the absence of the program, aggregated across incentivized vaccines | F27: % | G27: calc | H27: - | I27: =1-I26 -> 0.52386997 | J27: =1-J26 -> 0.37481565 | K27: =1-K26 -> 0.44718703 | L27: =1-L26 -> 0.30667084 | M27: =1-M26 -> 0.46571198 | N27: =1-N26 -> 0.56045504 | O27: =1-O26 -> 0.67794116 | P27: =1-P26 -> 0.7531465 | ... AS27: =1-AS26 -> 0.28327612
C29: Effect of the program on vaccination coverage
E30: Reduction in the proportion of children who are unvaccinated as a result of New Incentives' program, based on GW's analysis of the New Incentives RCT, aggregated across vaccines | F30: ='Treatment effect'!F70 -> % | G30: supp | H30: ='Treatment effect'!H70 -> 0.33388688 | I30: ='Treatment effect'!I70 -> - | J30: ='Treatment effect'!J70 -> - | K30: ='Treatment effect'!K70 -> - | L30: ='Treatment effect'!L70 -> - | M30: ='Treatment effect'!M70 -> - | N30: ='Treatment effect'!N70 -> - | O30: ='Treatment effect'!O70 -> - | ... AS30: ='Treatment effect'!AS70 -> -
E31: Internal validity adjustment | F31: =Inputs!F223 -> % | G31: =Inputs!G223 -> input | H31: =Inputs!H223 -> -0.12 | I31: =Inputs!I223 -> - | J31: =Inputs!J223 -> - | K31: =Inputs!K223 -> - | L31: =Inputs!L223 -> - | M31: =Inputs!M223 -> - | ... AS31: =Inputs!AS223 -> -
E32: Reduction in the proportion of children who are unvaccinated as a result of New Incentives' program | F32: % | G32: calc | H32: =H30*(1+H31) -> 0.29382046 | I32: - | J32: - | K32: - | L32: - | M32: - | N32: - | O32: - | P32: - | R32: - | S32: - | T32: - | U32: - | V32: - | W32: - | X32: - | Y32: - | Z32: - | AA32: - | AB32: - | AC32: - | AD32: - | AE32: - | AF32: - | AG32: - | AH32: - | AI32: - | AJ32: - | AK32: - | AL32: - | AM32: - | AN32: - | AO32: - | AP32: - | AQ32: - | AR32: - | AS32: -
E33: Corresponding increase in the proportion of children who are vaccinated as a result of New Incentives' program | F33: ppt | G33: calc | H33: - | I33: =I27*$H32 -> 0.15392371 | J33: =J27*$H32 -> 0.1101285 | K33: =K27*$H32 -> 0.1313927 | L33: =L27*$H32 -> 0.090106167 | M33: =M27*$H32 -> 0.1368357 | N33: =N27*$H32 -> 0.16467315 | O33: =O27*$H32 -> 0.19919298 | P33: =P27*$H32 -> 0.22128985 | ... AS33: =AS27*$H32 -> 0.08323232
E34: Total proportion of children in the target population who are vaccinated | F34: % | G34: calc | H34: - | I34: =I26+I33 -> 0.63005374 | J34: =J26+J33 -> 0.73531286 | K34: =K26+K33 -> 0.68420567 | L34: =L26+L33 -> 0.78343532 | M34: =M26+M33 -> 0.67112373 | N34: =N26+N33 -> 0.60421812 | O34: =O26+O33 -> 0.52125182 | P34: =P26+P33 -> 0.46814335 | ... AS34: =AS26+AS33 -> 0.7999562
C36: Number of children vaccinated as a result of New Incentives' program
E37: Children in the target population | F37: # | G37: calc | H37: - | I37: =I23/I34 -> 78530.51 | J37: =J23/J34 -> 67288.966 | K37: =K23/K34 -> 72315.159 | L37: =L23/L34 -> 63155.745 | M37: =M23/M34 -> 73724.769 | N37: =N23/N34 -> 81888.378 | O37: =O23/O34 -> 94922.338 | P37: =P23/P34 -> 105690.79 | ... AS37: =AS23/AS34 -> 61851.439
E38: Children counterfactually vaccinated | F38: # | G38: calc | H38: - | I38: =I37*I33 -> 12087.708 | J38: =J37*J33 -> 7410.4331 | K38: =K37*K33 -> 9501.6837 | L38: =L37*L33 -> 5690.7221 | M38: =M37*M33 -> 10088.181 | N38: =N37*N33 -> 13484.817 | O38: =O37*O33 -> 18907.863 | P38: =P37*P33 -> 23388.3 | ... AS38: =AS37*AS33 -> 5148.0387
A40: Outcomes
C42: Mortality reduction among people under age 5
E43: Probability that a person will die of a vaccine-preventable cause before reaching age 5, adjusted for deaths occurring before the age of vaccination | F43: ='Disease burden'!F184 -> % | G43: supp | H43: ='Disease burden'!H184 -> - | I43: ='Disease burden'!I184 -> 0.029558884 | J43: ='Disease burden'!J184 -> 0.021078685 | K43: ='Disease burden'!K184 -> 0.029201114 | L43: ='Disease burden'!L184 -> 0.012703905 | M43: ='Disease burden'!M184 -> 0.020249832 | N43: ='Disease burden'!N184 -> 0.021535107 | O43: ='Disease burden'!O184 -> 0.023390457 | ... AS43: ='Disease burden'!AS184 -> 0.015604259
E44: Proportion of people under age 5 represented in GBD 2021 disease burden estimates who were vaccinated, aggregated across vaccines | F44: ='Aggregation across vaccines'!F64 -> % | G44: supp | H44: ='Aggregation across vaccines'!H64 -> - | I44: ='Aggregation across vaccines'!I64 -> 0.27548418 | J44: ='Aggregation across vaccines'!J64 -> 0.34752396 | K44: ='Aggregation across vaccines'!K64 -> 0.30600516 | L44: ='Aggregation across vaccines'!L64 -> 0.4480187 | M44: ='Aggregation across vaccines'!M64 -> 0.29422974 | N44: ='Aggregation across vaccines'!N64 -> 0.2806275 | O44: ='Aggregation across vaccines'!O64 -> 0.31099173 | ... AS44: ='Aggregation across vaccines'!AS64 -> 0.33924752
E45: Proportion of vaccine-preventable disease incidence averted by full vaccination among people under age 5, aggregated across vaccines | F45: ='Aggregation across vaccines'!F53 -> % | G45: supp | H45: ='Aggregation across vaccines'!H53 -> - | I45: ='Aggregation across vaccines'!I53 -> 0.52870848 | J45: ='Aggregation across vaccines'!J53 -> 0.52476274 | K45: ='Aggregation across vaccines'!K53 -> 0.54543544 | L45: ='Aggregation across vaccines'!L53 -> 0.53079041 | M45: ='Aggregation across vaccines'!M53 -> 0.51766922 | N45: ='Aggregation across vaccines'!N53 -> 0.53814058 | O45: ='Aggregation across vaccines'!O53 -> 0.53885814 | ... AS45: ='Aggregation across vaccines'!AS53 -> 0.54241469
E46: Probability that an unvaccinated person will die of a vaccine-preventable cause before reaching age 5, adjusted for deaths occurring before the age of vaccination | F46: ='Disease burden'!F209 -> % | G46: calc | H46: ='Disease burden'!H209 -> - | I46: =I43/((1-I44)+(I44*(1-I45))) -> 0.03459813 | J46: =J43/((1-J44)+(J44*(1-J45))) -> 0.02578015 | K46: =K43/((1-K44)+(K44*(1-K45))) -> 0.035051406 | L46: =L43/((1-L44)+(L44*(1-L45))) -> 0.016667505 | M46: =M43/((1-M44)+(M44*(1-M45))) -> 0.023888356 | N46: =N43/((1-N44)+(N44*(1-N45))) -> 0.025365771 | O46: =O43/((1-O44)+(O44*(1-O45))) -> 0.02809936 | P46: =P43/((1-P44)+(P44*(1-P45))) -> 0.037980473 | ... AS46: =AS43/((1-AS44)+(AS44*(1-AS45))) -> 0.019123167
E47: Mortalities indirectly attributable to vaccine-preventable disease per mortality directly caused by vaccine-preventable disease | F47: =Inputs!F228 -> % | G47: =Inputs!G228 -> input | H47: =Inputs!H228 -> 0.75 | I47: =Inputs!I228 -> - | J47: =Inputs!J228 -> - | K47: =Inputs!K228 -> - | L47: =Inputs!L228 -> - | M47: =Inputs!M228 -> - | ... AS47: =Inputs!AS228 -> -
E48: Probability that an unvaccinated person will die of a vaccine-preventable cause before reaching age 5, including mortalities indirectly attributable to vaccine-preventable disease | F48: % | G48: calc | H48: - | I48: =I46*(1+$H47) -> 0.060546727 | J48: =J46*(1+$H47) -> 0.045115262 | K48: =K46*(1+$H47) -> 0.061339961 | L48: =L46*(1+$H47) -> 0.029168133 | M48: =M46*(1+$H47) -> 0.041804622 | N48: =N46*(1+$H47) -> 0.044390098 | O48: =O46*(1+$H47) -> 0.04917388 | P48: =P46*(1+$H47) -> 0.066465827 | ... AS48: =AS46*(1+$H47) -> 0.033465543
E49: Ratio of the reduction in vaccine-preventable disease mortality to the reduction in vaccine-preventable disease incidence | F49: =Inputs!F229 -> % | G49: =Inputs!G229 -> input | H49: =Inputs!H229 -> 1 | I49: =Inputs!I229 -> - | J49: =Inputs!J229 -> - | K49: =Inputs!K229 -> - | L49: =Inputs!L229 -> - | M49: =Inputs!M229 -> - | ... AS49: =Inputs!AS229 -> -
E50: Total deaths averted among people under age 5 | F50: # | G50: calc | H50: - | I50: =I38*I45*I48*$H49 -> 386.94648 | J50: =J38*J45*J48*$H49 -> 175.44058 | K50: =K38*K45*K48*$H49 -> 317.89772 | L50: =L38*L45*L48*$H49 -> 88.1047 | M50: =M38*M45*M48*$H49 -> 218.31798 | N50: =N38*N45*N48*$H49 -> 322.12685 | O50: =O38*O45*O48*$H49 -> 501.01575 | P50: =P38*P45*P48*$H49 -> 825.62163 | ... AS50: =AS38*AS45*AS48*$H49 -> 93.448237
C52: Mortality reduction among people age 5 through age 14
...

Sheet Aggregation across vaccines
I1: New Incentives – current states of operation | R1: New Incentives – prospective states | AF1: New Incentives – prospective states
I2: Nigeria | J2: Nigeria | K2: Nigeria | L2: Nigeria | M2: Nigeria | N2: Nigeria | O2: Nigeria | P2: Nigeria | Q2: Nigeria | R2: Nigeria | S2: Nigeria | T2: Nigeria | U2: Nigeria | V2: Nigeria | W2: Nigeria | X2: Nigeria | Y2: Nigeria | Z2: Nigeria | AA2: Nigeria | AB2: Nigeria | AC2: Nigeria | AD2: Nigeria | AE2: Nigeria | AF2: Nigeria | AG2: Nigeria | AH2: Nigeria | AI2: Nigeria | AJ2: Nigeria | AK2: Nigeria | AL2: Nigeria | AM2: Nigeria | AN2: Nigeria | AO2: Nigeria | AP2: Nigeria | AQ2: Nigeria | AR2: Nigeria | AS2: Nigeria
A3: Main calculations | F3: unit | G3: type | H3: Overall | I3: Bauchi | J3: Gombe | K3: Jigawa | L3: Kaduna | M3: Kano | N3: Katsina | O3: Kebbi | P3: Sokoto | Q3: Zamfara | R3: Abia | S3: Adamawa | T3: Akwa Ibom | U3: Anambra | V3: Bayelsa | W3: Benue | X3: Borno | Y3: Cross River | Z3: Delta | AA3: Ebonyi | AB3: Edo | AC3: Ekiti | AD3: Enugu | AE3: FCT | AF3: Imo | AG3: Kogi | AH3: Kwara | AI3: Lagos | AJ3: Nasarawa | AK3: Niger | AL3: Ogun | AM3: Ondo | AN3: Osun | AO3: Oyo | AP3: Plateau | AQ3: Rivers | AR3: Taraba | AS3: Yobe
E4: Final cost-effectiveness estimate (pulled from "Main calcs" sheet for visibility) | F4: ='Main CEA'!F241 -> xcash | G4: ='Main CEA'!G241 -> calc | H4: ='Main CEA'!H241 -> - | I4: ='Main CEA'!I241 -> 23.798889 | J4: ='Main CEA'!J241 -> 10.800641 | K4: ='Main CEA'!K241 -> 19.899944 | L4: ='Main CEA'!L241 -> 5.6568275 | M4: ='Main CEA'!M241 -> 13.129176 | ... AS4: ='Main CEA'!AS241 -> 6.7228331
A5: Baseline coverage for the target population
C7: Baseline vaccination coverage for the target population
E8: Baseline proportion of children in the target population who receive the BCG vaccine | F8: ='Vaccine coverage'!F91 -> % | G8: supp | H8: ='Vaccine coverage'!H91 -> - | I8: ='Vaccine coverage'!I91 -> 0.55353772 | J8: ='Vaccine coverage'!J91 -> 0.72328382 | K8: ='Vaccine coverage'!K91 -> 0.61118826 | L8: ='Vaccine coverage'!L91 -> 0.77568938 | M8: ='Vaccine coverage'!M91 -> 0.62892504 | N8: ='Vaccine coverage'!N91 -> 0.49455416 | O8: ='Vaccine coverage'!O91 -> 0.39201909 | ... AS8: ='Vaccine coverage'!AS91 -> 0.7529799
E9: Baseline proportion of children in the target population who receive the 1st dose of the Penta vaccine | F9: ='Vaccine coverage'!F92 -> % | G9: supp | H9: ='Vaccine coverage'!H92 -> - | I9: ='Vaccine coverage'!I92 -> 0.49558276 | J9: ='Vaccine coverage'!J92 -> 0.67331278 | K9: ='Vaccine coverage'!K92 -> 0.57384453 | L9: ='Vaccine coverage'!L92 -> 0.74159805 | M9: ='Vaccine coverage'!M92 -> 0.57953749 | N9: ='Vaccine coverage'!N92 -> 0.45805759 | O9: ='Vaccine coverage'!O92 -> 0.32588565 | ... AS9: ='Vaccine coverage'!AS92 -> 0.73896166
E10: Baseline proportion of children in the target population who receive the 2nd dose of the Penta vaccine | F10: ='Vaccine coverage'!F93 -> % | G10: supp | H10: ='Vaccine coverage'!H93 -> - | I10: ='Vaccine coverage'!I93 -> 0.45193705 | J10: ='Vaccine coverage'!J93 -> 0.63149437 | K10: ='Vaccine coverage'!K93 -> 0.51747533 | L10: ='Vaccine coverage'!L93 -> 0.67035112 | M10: ='Vaccine coverage'!M93 -> 0.49860579 | N10: ='Vaccine coverage'!N93 -> 0.4193159 | O10: ='Vaccine coverage'!O93 -> 0.23438593 | ... AS10: ='Vaccine coverage'!AS93 -> 0.71292778
E11: Baseline proportion of children in the target population who receive the 3rd dose of the Penta vaccine | F11: ='Vaccine coverage'!F94 -> % | G11: supp | H11: ='Vaccine coverage'!H94 -> - | I11: ='Vaccine coverage'!I94 -> 0.36136808 | J11: ='Vaccine coverage'!J94 -> 0.50198796 | K11: ='Vaccine coverage'!K94 -> 0.39680563 | L11: ='Vaccine coverage'!L94 -> 0.57935842 | M11: ='Vaccine coverage'!M94 -> 0.38185245 | N11: ='Vaccine coverage'!N94 -> 0.35294269 | O11: ='Vaccine coverage'!O94 -> 0.14129572 | ... AS11: ='Vaccine coverage'!AS94 -> 0.64283656
E12: Baseline proportion of children in the target population who receive the 1st dose of the PCV vaccine | F12: ='Vaccine coverage'!F103 -> % | G12: supp | H12: ='Vaccine coverage'!H103 -> - | I12: ='Vaccine coverage'!I103 -> 0.49380009 | J12: ='Vaccine coverage'!J103 -> 0.63762814 | K12: ='Vaccine coverage'!K103 -> 0.56626675 | L12: ='Vaccine coverage'!L103 -> 0.7278372 | M12: ='Vaccine coverage'!M103 -> 0.56588241 | N12: ='Vaccine coverage'!N103 -> 0.44352586 | O12: ='Vaccine coverage'!O103 -> 0.32098795 | ... AS12: ='Vaccine coverage'!AS103 -> 0.7209382
E13: Baseline proportion of children in the target population who receive the 2nd dose of the PCV vaccine | F13: ='Vaccine coverage'!F104 -> % | G13: supp | H13: ='Vaccine coverage'!H104 -> - | I13: ='Vaccine coverage'!I104 -> 0.45031138 | J13: ='Vaccine coverage'!J104 -> 0.59802605 | K13: ='Vaccine coverage'!K104 -> 0.51064193 | L13: ='Vaccine coverage'!L104 -> 0.65791231 | M13: ='Vaccine coverage'!M104 -> 0.48685763 | N13: ='Vaccine coverage'!N104 -> 0.39808199 | O13: ='Vaccine coverage'!O104 -> 0.23086336 | ... AS13: ='Vaccine coverage'!AS104 -> 0.68188738
E14: Baseline proportion of children in the target population who receive the 3rd dose of the PCV vaccine | F14: ='Vaccine coverage'!F105 -> % | G14: supp | H14: ='Vaccine coverage'!H105 -> - | I14: ='Vaccine coverage'!I105 -> 0.36006819 | J14: ='Vaccine coverage'!J105 -> 0.4753833 | K14: ='Vaccine coverage'!K105 -> 0.3915657 | L14: ='Vaccine coverage'!L105 -> 0.56860804 | M14: ='Vaccine coverage'!M105 -> 0.37285523 | N14: ='Vaccine coverage'!N105 -> 0.33628008 | O14: ='Vaccine coverage'!O105 -> 0.1391722 | ... AS14: ='Vaccine coverage'!AS105 -> 0.63182223
E15: Baseline proportion of children in the target popullation who receive the 1st dose of the rotavirus vaccine | F15: ='Vaccine coverage'!F110 -> % | G15: supp | H15: ='Vaccine coverage'!H110 -> - | I15: ='Vaccine coverage'!I110 -> 0.49469143 | J15: ='Vaccine coverage'!J110 -> 0.65547046 | K15: ='Vaccine coverage'!K110 -> 0.57005564 | L15: ='Vaccine coverage'!L110 -> 0.73471763 | M15: ='Vaccine coverage'!M110 -> 0.57270995 | N15: ='Vaccine coverage'!N110 -> 0.45079172 | O15: ='Vaccine coverage'!O110 -> 0.3234368 | ... AS15: ='Vaccine coverage'!AS110 -> 0.72994993
E16: Estimated proportion of children in the target population who receive the 2nd dose of the rotavirus vaccine | F16: ='Vaccine coverage'!F111 -> % | G16: supp | H16: ='Vaccine coverage'!H111 -> - | I16: ='Vaccine coverage'!I111 -> 0.45112421 | J16: ='Vaccine coverage'!J111 -> 0.61476021 | K16: ='Vaccine coverage'!K111 -> 0.51405863 | L16: ='Vaccine coverage'!L111 -> 0.66413171 | M16: ='Vaccine coverage'!M111 -> 0.49273171 | N16: ='Vaccine coverage'!N111 -> 0.40869894 | O16: ='Vaccine coverage'!O111 -> 0.23262465 | ... AS16: ='Vaccine coverage'!AS111 -> 0.69740758
E17: Baseline proportion of children in the target population who receive the 1st dose of the measles vaccine | F17: ='Vaccine coverage'!F118 -> % | G17: supp | H17: ='Vaccine coverage'!H118 -> - | I17: ='Vaccine coverage'!I118 -> 0.30840134 | J17: ='Vaccine coverage'!J118 -> 0.36747822 | K17: ='Vaccine coverage'!K118 -> 0.55972841 | L17: ='Vaccine coverage'!L118 -> 0.56773883 | M17: ='Vaccine coverage'!M118 -> 0.40552774 | N17: ='Vaccine coverage'!N118 -> 0.43756944 | O17: ='Vaccine coverage'!O118 -> 0.63282353 | ... AS17: ='Vaccine coverage'!AS118 -> 0.71392908
C19: Proportion of vaccine-preventable mortalities that could be prevented by each vaccine dose
E20: Proportion of vaccine-preventable mortalities among people under age 5 that could be prevented by the BCG vaccine | F20: ='Disease burden'!F384 -> % | G20: ='Disease burden'!G384 -> feed | H20: ='Disease burden'!H384 -> - | I20: ='Disease burden'!I384 -> 0.2130494 | J20: ='Disease burden'!J384 -> 0.15347722 | K20: ='Disease burden'!K384 -> 0.24112748 | L20: ='Disease burden'!L384 -> 0.13471259 | M20: ='Disease burden'!M384 -> 0.15263081 | ... AS20: ='Disease burden'!AS384 -> 0.19515058
E21: Proportion of vaccine-preventable mortalities among people under age 5 that could be prevented by the 1st dose of the Penta vaccine | F21: ='Disease burden'!F385 -> % | G21: supp | H21: ='Disease burden'!H385 -> - | I21: ='Disease burden'!I385 -> 0.053131051 | J21: ='Disease burden'!J385 -> 0.06606296 | K21: ='Disease burden'!K385 -> 0.059308756 | L21: ='Disease burden'!L385 -> 0.070627408 | M21: ='Disease burden'!M385 -> 0.057825023 | N21: ='Disease burden'!N385 -> 0.062888388 | O21: ='Disease burden'!O385 -> 0.070475442 | ... AS21: ='Disease burden'!AS385 -> 0.071075284
E22: Proportion of vaccine-preventable mortalities among people under age 5 that could be prevented by the 2nd dose of the Penta vaccine | F22: ='Disease burden'!F386 -> % | G22: supp | H22: ='Disease burden'!H386 -> - | I22: ='Disease burden'!I386 -> 0.083491652 | J22: ='Disease burden'!J386 -> 0.10381322 | K22: ='Disease burden'!K386 -> 0.093199474 | L22: ='Disease burden'!L386 -> 0.11098593 | M22: ='Disease burden'!M386 -> 0.090867893 | N22: ='Disease burden'!N386 -> 0.098824609 | O22: ='Disease burden'!O386 -> 0.11074712 | ... AS22: ='Disease burden'!AS386 -> 0.11168973
E23: Proportion of vaccine-preventable mortalities among people under age 5 that could be prevented by the 3rd dose of the Penta vaccine | F23: ='Disease burden'!F387 -> % | G23: supp | H23: ='Disease burden'!H387 -> - | I23: ='Disease burden'!I387 -> 0.0151803 | J23: ='Disease burden'!J387 -> 0.018875132 | K23: ='Disease burden'!K387 -> 0.016945359 | L23: ='Disease burden'!L387 -> 0.020179259 | M23: ='Disease burden'!M387 -> 0.016521435 | N23: ='Disease burden'!N387 -> 0.017968111 | O23: ='Disease burden'!O387 -> 0.02013584 | ... AS23: ='Disease burden'!AS387 -> 0.020307224
E24: Proportion of vaccine-preventable mortalities among people under age 5 that could be prevented by the 1st dose of the PCV vaccine | F24: ='Disease burden'!F388 -> % | G24: supp | H24: ='Disease burden'!H388 -> - | I24: ='Disease burden'!I388 -> 0.11779326 | J24: ='Disease burden'!J388 -> 0.13550544 | K24: ='Disease burden'!K388 -> 0.11656148 | L24: ='Disease burden'!L388 -> 0.14964149 | M24: ='Disease burden'!M388 -> 0.14524548 | N24: ='Disease burden'!N388 -> 0.10887223 | O24: ='Disease burden'!O388 -> 0.1087302 | ... AS24: ='Disease burden'!AS388 -> 0.11016126
E25: Proportion of vaccine-preventable mortalities among people under age 5 that could be prevented by the 2nd dose of the PCV vaccine | F25: ='Disease burden'!F389 -> % | G25: supp | H25: ='Disease burden'!H389 -> - | I25: ='Disease burden'!I389 -> 0.18510369 | J25: ='Disease burden'!J389 -> 0.21293712 | K25: ='Disease burden'!K389 -> 0.18316803 | L25: ='Disease burden'!L389 -> 0.23515091 | M25: ='Disease burden'!M389 -> 0.2282429 | N25: ='Disease burden'!N389 -> 0.17108494 | O25: ='Disease burden'!O389 -> 0.17086174 | ... AS25: ='Disease burden'!AS389 -> 0.17311055
E26: Proportion of vaccine-preventable mortalities among people under age 5 that could be prevented by the 3rd dose of the PCV vaccine | F26: ='Disease burden'!F390 -> % | G26: supp | H26: ='Disease burden'!H390 -> - | I26: ='Disease burden'!I390 -> 0.033655217 | J26: ='Disease burden'!J390 -> 0.03871584 | K26: ='Disease burden'!K390 -> 0.033303279 | L26: ='Disease burden'!L390 -> 0.042754711 | M26: ='Disease burden'!M390 -> 0.041498709 | N26: ='Disease burden'!N390 -> 0.031106352 | O26: ='Disease burden'!O390 -> 0.031065772 | ... AS26: ='Disease burden'!AS390 -> 0.031474645
E27: Proportion of vaccine-preventable mortalities among people under age 5 that could be prevented by the 1st dose of the rotavirus vaccine | F27: ='Disease burden'!F391 -> % | G27: supp | H27: ='Disease burden'!H391 -> - | I27: ='Disease burden'!I391 -> 0.20297125 | J27: ='Disease burden'!J391 -> 0.19018131 | K27: ='Disease burden'!K391 -> 0.16184636 | L27: ='Disease burden'!L391 -> 0.15476798 | M27: ='Disease burden'!M391 -> 0.19738225 | N27: ='Disease burden'!N391 -> 0.18869946 | O27: ='Disease burden'!O391 -> 0.18724923 | ... AS27: ='Disease burden'!AS391 -> 0.17620694
E28: Proportion of vaccine-preventable mortalities among people under age 5 that could be prevented by the 2nd dose of the rotavirus vaccine | F28: ='Disease burden'!F392 -> % | G28: supp | H28: ='Disease burden'!H392 -> - | I28: ='Disease burden'!I392 -> 0.035818456 | J28: ='Disease burden'!J392 -> 0.033561407 | K28: ='Disease burden'!K392 -> 0.028561122 | L28: ='Disease burden'!L392 -> 0.027311996 | M28: ='Disease burden'!M392 -> 0.034832162 | N28: ='Disease burden'!N392 -> 0.033299904 | O28: ='Disease burden'!O392 -> 0.033043981 | ... AS28: ='Disease burden'!AS392 -> 0.031095342
E29: Proportion of vaccine-preventable mortalities among people under age 5 that could be prevented by the 1st dose of the measles vaccine | F29: ='Disease burden'!F393 -> % | G29: supp | H29: ='Disease burden'!H393 -> - | I29: ='Disease burden'!I393 -> 0.059805717 | J29: ='Disease burden'!J393 -> 0.046870343 | K29: ='Disease burden'!K393 -> 0.06597866 | L29: ='Disease burden'!L393 -> 0.053867734 | M29: ='Disease burden'!M393 -> 0.034953333 | N29: ='Disease burden'!N393 -> 0.081308726 | O29: ='Disease burden'!O393 -> 0.076530784 | ... AS29: ='Disease burden'!AS393 -> 0.079728455
C31: Baseline vaccination coverage for the target population, aggregated across vaccines
E32: Proportion of children in the target population who would be vaccinated in the absence of the program, aggregated across vaccines | F32: % | G32: calc | H32: - | I32: =SUMPRODUCT(I8:I17,I20:I29) -> 0.47613003 | J32: =SUMPRODUCT(J8:J17,J20:J29) -> 0.62518435 | K32: =SUMPRODUCT(K8:K17,K20:K29) -> 0.55281297 | L32: =SUMPRODUCT(L8:L17,L20:L29) -> 0.69332916 | M32: =SUMPRODUCT(M8:M17,M20:M29) -> 0.53428802 | N32: =SUMPRODUCT(N8:N17,N20:N29) -> 0.43954496 | O32: =SUMPRODUCT(O8:O17,O20:O29) -> 0.32205884 | P32: =SUMPRODUCT(P8:P17,P20:P29) -> 0.2468535 | ... AS32: =SUMPRODUCT(AS8:AS17,AS20:AS29) -> 0.71672388
A34: Vaccine efficacy and coverage for people under age 5, aggregated across vaccines
C36: Vaccine efficacy with universal coverage
E37: BCG vaccine efficacy rate with universal coverage | F37: ='Vaccine efficacy'!F49 -> % | G37: supp | H37: ='Vaccine efficacy'!H49 -> 0.7226738 | I37: ='Vaccine efficacy'!I49 -> - | J37: ='Vaccine efficacy'!J49 -> - | K37: ='Vaccine efficacy'!K49 -> - | L37: ='Vaccine efficacy'!L49 -> - | M37: ='Vaccine efficacy'!M49 -> - | N37: ='Vaccine efficacy'!N49 -> - | O37: ='Vaccine efficacy'!O49 -> - | ... AT37: ='Vaccine efficacy'!AT49
E38: DTP vaccine efficacy rate with universal coverage (part of the Penta vaccine) | F38: ='Vaccine efficacy'!F50 -> % | G38: supp | H38: ='Vaccine efficacy'!H50 -> 0.71417176 | I38: ='Vaccine efficacy'!I50 -> - | J38: ='Vaccine efficacy'!J50 -> - | K38: ='Vaccine efficacy'!K50 -> - | L38: ='Vaccine efficacy'!L50 -> - | M38: ='Vaccine efficacy'!M50 -> - | N38: ='Vaccine efficacy'!N50 -> - | O38: ='Vaccine efficacy'!O50 -> - | ... AT38: ='Vaccine efficacy'!AT50
E39: Hib vaccine efficacy rate with universal coverage (part of the Penta vaccine) | F39: ='Vaccine efficacy'!F51 -> % | G39: supp | H39: ='Vaccine efficacy'!H51 -> 0.69716767 | I39: ='Vaccine efficacy'!I51 -> - | J39: ='Vaccine efficacy'!J51 -> - | K39: ='Vaccine efficacy'!K51 -> - | L39: ='Vaccine efficacy'!L51 -> - | M39: ='Vaccine efficacy'!M51 -> - | N39: ='Vaccine efficacy'!N51 -> - | O39: ='Vaccine efficacy'!O51 -> - | ... AT39: ='Vaccine efficacy'!AT51
E40: PCV vaccine efficacy rate with universal coverage | F40: ='Vaccine efficacy'!F52 -> % | G40: supp | H40: ='Vaccine efficacy'!H52 -> 0.49311859 | I40: ='Vaccine efficacy'!I52 -> - | J40: ='Vaccine efficacy'!J52 -> - | K40: ='Vaccine efficacy'!K52 -> - | L40: ='Vaccine efficacy'!L52 -> - | M40: ='Vaccine efficacy'!M52 -> - | N40: ='Vaccine efficacy'!N52 -> - | O40: ='Vaccine efficacy'!O52 -> - | ... AT40: ='Vaccine efficacy'!AT52
E41: Rotavirus vaccine efficacy rate with universal coverage | F41: ='Vaccine efficacy'!F53 -> % | G41: supp | H41: ='Vaccine efficacy'!H53 -> 0.39109406 | I41: ='Vaccine efficacy'!I53 -> - | J41: ='Vaccine efficacy'!J53 -> - | K41: ='Vaccine efficacy'!K53 -> - | L41: ='Vaccine efficacy'!L53 -> - | M41: ='Vaccine efficacy'!M53 -> - | N41: ='Vaccine efficacy'!N53 -> - | O41: ='Vaccine efficacy'!O53 -> - | ... AT41: ='Vaccine efficacy'!AT53
E42: Measles vaccine efficacy rate with universal coverage | F42: ='Vaccine efficacy'!F54 -> % | G42: supp | H42: ='Vaccine efficacy'!H54 -> 0.66531945 | I42: ='Vaccine efficacy'!I54 -> - | J42: ='Vaccine efficacy'!J54 -> - | K42: ='Vaccine efficacy'!K54 -> - | L42: ='Vaccine efficacy'!L54 -> - | M42: ='Vaccine efficacy'!M54 -> - | N42: ='Vaccine efficacy'!N54 -> - | O42: ='Vaccine efficacy'!O54 -> - | ... AT42: ='Vaccine efficacy'!AT54
C44: Proportion of deaths from vaccine-preventable causes among unvaccinated people under age 5 that are addressable by each vaccine, adjusted for deaths occurring before the age of vaccination
E45: Proportion of deaths from vaccine-preventable causes among unvaccinated people under age 5 that are addressable by the BCG vaccine, adjusted for deaths occurring before the age of vaccination | F45: ='Disease burden'!F212 -> % | G45: supp | H45: ='Disease burden'!H212 -> - | I45: ='Disease burden'!I212 -> 0.15586704 | J45: ='Disease burden'!J212 -> 0.11144603 | K45: ='Disease burden'!K212 -> 0.1819901 | L45: ='Disease burden'!L212 -> 0.098943878 | M45: ='Disease burden'!M212 -> 0.10933325 | N45: ='Disease burden'!N212 -> 0.15335908 | O45: ='Disease burden'!O212 -> 0.14253742 | ... AS45: ='Disease burden'!AS212 -> 0.14647347
E46: Proportion of deaths from vaccine-preventable causes among unvaccinated people under age 5 that are addressable by the DTP vaccine, adjusted for deaths occurring before the age of vaccination | F46: ='Disease burden'!F213 -> % | G46: supp | H46: ='Disease burden'!H213 -> - | I46: ='Disease burden'!I213 -> 0.088968849 | J46: ='Disease burden'!J213 -> 0.11092845 | K46: ='Disease burden'!K213 -> 0.10532978 | L46: ='Disease burden'!L213 -> 0.11816781 | M46: ='Disease burden'!M213 -> 0.091164015 | N46: ='Disease burden'!N213 -> 0.11285135 | O46: ='Disease burden'!O213 -> 0.12932727 | ... AS46: ='Disease burden'!AS213 -> 0.13083474
...

Sheet Treatment effect
I1: New Incentives – current states of operation | R1: New Incentives – prospective states | AF1: New Incentives – prospective states
I2: Nigeria | J2: Nigeria | K2: Nigeria | L2: Nigeria | M2: Nigeria | N2: Nigeria | O2: Nigeria | P2: Nigeria | Q2: Nigeria | R2: Nigeria | S2: Nigeria | T2: Nigeria | U2: Nigeria | V2: Nigeria | W2: Nigeria | X2: Nigeria | Y2: Nigeria | Z2: Nigeria | AA2: Nigeria | AB2: Nigeria | AC2: Nigeria | AD2: Nigeria | AE2: Nigeria | AF2: Nigeria | AG2: Nigeria | AH2: Nigeria | AI2: Nigeria | AJ2: Nigeria | AK2: Nigeria | AL2: Nigeria | AM2: Nigeria | AN2: Nigeria | AO2: Nigeria | AP2: Nigeria | AQ2: Nigeria | AR2: Nigeria | AS2: Nigeria
A3: Main calculations | F3: unit | G3: type | H3: Overall | I3: Bauchi | J3: Gombe | K3: Jigawa | L3: Kaduna | M3: Kano | N3: Katsina | O3: Kebbi | P3: Sokoto | Q3: Zamfara | R3: Abia | S3: Adamawa | T3: Akwa Ibom | U3: Anambra | V3: Bayelsa | W3: Benue | X3: Borno | Y3: Cross River | Z3: Delta | AA3: Ebonyi | AB3: Edo | AC3: Ekiti | AD3: Enugu | AE3: FCT | AF3: Imo | AG3: Kogi | AH3: Kwara | AI3: Lagos | AJ3: Nasarawa | AK3: Niger | AL3: Ogun | AM3: Ondo | AN3: Osun | AO3: Oyo | AP3: Plateau | AQ3: Rivers | AR3: Taraba | AS3: Yobe
E4: Final cost-effectiveness estimate (pulled from "Main calcs" sheet for visibility) | F4: ='Main CEA'!F241 -> xcash | G4: ='Main CEA'!G241 -> calc | H4: ='Main CEA'!H241 -> - | I4: ='Main CEA'!I241 -> 23.798889 | J4: ='Main CEA'!J241 -> 10.800641 | K4: ='Main CEA'!K241 -> 19.899944 | L4: ='Main CEA'!L241 -> 5.6568275 | M4: ='Main CEA'!M241 -> 13.129176 | ... AS4: ='Main CEA'!AS241 -> 6.7228331
A5: Vaccination coverage rates for the control group of the New Incentives RCT
C7: Vaccination coverage rates for the control group of the New Incentives RCT
E8: Proportion of children in the New Incentives RCT control group who reported receiving the BCG vaccine | F8: =Inputs!F195 -> % | G8: =Inputs!G195 -> input | H8: =Inputs!H195 -> 0.63 | I8: =Inputs!I195 -> - | J8: =Inputs!J195 -> - | K8: =Inputs!K195 -> - | L8: =Inputs!L195 -> - | M8: =Inputs!M195 -> - | ... AS8: =Inputs!AS195 -> -
E9: Proportion of children in the New Incentives RCT control group who reported receiving the 1st dose of the Penta vaccine | F9: =Inputs!F196 -> % | G9: =Inputs!G196 -> input | H9: =Inputs!H196 -> 0.5419 | I9: =Inputs!I196 -> - | J9: =Inputs!J196 -> - | K9: =Inputs!K196 -> - | L9: =Inputs!L196 -> - | M9: =Inputs!M196 -> - | ... AS9: =Inputs!AS196 -> -
E10: Proportion of children in the New Incentives RCT control group who reported receiving the 2nd dose of the Penta vaccine | F10: =Inputs!F197 -> % | G10: =Inputs!G197 -> input | H10: =Inputs!H197 -> 0.3961 | I10: =Inputs!I197 -> - | J10: =Inputs!J197 -> - | K10: =Inputs!K197 -> - | L10: =Inputs!L197 -> - | M10: =Inputs!M197 -> - | ... AS10: =Inputs!AS197 -> -
E11: Proportion of children in the New Incentives RCT control group who reported receiving the 3rd dose of the Penta vaccine | F11: =Inputs!F198 -> % | G11: =Inputs!G198 -> input | H11: =Inputs!H198 -> 0.2978 | I11: =Inputs!I198 -> - | J11: =Inputs!J198 -> - | K11: =Inputs!K198 -> - | L11: =Inputs!L198 -> - | M11: =Inputs!M198 -> - | ... AS11: =Inputs!AS198 -> -
E12: Proportion of children in the New Incentives RCT control group who reported receiving the 1st dose of the PCV vaccine | F12: =Inputs!F199 -> % | G12: =Inputs!G199 -> input | H12: =Inputs!H199 -> 0.4954 | I12: =Inputs!I199 -> - | J12: =Inputs!J199 -> - | K12: =Inputs!K199 -> - | L12: =Inputs!L199 -> - | M12: =Inputs!M199 -> - | ... AS12: =Inputs!AS199 -> -
E13: Proportion of children in the New Incentives RCT control group who reported receiving the 2nd dose of the PCV vaccine | F13: =Inputs!F200 -> % | G13: =Inputs!G200 -> input | H13: =Inputs!H200 -> 0.3554 | I13: =Inputs!I200 -> - | J13: =Inputs!J200 -> - | K13: =Inputs!K200 -> - | L13: =Inputs!L200 -> - | M13: =Inputs!M200 -> - | ... AS13: =Inputs!AS200 -> -
E14: Proportion of children in the New Incentives RCT control group who reported receiving the 3rd dose of the PCV vaccine | F14: =Inputs!F201 -> % | G14: =Inputs!G201 -> input | H14: =Inputs!H201 -> 0.266 | I14: =Inputs!I201 -> - | J14: =Inputs!J201 -> - | K14: =Inputs!K201 -> - | L14: =Inputs!L201 -> - | M14: =Inputs!M201 -> - | ... AS14: =Inputs!AS201 -> -
E15: Proportion of children in the New Incentives RCT control group who reported receiving the measles vaccine | F15: =Inputs!F202 -> % | G15: =Inputs!G202 -> input | H15: =Inputs!H202 -> 0.5894 | I15: =Inputs!I202 -> - | J15: =Inputs!J202 -> - | K15: =Inputs!K202 -> - | L15: =Inputs!L202 -> - | M15: =Inputs!M202 -> - | ... AS15: =Inputs!AS202 -> -
C17: Adjustment for self-report bias
E18: Adjustment for self-report bias in the New Incentives RCT | F18: =Inputs!F205 -> % | G18: =Inputs!G205 -> input | H18: =Inputs!H205 -> -0.2768959 | I18: =Inputs!I205 -> - | J18: =Inputs!J205 -> - | K18: =Inputs!K205 -> - | L18: =Inputs!L205 -> - | M18: =Inputs!M205 -> - | ... AS18: =Inputs!AS205 -> -
C20: Vaccination coverage rates for the control group of the New Incentives RCT, adjusted for self-report bias
E21: Proportion of children in the New Incentives RCT control group who received the BCG vaccine | F21: % | G21: calc | H21: =H8*(1+H$18) -> 0.45555558 | I21: - | J21: - | K21: - | L21: - | M21: - | N21: - | O21: - | P21: - | Q21: - | R21: - | S21: - | T21: - | U21: - | V21: - | W21: - | X21: - | Y21: - | Z21: - | AA21: - | AB21: - | AC21: - | AD21: - | AE21: - | AF21: - | AG21: - | AH21: - | AI21: - | AJ21: - | AK21: - | AL21: - | AM21: - | AN21: - | AO21: - | AP21: - | AQ21: - | AR21: - | AS21: -
E22: Proportion of children in the New Incentives RCT control group who received the 1st dose of the Penta vaccine | F22: % | G22: calc | H22: =H9*(1+H$18) -> 0.39185011 | I22: - | J22: - | K22: - | L22: - | M22: - | N22: - | O22: - | P22: - | Q22: - | R22: - | S22: - | T22: - | U22: - | V22: - | W22: - | X22: - | Y22: - | Z22: - | AA22: - | AB22: - | AC22: - | AD22: - | AE22: - | AF22: - | AG22: - | AH22: - | AI22: - | AJ22: - | AK22: - | AL22: - | AM22: - | AN22: - | AO22: - | AP22: - | AQ22: - | AR22: - | AS22: -
E23: Proportion of children in the New Incentives RCT control group who received the 2nd dose of the Penta vaccine | F23: % | G23: calc | H23: =H10*(1+H$18) -> 0.28642153 | I23: - | J23: - | K23: - | L23: - | M23: - | N23: - | O23: - | P23: - | Q23: - | R23: - | S23: - | T23: - | U23: - | V23: - | W23: - | X23: - | Y23: - | Z23: - | AA23: - | AB23: - | AC23: - | AD23: - | AE23: - | AF23: - | AG23: - | AH23: - | AI23: - | AJ23: - | AK23: - | AL23: - | AM23: - | AN23: - | AO23: - | AP23: - | AQ23: - | AR23: - | AS23: -
E24: Proportion of children in the New Incentives RCT control group who received the 3rd dose of the Penta vaccine | F24: % | G24: calc | H24: =H11*(1+H$18) -> 0.2153404 | I24: - | J24: - | K24: - | L24: - | M24: - | N24: - | O24: - | P24: - | Q24: - | R24: - | S24: - | T24: - | U24: - | V24: - | W24: - | X24: - | Y24: - | Z24: - | AA24: - | AB24: - | AC24: - | AD24: - | AE24: - | AF24: - | AG24: - | AH24: - | AI24: - | AJ24: - | AK24: - | AL24: - | AM24: - | AN24: - | AO24: - | AP24: - | AQ24: - | AR24: - | AS24: -
E25: Proportion of children in the New Incentives RCT control group who received the 1st dose of the PCV vaccine | F25: % | G25: calc | H25: =H12*(1+H$18) -> 0.35822577 | I25: - | J25: - | K25: - | L25: - | M25: - | N25: - | O25: - | P25: - | Q25: - | R25: - | S25: - | T25: - | U25: - | V25: - | W25: - | X25: - | Y25: - | Z25: - | AA25: - | AB25: - | AC25: - | AD25: - | AE25: - | AF25: - | AG25: - | AH25: - | AI25: - | AJ25: - | AK25: - | AL25: - | AM25: - | AN25: - | AO25: - | AP25: - | AQ25: - | AR25: - | AS25: -
E26: Proportion of children in the New Incentives RCT control group who received the 2nd dose of the PCV vaccine | F26: % | G26: calc | H26: =H13*(1+H$18) -> 0.2569912 | I26: - | J26: - | K26: - | L26: - | M26: - | N26: - | O26: - | P26: - | Q26: - | R26: - | S26: - | T26: - | U26: - | V26: - | W26: - | X26: - | Y26: - | Z26: - | AA26: - | AB26: - | AC26: - | AD26: - | AE26: - | AF26: - | AG26: - | AH26: - | AI26: - | AJ26: - | AK26: - | AL26: - | AM26: - | AN26: - | AO26: - | AP26: - | AQ26: - | AR26: - | AS26: -
E27: Proportion of children in the New Incentives RCT control group who received the 3rd dose of the PCV vaccine | F27: % | G27: calc | H27: =H14*(1+H$18) -> 0.19234569 | I27: - | J27: - | K27: - | L27: - | M27: - | N27: - | O27: - | P27: - | Q27: - | R27: - | S27: - | T27: - | U27: - | V27: - | W27: - | X27: - | Y27: - | Z27: - | AA27: - | AB27: - | AC27: - | AD27: - | AE27: - | AF27: - | AG27: - | AH27: - | AI27: - | AJ27: - | AK27: - | AL27: - | AM27: - | AN27: - | AO27: - | AP27: - | AQ27: - | AR27: - | AS27: -
E28: Proportion of children in the New Incentives RCT control group who received the measles vaccine | F28: % | G28: calc | H28: =H15*(1+H$18) -> 0.42619756 | I28: - | J28: - | K28: - | L28: - | M28: - | N28: - | O28: - | P28: - | Q28: - | R28: - | S28: - | T28: - | U28: - | V28: - | W28: - | X28: - | Y28: - | Z28: - | AA28: - | AB28: - | AC28: - | AD28: - | AE28: - | AF28: - | AG28: - | AH28: - | AI28: - | AJ28: - | AK28: - | AL28: - | AM28: - | AN28: - | AO28: - | AP28: - | AQ28: - | AR28: - | AS28: -
C30: Proportion of vaccine-preventable mortalities that could be prevented by each vaccine dose
E31: Proportion of vaccine-preventable mortalities among people under age 5 that could be prevented by the BCG vaccine | F31: ='Disease burden'!F384 -> % | G31: supp | H31: ='Disease burden'!H384 -> - | I31: ='Disease burden'!I384 -> 0.2130494 | J31: ='Disease burden'!J384 -> 0.15347722 | K31: ='Disease burden'!K384 -> 0.24112748 | L31: ='Disease burden'!L384 -> 0.13471259 | M31: ='Disease burden'!M384 -> 0.15263081 | N31: ='Disease burden'!N384 -> 0.20594728 | O31: ='Disease burden'!O384 -> 0.19115989 | ... AS31: ='Disease burden'!AS384 -> 0.19515058
E32: Proportion of vaccine-preventable mortalities among people under age 5 that could be prevented by the 1st dose of the Penta vaccine | F32: ='Disease burden'!F385 -> % | G32: supp | H32: ='Disease burden'!H385 -> - | I32: ='Disease burden'!I385 -> 0.053131051 | J32: ='Disease burden'!J385 -> 0.06606296 | K32: ='Disease burden'!K385 -> 0.059308756 | L32: ='Disease burden'!L385 -> 0.070627408 | M32: ='Disease burden'!M385 -> 0.057825023 | N32: ='Disease burden'!N385 -> 0.062888388 | O32: ='Disease burden'!O385 -> 0.070475442 | ... AS32: ='Disease burden'!AS385 -> 0.071075284
E33: Proportion of vaccine-preventable mortalities among people under age 5 that could be prevented by the 2nd dose of the Penta vaccine | F33: ='Disease burden'!F386 -> % | G33: supp | H33: ='Disease burden'!H386 -> - | I33: ='Disease burden'!I386 -> 0.083491652 | J33: ='Disease burden'!J386 -> 0.10381322 | K33: ='Disease burden'!K386 -> 0.093199474 | L33: ='Disease burden'!L386 -> 0.11098593 | M33: ='Disease burden'!M386 -> 0.090867893 | N33: ='Disease burden'!N386 -> 0.098824609 | O33: ='Disease burden'!O386 -> 0.11074712 | ... AS33: ='Disease burden'!AS386 -> 0.11168973
E34: Proportion of vaccine-preventable mortalities among people under age 5 that could be prevented by the 3rd dose of the Penta vaccine | F34: ='Disease burden'!F387 -> % | G34: supp | H34: ='Disease burden'!H387 -> - | I34: ='Disease burden'!I387 -> 0.0151803 | J34: ='Disease burden'!J387 -> 0.018875132 | K34: ='Disease burden'!K387 -> 0.016945359 | L34: ='Disease burden'!L387 -> 0.020179259 | M34: ='Disease burden'!M387 -> 0.016521435 | N34: ='Disease burden'!N387 -> 0.017968111 | O34: ='Disease burden'!O387 -> 0.02013584 | ... AS34: ='Disease burden'!AS387 -> 0.020307224
E35: Proportion of vaccine-preventable mortalities among people under age 5 that could be prevented by the 1st dose of the PCV vaccine | F35: ='Disease burden'!F388 -> % | G35: supp | H35: ='Disease burden'!H388 -> - | I35: ='Disease burden'!I388 -> 0.11779326 | J35: ='Disease burden'!J388 -> 0.13550544 | K35: ='Disease burden'!K388 -> 0.11656148 | L35: ='Disease burden'!L388 -> 0.14964149 | M35: ='Disease burden'!M388 -> 0.14524548 | N35: ='Disease burden'!N388 -> 0.10887223 | O35: ='Disease burden'!O388 -> 0.1087302 | ... AS35: ='Disease burden'!AS388 -> 0.11016126
E36: Proportion of vaccine-preventable mortalities among people under age 5 that could be prevented by the 2nd dose of the PCV vaccine | F36: ='Disease burden'!F389 -> % | G36: supp | H36: ='Disease burden'!H389 -> - | I36: ='Disease burden'!I389 -> 0.18510369 | J36: ='Disease burden'!J389 -> 0.21293712 | K36: ='Disease burden'!K389 -> 0.18316803 | L36: ='Disease burden'!L389 -> 0.23515091 | M36: ='Disease burden'!M389 -> 0.2282429 | N36: ='Disease burden'!N389 -> 0.17108494 | O36: ='Disease burden'!O389 -> 0.17086174 | ... AS36: ='Disease burden'!AS389 -> 0.17311055
E37: Proportion of vaccine-preventable mortalities among people under age 5 that could be prevented by the 3rd dose of the PCV vaccine | F37: ='Disease burden'!F390 -> % | G37: supp | H37: ='Disease burden'!H390 -> - | I37: ='Disease burden'!I390 -> 0.033655217 | J37: ='Disease burden'!J390 -> 0.03871584 | K37: ='Disease burden'!K390 -> 0.033303279 | L37: ='Disease burden'!L390 -> 0.042754711 | M37: ='Disease burden'!M390 -> 0.041498709 | N37: ='Disease burden'!N390 -> 0.031106352 | O37: ='Disease burden'!O390 -> 0.031065772 | ... AS37: ='Disease burden'!AS390 -> 0.031474645
E38: Proportion of vaccine-preventable mortalities among people under age 5 that could be prevented by the 1st dose of the measles vaccine | F38: ='Disease burden'!F393 -> % | G38: supp | H38: ='Disease burden'!H393 -> - | I38: ='Disease burden'!I393 -> 0.059805717 | J38: ='Disease burden'!J393 -> 0.046870343 | K38: ='Disease burden'!K393 -> 0.06597866 | L38: ='Disease burden'!L393 -> 0.053867734 | M38: ='Disease burden'!M393 -> 0.034953333 | N38: ='Disease burden'!N393 -> 0.081308726 | O38: ='Disease burden'!O393 -> 0.076530784 | ... AS38: ='Disease burden'!AS393 -> 0.079728455
C40: Average proportion of vaccine-preventable mortalities that could be prevented by each vaccine dose in RCT states (Jigawa, Katsina, Zamfara)
E41: Proportion of vaccine-preventable mortalities among people under age 5 that could be prevented by the BCG vaccine in RCT states | F41: % | G41: calc | H41: =AVERAGE(K31,N31,Q31) -> 0.22901989 | I41: - | J41: - | K41: - | L41: - | M41: - | N41: - | O41: - | P41: - | Q41: - | R41: - | S41: - | T41: - | U41: - | V41: - | W41: - | X41: - | Y41: - | Z41: - | AA41: - | AB41: - | AC41: - | AD41: - | AE41: - | AF41: - | AG41: - | AH41: - | AI41: - | AJ41: - | AK41: - | AL41: - | AM41: - | AN41: - | AO41: - | AP41: - | AQ41: - | AR41: - | AS41: -
E42: Proportion of vaccine-preventable mortalities among people under age 5 that could be prevented by the 1st dose of the Penta vaccine in RCT states | F42: % | G42: calc | H42: =AVERAGE(K32,N32,Q32) -> 0.061544223 | I42: - | J42: - | K42: - | L42: - | M42: - | N42: - | O42: - | P42: - | Q42: - | R42: - | S42: - | T42: - | U42: - | V42: - | W42: - | X42: - | Y42: - | Z42: - | AA42: - | AB42: - | AC42: - | AD42: - | AE42: - | AF42: - | AG42: - | AH42: - | AI42: - | AJ42: - | AK42: - | AL42: - | AM42: - | AN42: - | AO42: - | AP42: - | AQ42: - | AR42: - | AS42: -
E43: Proportion of vaccine-preventable mortalities among people under age 5 that could be prevented by the 2nd dose of the Penta vaccine in RCT states | F43: % | G43: calc | H43: =AVERAGE(K33,N33,Q33) -> 0.096712351 | I43: - | J43: - | K43: - | L43: - | M43: - | N43: - | O43: - | P43: - | Q43: - | R43: - | S43: - | T43: - | U43: - | V43: - | W43: - | X43: - | Y43: - | Z43: - | AA43: - | AB43: - | AC43: - | AD43: - | AE43: - | AF43: - | AG43: - | AH43: - | AI43: - | AJ43: - | AK43: - | AL43: - | AM43: - | AN43: - | AO43: - | AP43: - | AQ43: - | AR43: - | AS43: -
E44: Proportion of vaccine-preventable mortalities among people under age 5 that could be prevented by the 3rd dose of the Penta vaccine in RCT states | F44: % | G44: calc | H44: =AVERAGE(K34,N34,Q34) -> 0.017584064 | I44: - | J44: - | K44: - | L44: - | M44: - | N44: - | O44: - | P44: - | Q44: - | R44: - | S44: - | T44: - | U44: - | V44: - | W44: - | X44: - | Y44: - | Z44: - | AA44: - | AB44: - | AC44: - | AD44: - | AE44: - | AF44: - | AG44: - | AH44: - | AI44: - | AJ44: - | AK44: - | AL44: - | AM44: - | AN44: - | AO44: - | AP44: - | AQ44: - | AR44: - | AS44: -
E45: Proportion of vaccine-preventable mortalities among people under age 5 that could be prevented by the 1st dose of the PCV vaccine in RCT states | F45: % | G45: calc | H45: =AVERAGE(K35,N35,Q35) -> 0.10556603 | I45: - | J45: - | K45: - | L45: - | M45: - | N45: - | O45: - | P45: - | Q45: - | R45: - | S45: - | T45: - | U45: - | V45: - | W45: - | X45: - | Y45: - | Z45: - | AA45: - | AB45: - | AC45: - | AD45: - | AE45: - | AF45: - | AG45: - | AH45: - | AI45: - | AJ45: - | AK45: - | AL45: - | AM45: - | AN45: - | AO45: - | AP45: - | AQ45: - | AR45: - | AS45: -
...

Sheet Disease burden
I1: New Incentives – current states of operation | R1: New Incentives – prospective states | AF1: New Incentives – prospective states
I2: Nigeria | J2: Nigeria | K2: Nigeria | L2: Nigeria | M2: Nigeria | N2: Nigeria | O2: Nigeria | P2: Nigeria | Q2: Nigeria | R2: Nigeria | S2: Nigeria | T2: Nigeria | U2: Nigeria | V2: Nigeria | W2: Nigeria | X2: Nigeria | Y2: Nigeria | Z2: Nigeria | AA2: Nigeria | AB2: Nigeria | AC2: Nigeria | AD2: Nigeria | AE2: Nigeria | AF2: Nigeria | AG2: Nigeria | AH2: Nigeria | AI2: Nigeria | AJ2: Nigeria | AK2: Nigeria | AL2: Nigeria | AM2: Nigeria | AN2: Nigeria | AO2: Nigeria | AP2: Nigeria | AQ2: Nigeria | AR2: Nigeria | AS2: Nigeria
A3: Main calculations | F3: unit | G3: type | H3: Overall | I3: Bauchi | J3: Gombe | K3: Jigawa | L3: Kaduna | M3: Kano | N3: Katsina | O3: Kebbi | P3: Sokoto | Q3: Zamfara | R3: Abia | S3: Adamawa | T3: Akwa Ibom | U3: Anambra | V3: Bayelsa | W3: Benue | X3: Borno | Y3: Cross River | Z3: Delta | AA3: Ebonyi | AB3: Edo | AC3: Ekiti | AD3: Enugu | AE3: FCT | AF3: Imo | AG3: Kogi | AH3: Kwara | AI3: Lagos | AJ3: Nasarawa | AK3: Niger | AL3: Ogun | AM3: Ondo | AN3: Osun | AO3: Oyo | AP3: Plateau | AQ3: Rivers | AR3: Taraba | AS3: Yobe
E4: Final cost-effectiveness estimate (pulled from "Main calcs" sheet for visibility) | F4: ='Main CEA'!F241 -> xcash | G4: ='Main CEA'!G241 -> calc | H4: ='Main CEA'!H241 -> - | I4: ='Main CEA'!I241 -> 23.798889 | J4: ='Main CEA'!J241 -> 10.800641 | K4: ='Main CEA'!K241 -> 19.899944 | L4: ='Main CEA'!L241 -> 5.6568275 | M4: ='Main CEA'!M241 -> 13.129176 | ... AS4: ='Main CEA'!AS241 -> 6.7228331
A5: Tuberculosis
C7: Probability of dying of tuberculosis
E8: Probability that a person will die of tuberculosis before reaching age 5 | F8: =Inputs!F100 -> % | G8: =Inputs!G100 -> input | H8: =Inputs!H100 -> - | I8: =Inputs!I100 -> 0.003629763 | J8: =Inputs!J100 -> 0.001693533 | K8: =Inputs!K100 -> 0.004321809 | L8: =Inputs!L100 -> 0.000876042 | M8: =Inputs!M100 -> 0.001723095 | ... AS8: =Inputs!AS100 -> 0.00187352
E9: Probability that a 5-year-old will die of tuberculosis before reaching age 15 | F9: =Inputs!F101 -> % | G9: =Inputs!G101 -> input | H9: =Inputs!H101 -> - | I9: =Inputs!I101 -> 0.000531146 | J9: =Inputs!J101 -> 0.000260845 | K9: =Inputs!K101 -> 0.000599109 | L9: =Inputs!L101 -> 0.000139527 | M9: =Inputs!M101 -> 0.000283003 | ... AS9: =Inputs!AS101 -> 0.000388626
E10: Probability that a 15-year-old will die of tuberculosis before reaching age 50 | F10: =Inputs!F102 -> % | G10: =Inputs!G102 -> input | H10: =Inputs!H102 -> - | I10: =Inputs!I102 -> 0.007150253 | J10: =Inputs!J102 -> 0.004007767 | K10: =Inputs!K102 -> 0.008685948 | L10: =Inputs!L102 -> 0.002843472 | M10: =Inputs!M102 -> 0.003815045 | ... AS10: =Inputs!AS102 -> 0.006708114
E11: Probability that a 50-year-old will die of tuberculosis before reaching age 75 | F11: =Inputs!F103 -> % | G11: =Inputs!G103 -> input | H11: =Inputs!H103 -> - | I11: =Inputs!I103 -> 0.049361812 | J11: =Inputs!J103 -> 0.030242318 | K11: =Inputs!K103 -> 0.052337352 | L11: =Inputs!L103 -> 0.017468647 | M11: =Inputs!M103 -> 0.024547523 | ... AS11: =Inputs!AS103 -> 0.043770944
C13: Tuberculosis mortalities occurring before the age of vaccination
E14: Proportion of tuberculosis mortalities among people under age 5 that occur prior to the age of BCG vaccination (birth) | F14: % | G14: input | H14: =Inputs!H104 -> 0 | I14: =Inputs!I104 -> - | J14: =Inputs!J104 -> - | K14: =Inputs!K104 -> - | L14: =Inputs!L104 -> - | M14: =Inputs!M104 -> - | N14: =Inputs!N104 -> - | O14: =Inputs!O104 -> - | ... AS14: =Inputs!AS104 -> -
E15: Probability that a person will die of tuberculosis before reaching age 5, adjusted for deaths occurring before the age of vaccination | F15: % | G15: calc | H15: - | I15: =I8*(1-$H14) -> 0.003629763 | J15: =J8*(1-$H14) -> 0.001693533 | K15: =K8*(1-$H14) -> 0.004321809 | L15: =L8*(1-$H14) -> 0.000876042 | M15: =M8*(1-$H14) -> 0.001723095 | N15: =N8*(1-$H14) -> 0.002687563 | O15: =O8*(1-$H14) -> 0.002755632 | P15: =P8*(1-$H14) -> 0.004692335 | ... AS15: =AS8*(1-$H14) -> 0.00187352
A17: Diphtheria
C19: Probability of dying of diphtheria
E20: Probability that a person will die of diphtheria before reaching age 5 | F20: % | G20: input | H20: =Inputs!H107 -> - | I20: =Inputs!I107 -> 0.000501357 | J20: =Inputs!J107 -> 0.000347103 | K20: =Inputs!K107 -> 0.000579052 | L20: =Inputs!L107 -> 0.000105863 | M20: =Inputs!M107 -> 0.000247733 | N20: =Inputs!N107 -> 0.000380731 | O20: =Inputs!O107 -> 0.000728763 | ... AS20: =Inputs!AS107 -> 0.000257334
E21: Probability that a 5-year-old will die of diphtheria before reaching age 15 | F21: % | G21: input | H21: =Inputs!H108 -> - | I21: =Inputs!I108 -> 5.88e-05 | J21: =Inputs!J108 -> 4.39e-05 | K21: =Inputs!K108 -> 6.71e-05 | L21: =Inputs!L108 -> 1.99e-05 | M21: =Inputs!M108 -> 3.53e-05 | N21: =Inputs!N108 -> 4.59e-05 | O21: =Inputs!O108 -> 0.000109744 | ... AS21: =Inputs!AS108 -> 4.46e-05
E22: Probability that a 15-year-old will die of diphtheria before reaching age 50 | F22: % | G22: input | H22: =Inputs!H109 -> - | I22: =Inputs!I109 -> 2.77e-05 | J22: =Inputs!J109 -> 2.01e-05 | K22: =Inputs!K109 -> 3.52e-05 | L22: =Inputs!L109 -> 1.12e-05 | M22: =Inputs!M109 -> 1.33e-05 | N22: =Inputs!N109 -> 2.68e-05 | O22: =Inputs!O109 -> 5.9e-05 | ... AS22: =Inputs!AS109 -> 3.04e-05
E23: Probability that a 50-year-old will die of diphtheria before reaching age 75 | F23: % | G23: input | H23: =Inputs!H110 -> - | I23: =Inputs!I110 -> 4.12e-05 | J23: =Inputs!J110 -> 3.15e-05 | K23: =Inputs!K110 -> 4.55e-05 | L23: =Inputs!L110 -> 1.6e-05 | M23: =Inputs!M110 -> 2.15e-05 | N23: =Inputs!N110 -> 3.93e-05 | O23: =Inputs!O110 -> 8.1e-05 | ... AS23: =Inputs!AS110 -> 4.25e-05
C25: Diphtheria mortalities occurring before the age of vaccination
